Workbook
Name ASSUM_APDays_Start: '3 Statement Model'!$J$17
Name ASSUM_ARDays_Start: '3 Statement Model'!$J$15
Name ASSUM_Capex_Start: '3 Statement Model'!$J$18
Name ASSUM_COGSPct_Start: '3 Statement Model'!$J$8
Name ASSUM_DAPctPPE_Start: '3 Statement Model'!$J$11
Name ASSUM_DebtIssuance_Start: '3 Statement Model'!$J$19
Name ASSUM_EquityIssuance_Start: '3 Statement Model'!$J$20
Name ASSUM_IntPct_Start: '3 Statement Model'!$J$12
Name ASSUM_InvDays_Start: '3 Statement Model'!$J$16
Name ASSUM_RD_Start: '3 Statement Model'!$J$10
Name ASSUM_RevGrowth_Start: '3 Statement Model'!$J$7
Name ASSUM_SGA_Start: '3 Statement Model'!$J$9
Name ASSUM_TaxRate_Start: '3 Statement Model'!$J$13
Name BS_AP_Start: '3 Statement Model'!$E$48
Name BS_AR_Start: '3 Statement Model'!$E$42
Name BS_Cash_Start: '3 Statement Model'!$E$41
Name BS_Debt_Start: '3 Statement Model'!$E$49
Name BS_EquityCapital_Start: '3 Statement Model'!$E$52
Name BS_Inventory_Start: '3 Statement Model'!$E$43
Name BS_PPE_Start: '3 Statement Model'!$E$44
Name BS_RE_Start: '3 Statement Model'!$E$53
Name CF_Capex_Start: '3 Statement Model'!$E$68
Name CF_DebtIssuance_Start: '3 Statement Model'!$E$72
Name CF_DeltaNWC_Start: '3 Statement Model'!$E$64
Name CF_EquityIssuance_Start: '3 Statement Model'!$E$73
Name CF_OpeningCash_FY1: '3 Statement Model'!$D$78
Name DCF_Cash: 'DCF Model'!$D$14
Name DCF_Debt: 'DCF Model'!$D$13
Name DCF_ExitMultiple: 'DCF Model'!$D$8
Name DCF_FiscalYearEnd: 'DCF Model'!$D$10
Name DCF_PerpetualGrowth: 'DCF Model'!$D$7
Name DCF_SharePrice: 'DCF Model'!$D$11
Name DCF_Shares: 'DCF Model'!$D$12
Name DCF_TaxRate: 'DCF Model'!$D$5
Name DCF_TransactionDate: 'DCF Model'!$D$9
Name DCF_WACC: 'DCF Model'!$D$6
Name Forecast: #REF!
Name IS_BaseYear: '3 Statement Model'!$E$2
Name IS_COGS_FY1: '3 Statement Model'!$E$25
Name IS_COGS_FY2: '3 Statement Model'!$F$25
Name IS_COGS_FY3: '3 Statement Model'!$G$25
Name IS_COGS_FY4: '3 Statement Model'!$H$25
Name IS_COGS_FY5: '3 Statement Model'!$I$25
Name IS_COGS_Start: '3 Statement Model'!$E$25
Name IS_DA_Start: '3 Statement Model'!$E$30
Name IS_Interest_Start: '3 Statement Model'!$E$31
Name IS_RD_Start: '3 Statement Model'!$E$29
Name IS_Revenue_FY1: '3 Statement Model'!$E$24
Name IS_Revenue_FY2: '3 Statement Model'!$F$24
Name IS_Revenue_FY3: '3 Statement Model'!$G$24
Name IS_Revenue_FY4: '3 Statement Model'!$H$24
Name IS_Revenue_FY5: '3 Statement Model'!$I$24
Name IS_Revenue_Start: '3 Statement Model'!$E$24
Name IS_SGA_Start: '3 Statement Model'!$E$28
Name IS_Tax_Start: '3 Statement Model'!$E$35
Name Step_1: #REF!
Name Step_2: #REF!
Name Step_3: #REF!
Name Step_4: #REF!
Name Step_5: #REF!

Sheet Cover Page
C12: FICO — Model2.0 (3-Statement + DCF) | N12: Strictly Confidential
C14: Table of Contents
C15: 3 Statement Model
C19: Notes
C20: Named Ranges mark INPUT cells only. Formula cells (Gross Profit, NI, UFCF, EV) have NO names and must never be overwritten. Open in Excel to recalculate.
C21: Model2.0: revenue fades (not straight-lined). DCF uses unlevered EBIT×t taxes, Gordon TV primary, mid-year XNPV dates, CapEx/ΔNWC/D&A linked to 3-statement. Open in Excel to recalculate.
C22: https://corporatefinanceinstitute.com/
C24: © 2019 CFI Education Inc.
C25: All rights reserved. The contents of this publication, including but not limited to all written material, content layout, images, formulas, and code, are protected under international copyright and trademark laws.
C26: No part of this publication may be modified, manipulated, reproduced, distributed, or transmitted in any form by any means, including photocopying, recording, or other electronic or mechanical methods,
C27: without prior written permission of the publisher, except in the case of certain noncommercial uses permitted by copyright law.

Sheet 3 Statement Model
B1: © Corporate Finance Institute®. All rights reserved. | E1: Historical Results | J1: Forecast Period
B2: FINANCIAL STATEMENTS | E2: 2021 | F2: =+E2+1 -> 2022 | G2: =+F2+1 -> 2023 | H2: =+G2+1 -> 2024 | I2: =+H2+1 -> 2025 | J2: =+I2+1 -> 2026 | K2: =+J2+1 -> 2027 | L2: =+K2+1 -> 2028 | M2: =+L2+1 -> 2029 | N2: =+M2+1 -> 2030
B3: Balance Sheet Check | E3: =IFERROR(IF(ABS(E57)>1,"ERROR","OK"),"OK") -> OK | F3: =IFERROR(IF(ABS(F57)>1,"ERROR","OK"),"OK") -> OK | G3: =IFERROR(IF(ABS(G57)>1,"ERROR","OK"),"OK") -> OK | H3: =IFERROR(IF(ABS(H57)>1,"ERROR","OK"),"OK") -> OK | I3: =IFERROR(IF(ABS(I57)>1,"ERROR","OK"),"OK") -> OK | J3: =IFERROR(IF(ABS(J57)>1,"ERROR","OK"),"OK") -> OK | K3: =IFERROR(IF(ABS(K57)>1,"ERROR","OK"),"OK") -> OK | L3: =IFERROR(IF(ABS(L57)>1,"ERROR","OK"),"OK") -> OK | ... N3: =IFERROR(IF(ABS(N57)>1,"ERROR","OK"),"OK") -> OK
B5: Assumptions
B6: Income statement
B7: Revenue Growth (% Change) | F7: =F24/E24-1 -> 0.046131667 | G7: =G24/F24-1 -> 0.098954453 | H7: =H24/G24-1 -> 0.13476136 | I7: =I24/H24-1 -> 0.15914926 | J7: 0.27 | K7: 0.15 | L7: 0.12 | M7: 0.1 | N7: 0.08
B8: Cost of Goods Sold (% of Revenue) | E8: =E25/E24 -> 0.25252785 | F8: =F25/F24 -> 0.2194007 | G8: =G25/G24 -> 0.20551126 | H8: =H25/H24 -> 0.20273696 | I8: =I25/I24 -> 0.17767216 | J8: 0.17767216 | K8: 0.17767216 | L8: 0.17767216 | M8: 0.17767216 | N8: 0.17767216
B9: Salaries and Benefits ($000's) | E9: =E28 -> 396281 | F9: =F28 -> 383863 | G9: =G28 -> 400565 | H9: =H28 -> 462834 | I9: =I28 -> 513028 | J9: 651545.6 | K9: 749277.4 | L9: 839190.7 | M9: 923109.7 | N9: 996958.5
B10: Rent and Overhead ($000's) | E10: =E29 -> 171231 | F10: =F29 -> 146758 | G10: =G29 -> 159950 | H10: =H29 -> 171940 | I10: =I29 -> 188347 | J10: 239200.7 | K10: 275080.8 | L10: 308090.5 | M10: 338899.5 | N10: 366011.5
B11: Depreciation & Amortization (% of PP&E Open Bal) | E11: =E30/E92 -> 0.55132597 | F11: =F30/F92 -> 0.73317092 | G11: =G30/G92 -> 0.83265074 | H11: =H30/H92 -> 1.2608973 | I11: =I30/I92 -> 0.38871702 | J11: 0.22081432 | K11: 0.22081432 | L11: 0.22081432 | M11: 0.22081432 | N11: 0.22081432
B12: Interest (% of Debt Open Bal) | E12: =E101/E98 -> 0.054219776 | F12: =F101/F98 -> 0.054778407 | G12: =G101/G98 -> 0.051544262 | H12: =H101/H98 -> 0.056744042 | I12: =I101/I98 -> 0.060500557 | J12: 0.043737079 | K12: 0.043737079 | L12: 0.043737079 | M12: 0.043737079 | N12: 0.043737079
B13: Tax Rate (% of Earnings Before Tax) | E13: =E35/E33 -> 0.23101477 | F13: =F35/F33 -> 0.21485442 | G13: =G35/G33 -> 0.23363639 | H13: =H35/H33 -> 0.2100764 | I13: =I35/I33 -> 0.19137979 | J13: 0.18770239 | K13: 0.18770239 | L13: 0.18770239 | M13: 0.18770239 | N13: 0.18770239
B14: Balance Sheet
B15: Accounts Receivable (Days) | E15: =E42/E24*365 -> 86.529388 | F15: =F42/F24*365 -> 85.444139 | G15: =G42/G24*365 -> 93.554888 | H15: =H42/H24*365 -> 90.667815 | I15: =I42/I24*365 -> 97.01242 | J15: 97 | K15: 97 | L15: 97 | M15: 97 | N15: 97
B16: Inventory (Days) | E16: =E43/E25*365 -> 0 | F16: =F43/F25*365 -> 0 | G16: =G43/G25*365 -> 0 | H16: =H43/H25*365 -> 0 | I16: =I43/I25*365 -> 0 | J16: 0 | K16: 0 | L16: 0 | M16: 0 | N16: 0
B17: Accounts Payable (Days) | E17: =E48/E25*365 -> 22.779701 | F17: =F48/F25*365 -> 20.864287 | G17: =G48/G25*365 -> 22.305797 | H17: =H48/H25*365 -> 23.556874 | I17: =I48/I25*365 -> 33.345325 | J17: 33 | K17: 33 | L17: 33 | M17: 33 | N17: 33
B18: Capital Expenditures ($000's) | E18: =E68 -> 7569 | F18: =F68 -> 6029 | G18: =G68 -> 4237 | H18: =H68 -> 25551 | I18: =I68 -> 39407 | J18: 50046.9 | K18: 57553.9 | L18: 64460.4 | M18: 70906.4 | N18: 76578.9
B19: Debt Issuance (Repayment) ($000's) | E19: =E99 -> 519583 | F19: =F99 -> 594651 | G19: =G99 -> 7989 | H19: =H99 -> 347363 | I19: =I99 -> 846670 | J19: 0 | K19: 0 | L19: 0 | M19: 0 | N19: 0
B20: Equity Issued (Repaid) ($000's) | E20: =E73 -> 0 | F20: =F73 -> 0 | G20: =G73 -> 0 | H20: =H73 -> 0 | I20: =I73 -> 0 | J20: 0 | K20: 0 | L20: 0 | M20: 0 | N20: 0
B23: Income Statement
B24: Reveneue | E24: 1316536 | F24: 1377270 | G24: 1513557 | H24: 1717526 | I24: 1990869 | J24: =I24*(1+J7) -> 2528403.6 | K24: =J24*(1+K7) -> 2907664.2 | L24: =K24*(1+L7) -> 3256583.9 | M24: =L24*(1+M7) -> 3582242.3 | N24: =M24*(1+N7) -> 3868821.6
B25: Cost of Goods Sold (COGS) | E25: 332462 | F25: 302174 | G25: 311053 | H25: 348206 | I25: 353722 | J25: =J24*J8 -> 449226.94 | K25: =K24*K8 -> 516610.98 | L25: =L24*L8 -> 578604.3 | M25: =M24*M8 -> 636464.73 | N25: =N24*N8 -> 687381.91
B26: Gross Profit | E26: =E24-E25 -> 984074 | F26: =F24-F25 -> 1075096 | G26: =G24-G25 -> 1202504 | H26: =H24-H25 -> 1369320 | I26: =I24-I25 -> 1637147 | J26: =J24-J25 -> 2079176.7 | K26: =K24-K25 -> 2391053.2 | L26: =L24-L25 -> 2677979.6 | ... N26: =N24-N25 -> 3181439.7
B27: Expenses
B28: Salaries and Benefits | E28: 396281 | F28: 383863 | G28: 400565 | H28: 462834 | I28: 513028 | J28: =J9 -> 651545.6 | K28: =K9 -> 749277.4 | L28: =L9 -> 839190.7 | M28: =M9 -> 923109.7 | N28: =N9 -> 996958.5
B29: Rent and Overhead | E29: 171231 | F29: 146758 | G29: 159950 | H29: 171940 | I29: 188347 | J29: =J10 -> 239200.7 | K29: =K10 -> 275080.8 | L29: =L10 -> 308090.5 | M29: =M10 -> 338899.5 | N29: =N10 -> 366011.5
B30: Depreciation & Amortization | E30: 25592 | F30: 20465 | G30: 14638 | H30: 13827 | I30: 14952 | J30: =J94 -> 14952 | K30: =K94 -> 22701.456 | L30: =L94 -> 30397.375 | M30: =M94 -> 37918.979 | N30: =N94 -> 45203.074
B31: Interest | E31: 40092 | F31: 68967 | G31: 95546 | H31: 105638 | I31: 133647 | J31: =J101 -> 133647 | K31: =K101 -> 133647 | L31: =L101 -> 133647 | M31: =M101 -> 133647 | N31: =N101 -> 133647
B32: Total Expenses | E32: =SUM(E28:E31) -> 633196 | F32: =SUM(F28:F31) -> 620053 | G32: =SUM(G28:G31) -> 670699 | H32: =SUM(H28:H31) -> 754239 | I32: =SUM(I28:I31) -> 849974 | J32: =SUM(J28:J31) -> 1039345.3 | K32: =SUM(K28:K31) -> 1180706.7 | L32: =SUM(L28:L31) -> 1311325.6 | ... N32: =SUM(N28:N31) -> 1541820.1
B33: Earnings Before Tax | E33: =E26-E32 -> 350878 | F33: =F26-F32 -> 455043 | G33: =G26-G32 -> 531805 | H33: =H26-H32 -> 615081 | I33: =I26-I32 -> 787173 | J33: =J26-J32 -> 1039831.4 | K33: =K26-K32 -> 1210346.5 | L33: =L26-L32 -> 1366654 | ... N33: =N26-N32 -> 1639619.7
B35: Taxes | E35: 81058 | F35: 97768 | G35: 124249 | H35: 129214 | I35: 150649 | J35: =J33*J13 -> 195178.84 | K35: =K33*K13 -> 227184.94 | L35: =L33*L13 -> 256524.22 | M35: =M33*M13 -> 283844 | N35: =N33*N13 -> 307760.53
B36: Net Earnings | E36: =E33-E35 -> 269820 | F36: =F33-F35 -> 357275 | G36: =G33-G35 -> 407556 | H36: =H33-H35 -> 485867 | I36: =I33-I35 -> 636524 | J36: =J33-J35 -> 844652.55 | K36: =K33-K35 -> 983161.6 | L36: =L33-L35 -> 1110129.8 | ... N36: =N33-N35 -> 1331859.1
B39: Balance Sheet
B40: Assets
B41: Cash | E41: 195354 | F41: 133202 | G41: 136778 | H41: 150667 | I41: 134136 | J41: =J78 -> 809209.77 | K41: =K78 -> 1662821.4 | L41: =L78 -> 2651766.4 | M41: =M78 -> 3765823.7 | N41: =N78 -> 4994751.1
B42: Accounts Receivable | E42: 312107 | F42: 322410 | G42: 387947 | H42: 426642 | I42: 529148 | J42: =J24*J15/365 -> 671931.92 | K42: =K24*K15/365 -> 772721.71 | L42: =L24*L15/365 -> 865448.32 | M42: =M24*M15/365 -> 951993.15 | N42: =N24*N15/365 -> 1028152.6
B43: Inventory | E43: 0 | F43: 0 | G43: 0 | H43: 0 | I43: 0 | J43: =J25*J16/365 -> 0 | K43: =K25*K16/365 -> 0 | L43: =L25*L16/365 -> 0 | M43: =M25*M16/365 -> 0 | N43: =N25*N16/365 -> 0
B44: Property & Equipment | E44: 27913 | F44: 17580 | G44: 10966 | H44: 38465 | I44: 67713 | J44: =J95 -> 102807.9 | K44: =K95 -> 137660.34 | L44: =L95 -> 171723.37 | M44: =M95 -> 204710.79 | N44: =N95 -> 236086.62
B45: Total Assets | E45: =SUM(E41:E44) -> 535374 | F45: =SUM(F41:F44) -> 473192 | G45: =SUM(G41:G44) -> 535691 | H45: =SUM(H41:H44) -> 615774 | I45: =SUM(I41:I44) -> 730997 | J45: =SUM(J41:J44) -> 1583949.6 | K45: =SUM(K41:K44) -> 2573203.4 | L45: =SUM(L41:L44) -> 3688938.1 | ... N45: =SUM(N41:N44) -> 6258990.3
B47: Liabilities
...

Sheet DCF Model
A1: © Corporate Finance Institute®. All rights reserved.
B2: DCF Model
B4: Assumptions
B5: Tax Rate (unlevered / on EBIT) | D5: 0.18770239
B6: Discount Rate | D6: 0.096
B7: Perpetural Growth Rate | D7: 0.03
B8: EV/EBITDA Mulltiple | D8: 22
B9: Transaction Date | D9: 45930
B10: Fiscal Year End | D10: 46295
B11: Current Price | D11: 1046.23
B12: Shares Outstanding | D12: 21597.635
B13: Debt | D13: 5582389
B14: Cash | D14: 304537
B15: Capex (FY1 forecast, linked) | D15: ='3 Statement Model'!J68 -> 50046.9
B17: Discounted Cash Flow | D17: Entry | E17: =YEAR(E18) -> 2026 | F17: =YEAR(F18) -> 2027 | G17: =YEAR(G18) -> 2028 | H17: =YEAR(H18) -> 2029 | I17: =YEAR(I18) -> 2030 | J17: Exit | L17: Terminal value methods
B18: Date (mid-year convention) | D18: =D9 -> 45930 | E18: =DATE(YEAR($D$10)+E19,3,31) -> 46112 | F18: =DATE(YEAR($D$10)+F19,3,31) -> 46477 | G18: =DATE(YEAR($D$10)+G19,3,31) -> 46843 | H18: =DATE(YEAR($D$10)+H19,3,31) -> 47208 | I18: =DATE(YEAR($D$10)+I19,3,31) -> 47573 | J18: =I18 -> 47573 | L18: Gordon TV (in J27) — primary | M18: =J27 -> 20872926 | N18: =(I26*(1+D7))/(D6-D7) -> 20872926
B19: Time Periods | E19: 0 | F19: =E19+1 -> 1 | G19: =F19+1 -> 2 | H19: =G19+1 -> 3 | I19: =H19+1 -> 4 | L19: Exit EV/EBITDA cross-check | M19: =($I$21+$I$23)*$D$8 -> 40006334 | N19: =D8*(I21+I23) -> 40006334
B20: Year Fraction (display only; not applied to CF) | E20: =YEARFRAC(D18,E18) -> 0.5 | F20: =YEARFRAC(E18,F18) -> 1 | G20: =YEARFRAC(F18,G18) -> 1 | H20: =YEARFRAC(G18,H18) -> 1 | I20: =YEARFRAC(H18,I18) -> 1 | L20: Implied exit multiple vs Gordon | M20: =IF(($I$21+$I$23)=0,0,J27/($I$21+$I$23)) -> 11.478292 | N20: =AVERAGE(N18:N19) -> 30439630
B21: EBIT (linked to 3-stmt) | E21: ='3 Statement Model'!J26-'3 Statement Model'!J28-'3 Statement Model'!J29-'3 Statement Model'!J30 -> 1173478.4 | F21: ='3 Statement Model'!K26-'3 Statement Model'!K28-'3 Statement Model'!K29-'3 Statement Model'!K30 -> 1343993.5 | G21: ='3 Statement Model'!L26-'3 Statement Model'!L28-'3 Statement Model'!L29-'3 Statement Model'!L30 -> 1500301 | H21: ='3 Statement Model'!M26-'3 Statement Model'!M28-'3 Statement Model'!M29-'3 Statement Model'!M30 -> 1645849.4 | I21: ='3 Statement Model'!N26-'3 Statement Model'!N28-'3 Statement Model'!N29-'3 Statement Model'!N30 -> 1773266.7
B22: Less: Unlevered Cash Taxes (EBIT×t) | E22: =E21*$D$5 -> 220264.7 | F22: =F21*$D$5 -> 252270.8 | G22: =G21*$D$5 -> 281610.08 | H22: =H21*$D$5 -> 308929.86 | I22: =I21*$D$5 -> 332846.39
B23: Plus: D&A (linked to 3-stmt) | E23: ='3 Statement Model'!J30 -> 14952 | F23: ='3 Statement Model'!K30 -> 22701.456 | G23: ='3 Statement Model'!L30 -> 30397.375 | H23: ='3 Statement Model'!M30 -> 37918.979 | I23: ='3 Statement Model'!N30 -> 45203.074
B24: Less: Capex (linked to 3-stmt CF) | E24: ='3 Statement Model'!J68 -> 50046.9 | F24: ='3 Statement Model'!K68 -> 57553.9 | G24: ='3 Statement Model'!L68 -> 64460.4 | H24: ='3 Statement Model'!M68 -> 70906.4 | I24: ='3 Statement Model'!N68 -> 76578.9
B25: Less: ΔNWC (linked to 3-stmt CF) | E25: ='3 Statement Model'!J64 -> 134483.89 | F25: ='3 Statement Model'!K64 -> 94697.533 | G25: ='3 Statement Model'!L64 -> 87121.73 | H25: ='3 Statement Model'!M64 -> 81313.615 | I25: ='3 Statement Model'!N64 -> 71555.981
B26: Unlevered FCF | E26: =E21-E22+E23-E24-E25 -> 783634.91 | F26: =F21-F22+F23-F24-F25 -> 962172.76 | G26: =G21-G22+G23-G24-G25 -> 1097506.2 | H26: =H21-H22+H23-H24-H25 -> 1222618.5 | I26: =I21-I22+I23-I24-I25 -> 1337488.5
B27: (Entry)/Exit TV — Gordon | D27: =-I35 -> -27873946 | J27: =IF(($D$6-$D$7)<=0,"WACC must exceed g",$I$26*(1+$D$7)/($D$6-$D$7)) -> 20872926
B28: Transaction CF | D28: 0 | E28: =E27+E26 -> 783634.91 | F28: =F27+F26 -> 962172.76 | G28: =G27+G26 -> 1097506.2 | H28: =H27+H26 -> 1222618.5 | I28: =I27+I26 -> 1337488.5 | J28: =J27+J26 -> 20872926
B29: Transaction CF | D29: =D27+D26 -> -27873946 | E29: =E27+E26 -> 783634.91 | F29: =F27+F26 -> 962172.76 | G29: =G27+G26 -> 1097506.2 | H29: =H27+H26 -> 1222618.5 | I29: =I27+I26 -> 1337488.5 | J29: =J27 -> 20872926
B31: Intrinsic Value | G31: Market Value | L31: Rate of Return
B32: Enterprise Value (XNPV, mid-year dates) | D32: =XNPV(D6,D28:J28,D18:J18) -> 18048129 | G32: Market Cap | I32: =D12*D11 -> 22596094 | L32: Target Price Upside | N32: =D37/I37-1 -> -0.43484581
B33: Plus: Cash | D33: =+D14 -> 304537 | G33: Plus: Debt | I33: =D13 -> 5582389 | L33: Internal Rate of Return (IRR) | N33: =XIRR(D29:J29,D18:J18) -> -0.01412771
B34: Less: Debt | D34: =+D13 -> 5582389 | G34: Less: Cash | I34: =+D14 -> 304537
B35: Equity Value | D35: =D32+D33-D34 -> 12770277 | G35: Enterprise Value | I35: =I32+I33-I34 -> 27873946 | L35: Market Value vs Intrinsic Value
L36: Market Value | N36: =I37 -> 1046.23
B37: Equity Value/Share | D37: =D35/D12 -> 591.28127 | G37: Equity Value/Share | I37: =D11 -> 1046.23 | L37: Upside | N37: =D37-I37 -> -454.94873
L38: Intrinsic Value | N38: =SUM(N36:N37) -> 591.28127
B41: Instructions
B42: Step 1: Get EBIT and D&A from the income statement | N42: This file is for educational purposes only. E&OE
B43: Step 2: Calculate the net working capital
B44: There are two ways to find NWC:
B45: 1. NWC = Current Assets (less cash) - Current Liabilities (less debt)
...
