Workbook
Name ASSUM_APDays_Start: '3 Statement Model'!$J$17
Name ASSUM_ARDays_Start: '3 Statement Model'!$J$15
Name ASSUM_Capex_Start: '3 Statement Model'!$J$18
Name ASSUM_COGSPct_Start: '3 Statement Model'!$J$8
Name ASSUM_DAPctPPE_Start: '3 Statement Model'!$J$11
Name ASSUM_DebtIssuance_Start: '3 Statement Model'!$J$19
Name ASSUM_EquityIssuance_Start: '3 Statement Model'!$J$20
Name ASSUM_IntPct_Start: '3 Statement Model'!$J$12
Name ASSUM_InvDays_Start: '3 Statement Model'!$J$16
Name ASSUM_RD_Start: '3 Statement Model'!$J$10
Name ASSUM_RevGrowth_Start: '3 Statement Model'!$J$7
Name ASSUM_SGA_Start: '3 Statement Model'!$J$9
Name ASSUM_TaxRate_Start: '3 Statement Model'!$J$13
Name BS_AP_Start: '3 Statement Model'!$E$48
Name BS_AR_Start: '3 Statement Model'!$E$42
Name BS_Cash_Start: '3 Statement Model'!$E$41
Name BS_Debt_Start: '3 Statement Model'!$E$49
Name BS_EquityCapital_Start: '3 Statement Model'!$E$52
Name BS_Inventory_Start: '3 Statement Model'!$E$43
Name BS_PPE_Start: '3 Statement Model'!$E$44
Name BS_RE_Start: '3 Statement Model'!$E$53
Name CF_Capex_Start: '3 Statement Model'!$E$68
Name CF_DebtIssuance_Start: '3 Statement Model'!$E$72
Name CF_DeltaNWC_Start: '3 Statement Model'!$E$65
Name CF_EquityIssuance_Start: '3 Statement Model'!$E$73
Name CF_OpeningCash_FY1: '3 Statement Model'!$D$78
Name DCF_Cash: 'DCF Model'!$D$14
Name DCF_Debt: 'DCF Model'!$D$13
Name DCF_ExitMultiple: 'DCF Model'!$D$8
Name DCF_FiscalYearEnd: 'DCF Model'!$D$10
Name DCF_PerpetualGrowth: 'DCF Model'!$D$7
Name DCF_SharePrice: 'DCF Model'!$D$11
Name DCF_Shares: 'DCF Model'!$D$12
Name DCF_TaxRate: 'DCF Model'!$D$5
Name DCF_TransactionDate: 'DCF Model'!$D$9
Name DCF_WACC: 'DCF Model'!$D$6
Name Forecast: #REF!
Name IS_BaseYear: '3 Statement Model'!$E$2
Name IS_COGS_FY1: '3 Statement Model'!$E$25
Name IS_COGS_FY2: '3 Statement Model'!$F$25
Name IS_COGS_FY3: '3 Statement Model'!$G$25
Name IS_COGS_FY4: '3 Statement Model'!$H$25
Name IS_COGS_FY5: '3 Statement Model'!$I$25
Name IS_COGS_Start: '3 Statement Model'!$E$25
Name IS_DA_Start: '3 Statement Model'!$E$30
Name IS_Interest_Start: '3 Statement Model'!$E$31
Name IS_RD_Start: '3 Statement Model'!$E$29
Name IS_Revenue_FY1: '3 Statement Model'!$E$24
Name IS_Revenue_FY2: '3 Statement Model'!$F$24
Name IS_Revenue_FY3: '3 Statement Model'!$G$24
Name IS_Revenue_FY4: '3 Statement Model'!$H$24
Name IS_Revenue_FY5: '3 Statement Model'!$I$24
Name IS_Revenue_Start: '3 Statement Model'!$E$24
Name IS_SGA_Start: '3 Statement Model'!$E$28
Name IS_Tax_Start: '3 Statement Model'!$E$35
Name Step_1: #REF!
Name Step_2: #REF!
Name Step_3: #REF!
Name Step_4: #REF!
Name Step_5: #REF!

Sheet Cover Page
C12: FICO — vengeanceaiUSCMODEL18.0 (3-Statement + DCF) | E12: =HYPERLINK("https://raw.githubusercontent.com/vengeanceaiUSC/Rainmaker/cursor/vengeanceaiusmodel18-d3ac/FICO/output/MODEL18_FICO_ASSUMPTIONS_LIST.pdf","⬇ ASSUMPTIONS PDF") -> ⬇ ASSUMPTIONS PDF | N12: Strictly Confidential
C13: =HYPERLINK("https://raw.githubusercontent.com/vengeanceaiUSC/Rainmaker/cursor/vengeanceaiusmodel18-d3ac/FICO/output/MODEL18_FICO_ASSUMPTIONS_LIST.pdf","⬇ CLICK HERE — DOWNLOAD ASSUMPTIONS LIST PDF (NO CHARTS)") -> ⬇ CLICK HERE — DOWNLOAD ASSUMPTIONS LIST PDF (NO CHARTS)
C14: Table of Contents
C15: 3 Statement Model
C19: Notes
C20: Named Ranges mark INPUT cells only. Formula cells (Gross Profit, NI, UFCF, EV) have NO names and must never be overwritten. Open in Excel to recalculate.
C21: vengeanceaiUSCMODEL18.0: MODEL17=7.0/10; stub 64.7% of Y1 FCFF from 2026-08-06; WACC Yacktman-adj 7.68% (β 0.854); SBC 7%/6%/6%/6%/5%; SaaS +300bps; exit 23.0x; shares 21.6M @ $1,149. ASSUMPTIONS PDF DOWNLOAD is the orange banner on Cover row 13 (C13). Also listed in Source Index (cols E–G).
C22: =HYPERLINK("https://raw.githubusercontent.com/vengeanceaiUSC/Rainmaker/cursor/vengeanceaiusmodel18-d3ac/FICO/output/MODEL18_FICO_ASSUMPTIONS_LIST.pdf","⬇ DOWNLOAD ASSUMPTIONS LIST PDF — CLICK THIS LINK") -> ⬇ DOWNLOAD ASSUMPTIONS LIST PDF — CLICK THIS LINK
C23: =HYPERLINK("https://raw.githubusercontent.com/vengeanceaiUSC/Rainmaker/cursor/vengeanceaiusmodel18-d3ac/FICO/output/MODEL18_FICO_ASSUMPTIONS_LIST.pdf","https://raw.githubusercontent.com/vengeanceaiUSC/Rainmaker/cursor/vengeanceaiusmodel18-d3ac/FICO/output/MODEL18_FICO_ASSUMPTIONS_LIST.pdf") -> https://raw.githubusercontent.com/vengeanceaiUSC/Rainmaker/cursor/vengeanceaiusmodel18-d3ac/FICO/output/MODEL18_FICO_ASSUMPTIONS_LIST.pdf
C24: © 2019 CFI Education Inc. | E24: vengeanceaiUSCMODEL18.0 — SOURCE INDEX (click any link)
C25: All rights reserved. The contents of this publication, including but not limited to all written material, content layout, images, formulas, and code, are protected under international copyright and trademark laws. | E25: Every assumption / WACC / filing source used in this workbook. Same links appear on 3-statement col U/V and DCF col U/V.
C26: No part of this publication may be modified, manipulated, reproduced, distributed, or transmitted in any form by any means, including photocopying, recording, or other electronic or mechanical methods, | E26: Source | F26: Clickable link | G26: URL
C27: without prior written permission of the publisher, except in the case of certain noncommercial uses permitted by copyright law. | E27: 10-K FY2025 | F27: 10-K FY2025 | G27: https://www.sec.gov/Archives/edgar/data/814547/000081454725000030/fico-20250930.htm
E28: 10-Q Q3 FY2026 | F28: 10-Q Q3 FY2026 | G28: https://www.sec.gov/Archives/edgar/data/814547/000081454726000030/fico-20260630.htm
E29: 8-K 6.250% notes | F29: 8-K 6.250% notes | G29: https://www.sec.gov/Archives/edgar/data/814547/000119312526117936/d56220d8k.htm
E30: Blume (1971) — beta adjustment toward 1.0 | F30: Blume (1971) — beta adjustment toward 1.0 | G30: https://www.jstor.org/stable/2329867
E31: Damodaran ERP | F31: Damodaran ERP | G31: https://pages.stern.nyu.edu/adamodar/New_Home_Page/home.htm
E32: Damodaran EV/EBITDA by sector | F32: Damodaran EV/EBITDA by sector | G32: https://pages.stern.nyu.edu/adamodar/New_Home_Page/datafile/vebitda.htm
E33: Damodaran FCFF | F33: Damodaran FCFF | G33: https://pages.stern.nyu.edu/~adamodar/New_Home_Page/datafile/histfcff.html
E34: Damodaran Implied ERP | F34: Damodaran Implied ERP | G34: https://pages.stern.nyu.edu/adamodar/New_Home_Page/home.htm
E35: Damodaran implied ERP table | F35: Damodaran implied ERP table | G35: https://pages.stern.nyu.edu/~adamodar/New_Home_Page/datafile/histimpl.html
E36: Equifax statement — FICO 2026 2x mortgage royalty | F36: Equifax statement — FICO 2026 2x mortgage royalty | G36: https://www.equifax.com/newsroom/all-news/-/story/equifax-statement-on-fico-2x-price-increase-for-2026-and-mortgage-direct-license-program/
E37: FICO EV/EBITDA (Alpha Spread) | F37: FICO EV/EBITDA (Alpha Spread) | G37: https://www.alphaspread.com/security/nyse/fico/relative-valuation/ratio/enterprise-value-to-ebitda
E38: FICO IR | F38: FICO IR | G38: https://www.fico.com/en/investors
E39: FICO IR investor presentation — Scores OM ~91% | F39: FICO IR investor presentation — Scores OM ~91% | G39: https://investors.fico.com/static-files/66ef723c-1f2e-4501-a452-ab2f3d02ae85
... E64: companyfacts | F64: companyfacts | G64: https://data.sec.gov/api/xbrl/companyfacts/CIK0000814547.json

Sheet 3 Statement Model
B1: © Corporate Finance Institute®. All rights reserved. | E1: Historical Results | J1: Forecast Period
B2: FINANCIAL STATEMENTS | E2: 2021 | F2: =+E2+1 -> 2022 | G2: =+F2+1 -> 2023 | H2: =+G2+1 -> 2024 | I2: =+H2+1 -> 2025 | J2: =+I2+1 -> 2026 | K2: =+J2+1 -> 2027 | L2: =+K2+1 -> 2028 | M2: =+L2+1 -> 2029 | N2: =+M2+1 -> 2030
B3: Balance Sheet Check | E3: =IFERROR(IF(ABS(E57)>0.5,"ERROR","OK"),"OK") -> OK | F3: =IFERROR(IF(ABS(F57)>0.5,"ERROR","OK"),"OK") -> OK | G3: =IFERROR(IF(ABS(G57)>0.5,"ERROR","OK"),"OK") -> OK | H3: =IFERROR(IF(ABS(H57)>0.5,"ERROR","OK"),"OK") -> OK | I3: =IFERROR(IF(ABS(I57)>0.5,"ERROR","OK"),"OK") -> OK | J3: =IFERROR(IF(ABS(J57)>0.5,"ERROR","OK"),"OK") -> OK | K3: =IFERROR(IF(ABS(K57)>0.5,"ERROR","OK"),"OK") -> OK | L3: =IFERROR(IF(ABS(L57)>0.5,"ERROR","OK"),"OK") -> OK | ... N3: =IFERROR(IF(ABS(N57)>0.5,"ERROR","OK"),"OK") -> OK
A4: =HYPERLINK("https://raw.githubusercontent.com/vengeanceaiUSC/Rainmaker/cursor/vengeanceaiusmodel18-d3ac/FICO/output/MODEL18_FICO_ASSUMPTIONS_LIST.pdf","⬇ Download Assumptions List PDF") -> ⬇ Download Assumptions List PDF | B4: vengeanceaiUSCMODEL18.0: hover J–N for WHY+SOURCE; col U = filing source; col W = download Assumptions List PDF (no charts) | P4: =HYPERLINK("https://raw.githubusercontent.com/vengeanceaiUSC/Rainmaker/cursor/vengeanceaiusmodel18-d3ac/FICO/output/MODEL18_FICO_ASSUMPTIONS_LIST.pdf","ASSUMPTIONS EXPLAINED — click blue Source (col U) for the filing/data") -> ASSUMPTIONS EXPLAINED — click blue Source (col U) for the filing/data
B5: Assumptions | P5: Yellow = policy. Green = FY25-linked equations. Orange title above = click to download the Assumptions List PDF (no charts). PDF: https://raw.githubusercontent.com/vengeanceaiUSC/Rainmaker/cursor/vengeanceaiusmodel18-d3ac/FICO/output/MODEL18_FICO_ASSUMPTIONS_LIST.pdf
B6: Income statement | P6: Row | Q6: Assumption | R6: What it is | S6: How set in model | T6: Why this choice | U6: Source (click) | V6: Source URL
B7: Revenue Growth (% Change) | C7: WHY: Revenue growth path unchanged vs Model17 (30%/18%/14.5%/11%/8.5%). DCF applies stub scaling to Y1 FCFF only — 3S stil… | SOURCE: SEC EX-99.1 Q3 FY2026 — Scores +41% / B2B +49%; FY2026 guidance | LINK: https://www.sec.gov/Archives/edgar/data/814547/000081454726000031/exhibit991erq32026.htm | HOW: Yellow POLICY input: 30.0% / 18.0% / 14.5% / 11.0% / 8.5%. | ASSUMPTIONS PDF: https://raw.githubusercontent.com/vengeanceaiUSC/Rainmaker/cursor/vengeanceaiusmodel18-d3ac/FICO/output/MODEL18_FICO_ASSUMPTIONS_LIST.pdf | F7: =F24/E24-1 -> 0.046131667 | G7: =G24/F24-1 -> 0.098954453 | H7: =H24/G24-1 -> 0.13476136 | I7: =I24/H24-1 -> 0.15914926 | J7: 0.3 | K7: 0.18 | L7: 0.145 | M7: 0.11 | N7: 0.085 | P7: 7 | Q7: Revenue Growth | R7: Year-over-year % increase in revenue for each forecast year. | S7: Yellow POLICY input: 30.0% / 18.0% / 14.5% / 11.0% / 8.5%. | T7: Revenue growth path unchanged vs Model17 (30%/18%/14.5%/11%/8.5%). DCF applies stub scaling to Y1 FCFF only — 3S still builds a full fiscal year for BS integrity. | U7: =HYPERLINK("https://www.sec.gov/Archives/edgar/data/814547/000081454726000031/exhibit991erq32026.htm","SEC EX-99.1 Q3 FY2026 — Scores +41% / B2B +49%; FY2026 guidance") -> SEC EX-99.1 Q3 FY2026 — Scores +41% / B2B +49%; FY2026 guidance | V7: =HYPERLINK("https://www.sec.gov/Archives/edgar/data/814547/000081454726000031/exhibit991erq32026.htm","https://www.sec.gov/Archives/edgar/data/814547/000081454726000031/exhibit991erq32026.htm") -> https://www.sec.gov/Archives/edgar/data/814547/000081454726000031/exhibit991erq32026.htm
B8: COGS % of Revenue (floor 8%; −120bps×t Scores pricing) | C8: WHY: MODEL18 Yacktman: Margins unchanged vs Model17 (COGS −120 / SG&A −175 / R&D −50; floor 8%; GM_B2B 97%). Mix % offset … | SOURCE: SEC 10-K FY2025 — Scores +$249M YoY 'primarily attributable to a higher unit price' | LINK: https://www.sec.gov/Archives/edgar/data/814547/000081454725000030/fico-20250930.htm | HOW: Excel: MAX(8%, segment blended COGS base≈12.98% − 120bps × year). | ASSUMPTIONS PDF: https://raw.githubusercontent.com/vengeanceaiUSC/Rainmaker/cursor/vengeanceaiusmodel18-d3ac/FICO/output/MODEL18_FICO_ASSUMPTIONS_LIST.pdf | E8: =E25/E24 -> 0.25252785 | F8: =F25/F24 -> 0.2194007 | G8: =G25/G24 -> 0.20551126 | H8: =H25/H24 -> 0.20273696 | I8: =I25/I24 -> 0.17767216 | J8: =MAX(0.08,J122-0.012) -> 0.11661353 | K8: =MAX(0.08,K122-0.024) -> 0.10341353 | L8: =MAX(0.08,L122-0.036) -> 0.090213529 | M8: =MAX(0.08,M122-0.048) -> 0.08 | N8: =MAX(0.08,N122-0.06) -> 0.08 | P8: 8 | Q8: COGS % of Revenue | R8: Cost of revenues as a % of sales (gross margin = 1 − this). | S8: Excel: MAX(8%, segment blended COGS base≈12.98% − 120bps × year). | T8: Model 18 keeps previous profit assumptions. Yearly, product costs drop 1.2% (stopping at an 8% floor), overhead drops 1.75%, and R&D drops 0.5%. Sales percentages shift within one revenue forecast. | U8: =HYPERLINK("https://www.sec.gov/Archives/edgar/data/814547/000081454725000030/fico-20250930.htm","SEC 10-K FY2025 — Scores +$249M YoY 'primarily attributable to a higher unit price'") -> SEC 10-K FY2025 — Scores +$249M YoY 'primarily attributable to a higher unit price' | V8: =HYPERLINK("https://www.sec.gov/Archives/edgar/data/814547/000081454725000030/fico-20250930.htm","https://www.sec.gov/Archives/edgar/data/814547/000081454725000030/fico-20250930.htm") -> https://www.sec.gov/Archives/edgar/data/814547/000081454725000030/fico-20250930.htm
B9: SG&A % of Revenue (floor 14%, −175bps×t) | C9: WHY: SG&A unchanged vs Model17 (−175 bps/yr, floor 14%) — Scores near-100% incremental margins. | SOURCE: SEC 10-K FY2025 — SG&A + Scores pricing commentary | LINK: https://www.sec.gov/Archives/edgar/data/814547/000081454725000030/fico-20250930.htm | HOW: Equation: MAX(14%, (I28 − 10,922)/I24 − 175bps × year). Strips FY25 restructuring; then −1.75% of sales each year. | ASSUMPTIONS PDF: https://raw.githubusercontent.com/vengeanceaiUSC/Rainmaker/cursor/vengeanceaiusmodel18-d3ac/FICO/output/MODEL18_FICO_ASSUMPTIONS_LIST.pdf | E9: =E28 -> 396281 | F9: =F28 -> 383863 | G9: =G28 -> 400565 | H9: =H28 -> 462834 | I9: =I28 -> 513028 | J9: =MAX(0.14,(($I$28-10922)/$I$24)-0.0175) -> 0.23470444 | K9: =MAX(0.14,(($I$28-10922)/$I$24)-0.035) -> 0.21720444 | L9: =MAX(0.14,(($I$28-10922)/$I$24)-0.0525) -> 0.19970444 | M9: =MAX(0.14,(($I$28-10922)/$I$24)-0.07) -> 0.18220444 | N9: =MAX(0.14,(($I$28-10922)/$I$24)-0.0875) -> 0.16470444 | P9: 9 | Q9: SG&A % of Revenue | R9: Operating opex (SG&A) as % of sales. | S9: Yes, it's reasonable. The formula removes a one-time $10.9 million restructuring fee from last year's overhead. Then, it realistically shrinks future overhead by 1.75% annually, stopping at a 14% floor. | T9: Yes, it is reasonable. In the model, SG&A dropped from 30.1% of revenue in 2021 to 25.8% in 2025. This proves the historical trend of increasing efficiency. wait is that around 175 BSP yearly? This is capped to 14% | U9: =HYPERLINK("https://www.sec.gov/Archives/edgar/data/814547/000081454725000030/fico-20250930.htm","SEC 10-K FY2025 — SG&A + Scores pricing commentary") -> SEC 10-K FY2025 — SG&A + Scores pricing commentary | V9: =HYPERLINK("https://www.sec.gov/Archives/edgar/data/814547/000081454725000030/fico-20250930.htm","https://www.sec.gov/Archives/edgar/data/814547/000081454725000030/fico-20250930.htm") -> https://www.sec.gov/Archives/edgar/data/814547/000081454725000030/fico-20250930.htm
B10: R&D % of Revenue (floor 7%, −50bps×t) | C10: WHY: R&D unchanged vs Model17 (−50 bps/yr, floor 7%) — royalty price dollars do not require 1:1 R&D. | SOURCE: SEC 10-K FY2025 — Research and development | LINK: https://www.sec.gov/Archives/edgar/data/814547/000081454725000030/fico-20250930.htm | HOW: Excel: MAX(7%, I29/I24 − 50bps × year). | ASSUMPTIONS PDF: https://raw.githubusercontent.com/vengeanceaiUSC/Rainmaker/cursor/vengeanceaiusmodel18-d3ac/FICO/output/MODEL18_FICO_ASSUMPTIONS_LIST.pdf | E10: =E29 -> 171231 | F10: =F29 -> 146758 | G10: =G29 -> 159950 | H10: =H29 -> 171940 | I10: =I29 -> 188347 | J10: =MAX(0.07,$I$29/$I$24-0.005) -> 0.089605421 | K10: =MAX(0.07,$I$29/$I$24-0.01) -> 0.084605421 | L10: =MAX(0.07,$I$29/$I$24-0.015) -> 0.079605421 | M10: =MAX(0.07,$I$29/$I$24-0.02) -> 0.074605421 | N10: =MAX(0.07,$I$29/$I$24-0.025) -> 0.07 | P10: 10 | Q10: R&D % of Revenue | R10: Research & development expense as % of sales (IS label: R&D, not Rent). | S10: This formula reduces R&D costs by 0.5% of total revenue each year as the company scales. The MAX function ensures that these expenses never drop below a hard 7% floor. | T10: Yes. From 2021 to 2025, FICO's R&D dropped from 13.0% to 9.5% of revenue, averaging an 89 bps annual decline. Your 50 bps projected reduction is realistic and conservative. | U10: =HYPERLINK("https://www.sec.gov/Archives/edgar/data/814547/000081454725000030/fico-20250930.htm","SEC 10-K FY2025 — Research and development") -> SEC 10-K FY2025 — Research and development | V10: =HYPERLINK("https://www.sec.gov/Archives/edgar/data/814547/000081454725000030/fico-20250930.htm","https://www.sec.gov/Archives/edgar/data/814547/000081454725000030/fico-20250930.htm") -> https://www.sec.gov/Archives/edgar/data/814547/000081454725000030/fico-20250930.htm
B11: D&A % of Revenue (TOTAL D&A incl. amort. of intangibles — CF add-back) | C11: WHY: MODEL18: TOTAL D&A ≈ 0.84% of Rev. SBC is a SEPARATE add-back — no double-count. | SOURCE: SEC companyfacts — DepreciationDepletionAndAmortization (+ AmortizationOfIntangibleAssets) | LINK: https://data.sec.gov/api/xbrl/companyfacts/CIK0000814547.json | HOW: Yellow POLICY input: flat 0.84% (3yr FY23–25 avg TOTAL D&A). Forecast DA$ = Revenue × DA%; CF row 63 adds it back once. | ASSUMPTIONS PDF: https://raw.githubusercontent.com/vengeanceaiUSC/Rainmaker/cursor/vengeanceaiusmodel18-d3ac/FICO/output/MODEL18_FICO_ASSUMPTIONS_LIST.pdf | E11: =E30/E92 -> 0.55132597 | F11: =F30/F92 -> 0.73317092 | G11: =G30/G92 -> 0.83265074 | H11: =H30/H92 -> 1.2608973 | I11: =I30/I92 -> 0.38871702 | J11: 0.008411 | K11: 0.008411 | L11: 0.008411 | M11: 0.008411 | N11: 0.008411 | P11: 11 | Q11: D&A % of Revenue | R11: Total depreciation & amortization as % of sales (software-industry driver). | S11: flat 0.84% (3yr FY23–25 avg TOTAL D&A). Depreciation costs stay fixed at 0.84% of total revenue based on past averages, and are added back to cash flow. | T11: FICO’s asset-light model needs minimal capital, so non-cash D&A predictably stays flat at its 0.84% historical revenue average. | U11: =HYPERLINK("https://data.sec.gov/api/xbrl/companyfacts/CIK0000814547.json","SEC companyfacts — DepreciationDepletionAndAmortization (+ AmortizationOfIntangibleAssets)") -> SEC companyfacts — DepreciationDepletionAndAmortization (+ AmortizationOfIntangibleAssets) | V11: =HYPERLINK("https://data.sec.gov/api/xbrl/companyfacts/CIK0000814547.json","https://data.sec.gov/api/xbrl/companyfacts/CIK0000814547.json") -> https://data.sec.gov/api/xbrl/companyfacts/CIK0000814547.json
B12: Interest (% of Debt Open Bal) | C12: WHY: Approximates average coupon / cost of debt on the book. Debt stock follows the net debt issuance assumption (row 19). | SOURCE: SEC 10-K FY2025 — Interest expense; see also 8-K 6.250% notes | LINK: https://www.sec.gov/Archives/edgar/data/814547/000081454725000030/fico-20250930.htm | HOW: Excel equation: I101/I98 (FY25 interest ÷ FY25 opening debt in schedule). | ASSUMPTIONS PDF: https://raw.githubusercontent.com/vengeanceaiUSC/Rainmaker/cursor/vengeanceaiusmodel18-d3ac/FICO/output/MODEL18_FICO_ASSUMPTIONS_LIST.pdf | E12: =E101/E98 -> 0.054219776 | F12: =F101/F98 -> 0.054778407 | G12: =G101/G98 -> 0.051544262 | H12: =H101/H98 -> 0.056744042 | I12: =I101/I98 -> 0.060500557 | J12: =IF($I$98=0,0.05,$I$101/$I$98) -> 0.060500557 | K12: =IF($I$98=0,0.05,$I$101/$I$98) -> 0.060500557 | L12: =IF($I$98=0,0.05,$I$101/$I$98) -> 0.060500557 | M12: =IF($I$98=0,0.05,$I$101/$I$98) -> 0.060500557 | N12: =IF($I$98=0,0.05,$I$101/$I$98) -> 0.060500557 | P12: 12 | Q12: Interest % of Debt Open | R12: Interest expense as % of opening debt balance. | S12: Yes. The 6.1% rate is straight-lined across all forecast years because it directly reflects FICO's actual FY2025 effective interest rate (FY25 interest divided by opening debt). | T12: Assume a flat 6.1% interest rate based on FY25's effective cost of debt. Future interest expense scales as net debt issuances fluctuate to fund leveraged share buybacks. | U12: =HYPERLINK("https://www.sec.gov/Archives/edgar/data/814547/000081454725000030/fico-20250930.htm","SEC 10-K FY2025 — Interest expense; see also 8-K 6.250% notes") -> SEC 10-K FY2025 — Interest expense; see also 8-K 6.250% notes | V12: =HYPERLINK("https://www.sec.gov/Archives/edgar/data/814547/000081454725000030/fico-20250930.htm","https://www.sec.gov/Archives/edgar/data/814547/000081454725000030/fico-20250930.htm") -> https://www.sec.gov/Archives/edgar/data/814547/000081454725000030/fico-20250930.htm
B13: Tax Rate (% of Earnings Before Tax) | C13: WHY: Book rate (~19%) remains on the income statement. DCF unlevered cash taxes use a separate cash tax rate (22.87% = 3yr… | SOURCE: SEC 10-K FY2025 — tax expense; cash taxes from IncomeTaxesPaidNet | LINK: https://data.sec.gov/api/xbrl/companyfacts/CIK0000814547.json | HOW: Excel equation: I35/I33 (FY25 tax ÷ simplified FY25 EBT in this template). | ASSUMPTIONS PDF: https://raw.githubusercontent.com/vengeanceaiUSC/Rainmaker/cursor/vengeanceaiusmodel18-d3ac/FICO/output/MODEL18_FICO_ASSUMPTIONS_LIST.pdf | E13: =E35/E33 -> 0.23101477 | F13: =F35/F33 -> 0.21485442 | G13: =G35/G33 -> 0.23363639 | H13: =H35/H33 -> 0.2100764 | I13: =I35/I33 -> 0.19137979 | J13: =IF($I$33=0,0.21,$I$35/$I$33) -> 0.19137979 | K13: =IF($I$33=0,0.21,$I$35/$I$33) -> 0.19137979 | L13: =IF($I$33=0,0.21,$I$35/$I$33) -> 0.19137979 | M13: =IF($I$33=0,0.21,$I$35/$I$33) -> 0.19137979 | N13: =IF($I$33=0,0.21,$I$35/$I$33) -> 0.19137979 | P13: 13 | Q13: Book Tax Rate (% of EBT) | R13: Effective book tax rate applied to forecast EBT → Net Income. | S13: The equation calculates the 19.1% tax rate flatlined | T13: by dividing FY25 income tax expense by FY25 earnings before taxes, then holds this 19.1% rate flat for all future forecast years. Commentary: NO My 3 Statement straightlines 19.1% but we have 22.87% on the DCF explain: built the DCF on the 22.87% 3-year cash tax average. The 3-year cash tax average covers FY2023, FY2024, and FY2025 (FY23–FY25). | U13: =HYPERLINK("https://data.sec.gov/api/xbrl/companyfacts/CIK0000814547.json","SEC 10-K FY2025 — tax expense; cash taxes from IncomeTaxesPaidNet") -> SEC 10-K FY2025 — tax expense; cash taxes from IncomeTaxesPaidNet | V13: =HYPERLINK("https://data.sec.gov/api/xbrl/companyfacts/CIK0000814547.json","https://data.sec.gov/api/xbrl/companyfacts/CIK0000814547.json") -> https://data.sec.gov/api/xbrl/companyfacts/CIK0000814547.json
B14: Balance Sheet
B15: DSO — phased 97→28d over 5yrs (segment blend ref ≈ 27.5d @ row 115; AR=Rev×DSO/365) | C15: WHY: DSO path unchanged vs Model17 (97→28d). DSO path unchanged vs Model17 (97→28d). Op NWC = AR+Inv−AP ONLY. +ΔDeferred i… | SOURCE: SEC 10-K FY2025 — AR; Q1 FY2026 deferred detail (R45) | LINK: https://www.sec.gov/Archives/edgar/data/814547/000081454726000011/R45.htm | HOW: Yellow POLICY path: phases 97d (FY25 hist) → 28d over 5 years (Y1≈83.2d … Y5=28d). Segment blend ref ≈ 27.5d on schedule row 115 (SaaS 40/B2C 2/B2B 25/PS 12/On-prem 40). | ASSUMPTIONS PDF: https://raw.githubusercontent.com/vengeanceaiUSC/Rainmaker/cursor/vengeanceaiusmodel18-d3ac/FICO/output/MODEL18_FICO_ASSUMPTIONS_LIST.pdf | E15: =E42/E24*365 -> 86.529388 | F15: =F42/F24*365 -> 85.444139 | G15: =G42/G24*365 -> 93.554888 | H15: =H42/H24*365 -> 90.667815 | I15: =I42/I24*365 -> 97.01242 | J15: 83.2 | K15: 69.4 | L15: 55.6 | M15: 41.8 | N15: 28 | P15: 15 | Q15: DSO — Accounts Receivable (Days) | R15: Days Sales Outstanding. AR = Revenue × DSO / 365. | S15: Yellow POLICY path: phases 97d (FY25 hist) → 28d over 5 years (Y1≈83.2d … Y5=28d). Segment blend ref ≈ 27.5d on schedule row 115 (SaaS 40/B2C 2/B2B 25/PS 12/On-prem 40). | T15: FY 2025 used had 97 DSO, however we averaged. Historical 97 days included legacy multi-year software contract billings and unbilled accruals, while subsegment targets reflect steady-state standard payment terms. Historical 97 days included legacy multi-year software contract billings and unbilled accruals, while subsegment targets reflect steady-state standard payment terms. (SaaS 40/B2C 2/B2B 25/PS 12/On-prem 40). SIDE:NOTE: Op NWC = AR+Inv−AP ONLY. +ΔDeferred is a SEPARATE CFO/FCFF source. No AR/unearned double-count. Source: https://www.sec.gov/Archives/edgar/data/814547/000081454726000011/R45.htm. Deferred = Rev × (SaaS%+OnPrem%) × (FY25 Def/FY25 soft Rev); +ΔDeferred in CFO row 81. Faster SaaS mix (+300 bps/yr) raises Deferred cash vs Model17 (+250). Detail: https://www.sec.gov/Archives/edgar/data/814547/000081454726000011/R45.htm. wait we should include the math equations there | U15: =HYPERLINK("https://www.sec.gov/Archives/edgar/data/814547/000081454726000011/R45.htm","SEC 10-K FY2025 — AR; Q1 FY2026 deferred detail (R45)") -> SEC 10-K FY2025 — AR; Q1 FY2026 deferred detail (R45) | V15: =HYPERLINK("https://www.sec.gov/Archives/edgar/data/814547/000081454726000011/R45.htm","https://www.sec.gov/Archives/edgar/data/814547/000081454726000011/R45.htm") -> https://www.sec.gov/Archives/edgar/data/814547/000081454726000011/R45.htm
B16: Inventory (Days) | C16: WHY: No inventory cycle to fund. | SOURCE: SEC 10-K FY2025 — Inventory ≈ $0 | LINK: https://www.sec.gov/Archives/edgar/data/814547/000081454725000030/fico-20250930.htm | HOW: Hard zero — FICO is software / scores; inventory is immaterial. | ASSUMPTIONS PDF: https://raw.githubusercontent.com/vengeanceaiUSC/Rainmaker/cursor/vengeanceaiusmodel18-d3ac/FICO/output/MODEL18_FICO_ASSUMPTIONS_LIST.pdf | E16: =E43/E25*365 -> 0 | F16: =F43/F25*365 -> 0 | G16: =G43/G25*365 -> 0 | H16: =H43/H25*365 -> 0 | I16: =I43/I25*365 -> 0 | J16: 0 | K16: 0 | L16: 0 | M16: 0 | N16: 0 | P16: 16 | Q16: Inventory (Days) | R16: Inventory days (Inv = COGS × days/365). | S16: Hard zero — FICO is software / scores; inventory is immaterial. | T16: No inventory cycle to fund. | U16: =HYPERLINK("https://www.sec.gov/Archives/edgar/data/814547/000081454725000030/fico-20250930.htm","SEC 10-K FY2025 — Inventory ≈ $0") -> SEC 10-K FY2025 — Inventory ≈ $0 | V16: =HYPERLINK("https://www.sec.gov/Archives/edgar/data/814547/000081454725000030/fico-20250930.htm","https://www.sec.gov/Archives/edgar/data/814547/000081454725000030/fico-20250930.htm") -> https://www.sec.gov/Archives/edgar/data/814547/000081454725000030/fico-20250930.htm
B17: DPO — Accounts Payable (Days) [AP = COGS × DPO/365] | C17: WHY: MODEL18: DPO pairs with phased DSO for Op NWC = AR+Inv−AP. Deferred is a SEPARATE CFO cash source (row 81) — never mi… | SOURCE: SEC 10-K FY2025 — Accounts payable | LINK: https://www.sec.gov/Archives/edgar/data/814547/000081454725000030/fico-20250930.htm | HOW: Excel equation: ROUND(I48/I25×365, 0) from FY25; held flat. | ASSUMPTIONS PDF: https://raw.githubusercontent.com/vengeanceaiUSC/Rainmaker/cursor/vengeanceaiusmodel18-d3ac/FICO/output/MODEL18_FICO_ASSUMPTIONS_LIST.pdf | E17: =E48/E25*365 -> 22.779701 | F17: =F48/F25*365 -> 20.864287 | G17: =G48/G25*365 -> 22.305797 | H17: =H48/H25*365 -> 23.556874 | I17: =I48/I25*365 -> 33.345325 | J17: =IF($I$25=0,0,ROUND($I$48/$I$25*365,0)) -> 33 | K17: =IF($I$25=0,0,ROUND($I$48/$I$25*365,0)) -> 33 | L17: =IF($I$25=0,0,ROUND($I$48/$I$25*365,0)) -> 33 | M17: =IF($I$25=0,0,ROUND($I$48/$I$25*365,0)) -> 33 | N17: =IF($I$25=0,0,ROUND($I$48/$I$25*365,0)) -> 33 | P17: 17 | Q17: DPO — Accounts Payable (Days) | R17: Days Payable Outstanding. AP = COGS × DPO / 365. | S17: Excel equation: ROUND(I48/I25×365, 0) from FY25; held flat. | T17: DPO is held flat at 33 days because FICO's FY25 actuals equaled 33.3 days. This reflects stable, standardized vendor payment terms, allowing Accounts Payable to scale predictably alongside future COGS. FY21-24 DPO ~ 20 but im giving FICO Benefit of the doubt. RAINMAKER ANTI-DOUBLECOUNT:MODEL18: DPO pairs with phased DSO for Op NWC = AR+Inv−AP. Deferred is a SEPARATE CFO cash source (row 81) — never mixed into AR/DPO.a | U17: =HYPERLINK("https://www.sec.gov/Archives/edgar/data/814547/000081454725000030/fico-20250930.htm","SEC 10-K FY2025 — Accounts payable") -> SEC 10-K FY2025 — Accounts payable | V17: =HYPERLINK("https://www.sec.gov/Archives/edgar/data/814547/000081454725000030/fico-20250930.htm","https://www.sec.gov/Archives/edgar/data/814547/000081454725000030/fico-20250930.htm") -> https://www.sec.gov/Archives/edgar/data/814547/000081454725000030/fico-20250930.htm
B18: CapEx % of Revenue (fade 0.85%→0.35%) | C18: WHY: MODEL18 Yacktman: Updated CapEx from Model17 (Previous: 1.00% → 0.85% → 0.70% → 0.55% → 0.40%) to Model18 (New: 0.85%… | SOURCE: SEC 10-K / companyfacts — PPE purchases + capitalized software; fade to maintenance | LINK: https://data.sec.gov/api/xbrl/companyfacts/CIK0000814547.json | HOW: Yellow POLICY path: 0.85% / 0.70% / 0.55% / 0.45% / 0.35% (fade with operating leverage). | ASSUMPTIONS PDF: https://raw.githubusercontent.com/vengeanceaiUSC/Rainmaker/cursor/vengeanceaiusmodel18-d3ac/FICO/output/MODEL18_FICO_ASSUMPTIONS_LIST.pdf | E18: =E68 -> 7569 | F18: =F68 -> 6029 | G18: =G68 -> 4237 | H18: =H68 -> 25551 | I18: =I68 -> 39407 | J18: 0.0085 | K18: 0.007 | L18: 0.0055 | M18: 0.0045 | N18: 0.0035 | P18: 18 | Q18: CapEx % of Revenue | R18: Capital investment (PPE + capitalized software) as % of sales. | S18: Yellow POLICY path: 0.85% / 0.70% / 0.55% / 0.45% / 0.35% (fade with operating leverage). 15 BSP fade 4-Year Historical Average (0.70%) Sum of FY21 through FY24 divided by 4: (0.58% + 0.44% + 0.28% + 1.49%) / 4 = 2.79% / 4 = 0.695% (rounds to 0.70%) 5-Year Historical Average (0.95%) Sum of FY21 through FY25 divided by 5: (0.58% + 0.44% + 0.28% + 1.49% + 1.98%) / 5 = 4.77% / 5 = 0.952% (rounds to 0.95%) Policy Baseline (0.85%) Midpoint between the 4-year and 5-year averages: (0.70% + 0.95%) / 2 = 1.65% / 2 = 0.825% (set to 0.85% model starting baseline) | T18: CapEx fades below D&A because FICO's Scores segment requires almost zero physical capital, while software expansion runs on public cloud OpEx rather than capitalized PPE, unlocking strong asset-light operating leverage. TLDR: since its software the cost increases are diverted to Opex as annual cloud usage How Will Capex Fall: CapEx fades from 0.85% to 0.35% as FICO shifts to cloud OpEx, completes upfront platform buildouts, and leverages asset-light growth. A 15 bps annual fade is reasonable because it carries a modest $3.8M yearly impact of 2.5B+ Revenue, reflects operating leverage as revenue outpaces CapEx, and smoothly transitions away from recent spending spikes. | U18: =HYPERLINK("https://data.sec.gov/api/xbrl/companyfacts/CIK0000814547.json","SEC 10-K / companyfacts — PPE purchases + capitalized software; fade to maintenance") -> SEC 10-K / companyfacts — PPE purchases + capitalized software; fade to maintenance | V18: =HYPERLINK("https://data.sec.gov/api/xbrl/companyfacts/CIK0000814547.json","https://data.sec.gov/api/xbrl/companyfacts/CIK0000814547.json") -> https://data.sec.gov/api/xbrl/companyfacts/CIK0000814547.json
B19: Debt Issuance (Repayment) — funds buybacks above 1.0× FCF (MULT=1.40) | C19: WHY: MODEL18: Buybacks unchanged vs Model17 (1.40×(CFO−CapEx); debt funds MULT−1). Q3 FY2026 buybacks $1960M vs FCF $370.3… | SOURCE: SEC EX-99.1 Q3 FY2026 — levered buybacks; companyfacts senior notes / LOC | LINK: https://data.sec.gov/api/xbrl/companyfacts/CIK0000814547.json | HOW: Equation: −(CFO−CapEx) − EquityCF = (1.40−1)×FCF (debt funds buybacks above organic FCF). | ASSUMPTIONS PDF: https://raw.githubusercontent.com/vengeanceaiUSC/Rainmaker/cursor/vengeanceaiusmodel18-d3ac/FICO/output/MODEL18_FICO_ASSUMPTIONS_LIST.pdf | E19: =E99 -> 519583 | F19: =F99 -> 594651 | G19: =G99 -> 7989 | H19: =H99 -> 347363 | I19: =I99 -> 846670 | J19: =-(J66-J69)-J20 -> 469707.54 | K19: =-(K66-K69)-K20 -> 613111.16 | L19: =-(L66-L69)-L20 -> 746453.03 | M19: =-(M66-M69)-M20 -> 867482.6 | N19: =-(N66-N69)-N20 -> 963915.13 | P19: 19 | Q19: Debt Issuance (Repayment) | R19: New borrowing (+) or repayment (−) in the forecast ($000s). | S19: Net Debt Issued = Total Share Buybacks - Free Cash Flow The model calculates net debt issuance by subtracting organic Free Cash Flow from total share buybacks, automatically financing any repurchases that exceed 100% of the organic cash generated from operations. is that true for new debt we are only looking at the money borrowed for share buybacks? | T19: MODEL18: Buybacks unchanged vs Model17 (1.40×(CFO−CapEx); debt funds MULT−1). Q3 FY2026 buybacks $1960M vs FCF $370.3M (https://www.sec.gov/Archives/edgar/data/814547/000081454726000031/exhibit991erq32026.htm). Financing is excluded from FCFF. | U19: =HYPERLINK("https://data.sec.gov/api/xbrl/companyfacts/CIK0000814547.json","SEC EX-99.1 Q3 FY2026 — levered buybacks; companyfacts senior notes / LOC") -> SEC EX-99.1 Q3 FY2026 — levered buybacks; companyfacts senior notes / LOC | V19: =HYPERLINK("https://data.sec.gov/api/xbrl/companyfacts/CIK0000814547.json","https://data.sec.gov/api/xbrl/companyfacts/CIK0000814547.json") -> https://data.sec.gov/api/xbrl/companyfacts/CIK0000814547.json
B20: Equity Issued (Repaid) — 1.40×(CFO−CapEx) buybacks (hist avg $881M; Q3 FY26 levered) | C20: WHY: Buybacks unchanged vs Model17 (1.40× FCF); Y1 DCF share effect stub-scaled. Shares unchanged vs Model17 (21,597.635k … | SOURCE: SEC EX-99.1 Q3 FY2026 — buybacks vs FCF; 10-K FY2025 repurchase footnote | LINK: https://www.sec.gov/Archives/edgar/data/814547/000081454725000030/fico-20250930.htm | HOW: Equation: −1.40×(CFO−CapEx) levered buybacks (hist 3yr avg ≈ $881M/yr; Q3 FY26 >> FCF). | ASSUMPTIONS PDF: https://raw.githubusercontent.com/vengeanceaiUSC/Rainmaker/cursor/vengeanceaiusmodel18-d3ac/FICO/output/MODEL18_FICO_ASSUMPTIONS_LIST.pdf | E20: =E73 -> -881923 | F20: =F73 -> -1144718 | G20: =G73 -> -499101 | H20: =H73 -> -941992 | I20: =I73 -> -1569748 | J20: =-1.4*(J66-J69) -> -1643976.4 | K20: =-1.4*(K66-K69) -> -2145889.1 | L20: =-1.4*(L66-L69) -> -2612585.6 | M20: =-1.4*(M66-M69) -> -3036189.1 | N20: =-1.4*(N66-N69) -> -3373702.9 | P20: 20 | Q20: Equity Issued (Repaid) | R20: New equity issued (+) or buybacks (−) in the forecast BS/CF. Equity issued means selling new stock to raise capital (increasing share count). In contrast, buybacks are payouts where the company repurchases its own shares using cash or debt. FCF (Free Cash Flow): The leftover cash a company generates after paying for operating expenses and capital investments, used for dividends, buybacks, or debt. ==CFO- Capex CFO (Cash Flow from Operations): Cash generated from everyday core business operations. CapEx (Capital Expenditures): Money spent to purchase or upgrade physical assets (equipment, buildings, software). | S20: Equation: −1.40×(CFO−CapEx) levered buybacks (hist 3yr avg ≈ $881M/yr; Q3 FY26 >> FCF). | T20: Over three years, average free cash flow was 377.6 million while share buybacks averaged 1,003.6 million annually. Repurchases reached 2.66 times cash flow, fully justifying the conservative 1.40x model policy. | U20: =HYPERLINK("https://www.sec.gov/Archives/edgar/data/814547/000081454725000030/fico-20250930.htm","SEC EX-99.1 Q3 FY2026 — buybacks vs FCF; 10-K FY2025 repurchase footnote") -> SEC EX-99.1 Q3 FY2026 — buybacks vs FCF; 10-K FY2025 repurchase footnote | V20: =HYPERLINK("https://www.sec.gov/Archives/edgar/data/814547/000081454725000030/fico-20250930.htm","https://www.sec.gov/Archives/edgar/data/814547/000081454725000030/fico-20250930.htm") -> https://www.sec.gov/Archives/edgar/data/814547/000081454725000030/fico-20250930.htm
B21: SBC % of Revenue (fade path; CF/FCFF add-back ONLY — buybacks cut DCF shares) | C21: WHY: MODEL18 Yacktman: Updated SBC from Model17 (Previous: fade 8.25% / 7.80% / 7.40% / 7.00% / 6.60%) to Model18 (New: fa… | SOURCE: SEC 10-K cash flow — ShareBasedCompensation (add-back only; no share dilution) | LINK: https://data.sec.gov/api/xbrl/companyfacts/CIK0000814547.json | HOW: Yellow POLICY fade path: 7.00% / 6.50% / 6.00% / 5.50% / 5.00% (starts at 3yr avg 7.00%). | ASSUMPTIONS PDF: https://raw.githubusercontent.com/vengeanceaiUSC/Rainmaker/cursor/vengeanceaiusmodel18-d3ac/FICO/output/MODEL18_FICO_ASSUMPTIONS_LIST.pdf | J21: 0.07 | K21: 0.065 | L21: 0.06 | M21: 0.055 | N21: 0.05 | P21: 21 | Q21: SBC % of Revenue | R21: Stock-based compensation as % of sales; non-cash add-back in CFO and FCFF. Added Back to Income Statement | S21: Yellow POLICY fade path: 7.00% / 6.50% / 6.00% / 5.50% / 5.00% (starts at 3yr avg 7.00%). | T21: Why Stock grants dilute shareholders, but revenue is growing from price increases rather than new hiring. Therefore, penalizing stock compensation too harshly would unfairly distort and understate the company's real profits. TLDR: Revenue seems to be increasing from profit instead of hiring/scaling so we will reduce SBC conservatively 50 Basis points ' Proof That Revenue/Profit Comes From Pricing, Not Hiring (30 Words) SEC filings confirm revenue growth came primarily from higher unit prices on Scores with near 100 percent incremental margins, proving profits increased from pricing power, not headcount or hiring expansion. | U21: =HYPERLINK("https://data.sec.gov/api/xbrl/companyfacts/CIK0000814547.json","SEC 10-K cash flow — ShareBasedCompensation (add-back only; no share dilution)") -> SEC 10-K cash flow — ShareBasedCompensation (add-back only; no share dilution) | V21: =HYPERLINK("https://data.sec.gov/api/xbrl/companyfacts/CIK0000814547.json","https://data.sec.gov/api/xbrl/companyfacts/CIK0000814547.json") -> https://data.sec.gov/api/xbrl/companyfacts/CIK0000814547.json
B23: Income Statement
B24: Reveneue | C24: eqn: PriorRev × (1 + growth) | E24: 1316536 | F24: 1377270 | G24: 1513557 | H24: 1717526 | I24: 1990869 | J24: =I24*(1+J7) -> 2588129.7 | K24: =J24*(1+K7) -> 3053993 | L24: =K24*(1+L7) -> 3496822 | M24: =L24*(1+M7) -> 3881472.5 | N24: =M24*(1+N7) -> 4211397.6
B25: Cost of Goods Sold (COGS) | C25: eqn: Rev × COGS% | E25: 332462 | F25: 302174 | G25: 311053 | H25: 348206 | I25: 353722 | J25: =J24*J8 -> 301810.94 | K25: =K24*K8 -> 315824.2 | L25: =L24*L8 -> 315460.66 | M25: =M24*M8 -> 310517.8 | N25: =N24*N8 -> 336911.81
B26: Gross Profit | C26: eqn: Rev − COGS | E26: =E24-E25 -> 984074 | F26: =F24-F25 -> 1075096 | G26: =G24-G25 -> 1202504 | H26: =H24-H25 -> 1369320 | I26: =I24-I25 -> 1637147 | J26: =J24-J25 -> 2286318.8 | K26: =K24-K25 -> 2738168.8 | L26: =L24-L25 -> 3181361.4 | ... N26: =N24-N25 -> 3874485.8
B27: Expenses
B28: SG&A Expense | C28: eqn: Rev × SG&A% | E28: 396281 | F28: 383863 | G28: 400565 | H28: 462834 | I28: 513028 | J28: =J24*J9 -> 607445.53 | K28: =K24*K9 -> 663340.85 | L28: =L24*L9 -> 698330.88 | M28: =M24*M9 -> 707221.51 | N28: =N24*N9 -> 693635.88
B29: Research & Development (R&D) | C29: eqn: Rev × R&D% | E29: 171231 | F29: 146758 | G29: 159950 | H29: 171940 | I29: 188347 | J29: =J24*J10 -> 231910.45 | K29: =K24*K10 -> 258384.37 | L29: =L24*L10 -> 278365.99 | M29: =M24*M10 -> 289578.89 | N29: =N24*N10 -> 294797.83
B30: Depreciation & Amortization | C30: eqn: Rev × DA% (total D&A / sales) | E30: 25592 | F30: 20465 | G30: 14638 | H30: 13827 | I30: 14952 | J30: =J24*J11 -> 21768.759 | K30: =K24*K11 -> 25687.136 | L30: =L24*L11 -> 29411.77 | M30: =M24*M11 -> 32647.065 | N30: =N24*N11 -> 35422.065
B31: Interest | C31: eqn: Debt_open × Int% | E31: 40092 | F31: 68967 | G31: 95546 | H31: 105638 | I31: 133647 | J31: =J98*J12 -> 184871.01 | K31: =K98*K12 -> 213288.57 | L31: =L98*L12 -> 250382.14 | M31: =M98*M12 -> 295542.96 | N31: =N98*N12 -> 348026.14
B32: Total Expenses | E32: =SUM(E28:E31) -> 633196 | F32: =SUM(F28:F31) -> 620053 | G32: =SUM(G28:G31) -> 670699 | H32: =SUM(H28:H31) -> 754239 | I32: =SUM(I28:I31) -> 849974 | J32: =SUM(J28:J31) -> 1045995.7 | K32: =SUM(K28:K31) -> 1160700.9 | L32: =SUM(L28:L31) -> 1256490.8 | ... N32: =SUM(N28:N31) -> 1371881.9
B33: Earnings Before Tax | C33: eqn: GP − Expenses | E33: =E26-E32 -> 350878 | F33: =F26-F32 -> 455043 | G33: =G26-G32 -> 531805 | H33: =H26-H32 -> 615081 | I33: =I26-I32 -> 787173 | J33: =J26-J32 -> 1240323 | K33: =K26-K32 -> 1577467.9 | L33: =L26-L32 -> 1924870.6 | ... N33: =N26-N32 -> 2502603.9
B35: Taxes | C35: eqn: EBT × book tax% | E35: 81058 | F35: 97768 | G35: 124249 | H35: 129214 | I35: 150649 | J35: =J33*J13 -> 237372.75 | K35: =K33*K13 -> 301895.47 | L35: =L33*L13 -> 368381.32 | M35: =M33*M13 -> 429832.15 | N35: =N33*N13 -> 478947.79
B36: Net Earnings | C36: eqn: EBT × (1 − book tax%) | E36: =E33-E35 -> 269820 | F36: =F33-F35 -> 357275 | G36: =G33-G35 -> 407556 | H36: =H33-H35 -> 485867 | I36: =I33-I35 -> 636524 | J36: =J33*(1-J13) -> 1002950.3 | K36: =K33*(1-K13) -> 1275572.5 | L36: =L33*(1-L13) -> 1556489.3 | M36: =M33*(1-M13) -> 1816132.1 | N36: =N33*(1-N13) -> 2023656.1
B39: Balance Sheet
B40: Assets
B41: Cash | E41: 195354 | F41: 133202 | G41: 136778 | H41: 150667 | I41: 134136 | J41: =J78 -> 134136 | K41: =K78 -> 134136 | L41: =L78 -> 134136 | M41: =M78 -> 134136 | N41: =N78 -> 134136
B42: Accounts Receivable | C42: eqn: Rev × phased DSO / 365 (AR ≠ Deferred) | E42: 312107 | F42: 322410 | G42: 387947 | H42: 426642 | I42: 529148 | J42: =J24*J15/365 -> 589951.76 | K42: =K24*K15/365 -> 580677.03 | L42: =L24*L15/365 -> 532666.59 | M42: =M24*M15/365 -> 444508.35 | N42: =N24*N15/365 -> 323066.12
B43: Inventory | E43: 0 | F43: 0 | G43: 0 | H43: 0 | I43: 0 | J43: =J25*J16/365 -> 0 | K43: =K25*K16/365 -> 0 | L43: =L25*L16/365 -> 0 | M43: =M25*M16/365 -> 0 | N43: =N25*N16/365 -> 0
B44: Property & Equipment | E44: 27913 | F44: 17580 | G44: 10966 | H44: 38465 | I44: 67713 | J44: =J95 -> 67943.344 | K44: =K95 -> 63634.159 | L44: =L95 -> 53454.91 | M44: =M95 -> 38274.472 | N44: =N95 -> 17592.298
...

Sheet DCF Model
A1: © Corporate Finance Institute®. All rights reserved. | L1: vengeanceaiUSCMODEL18.0 — Public Peer EV/EBITDA Comps
B2: DCF Model | L2: Ticker | M2: Company | N2: EV/EBITDA | O2: Source | Q2: vengeanceaiUSCMODEL18.0 — LIVE EQUATIONS + SOURCE LINKS
L3: EFX | M3: Equifax | N3: 13.88 | O3: VCP Scanner peer set | Q3: Yellow = inputs (edit). Green = formulas. Blue underlined = clickable sources.
A4: =HYPERLINK("https://raw.githubusercontent.com/vengeanceaiUSC/Rainmaker/cursor/vengeanceaiusmodel18-d3ac/FICO/output/MODEL18_FICO_ASSUMPTIONS_LIST.pdf","⬇ Download Assumptions List PDF") -> ⬇ Download Assumptions List PDF | B4: Assumptions — full list PDF (no charts): MODEL18_FICO_ASSUMPTIONS_LIST.pdf | C4: https://github.com/vengeanceaiUSC/Rainmaker/blob/cursor/vengeanceaiusmodel18-d3ac/FICO/output/MODEL18_FICO_ASSUMPTIONS_LIST.pdf | L4: VRSK | M4: Verisk Analytics | N4: 17.42 | O4: VCP Scanner peer set | Q4: Input | R4: Value | S4: Description | T4: Role | U4: Primary source (click) | V4: Secondary source (click)
B5: Cash Tax Rate (3yr avg IncomeTaxesPaid/EBT = 22.87%) | C5: MODEL18 — cash taxes ≠ book tax (3S J13 still book for NI) | D5: 0.22873 | E5: Tax source: SEC 10-K | L5: SPGI | M5: S&P Global | N5: 18.11 | O5: VCP Scanner peer set | Q5: 1) Yacktman-adjusted CAPM → WACC (D6=R15); β=0.3×Blume(1.213)+0.7×AAA(0.70)=0.854 (Yahoo raw 1.32 kept as ref)
A6: WACC sources → columns U–V | B6: Discount Rate (Yacktman-adj CAPM WACC = R15 ≈ 7.68%; Model17 was 7.68%) | C6: WACC algebra unchanged vs Model17 (Previous: 7.68%) in Model18 (New: 7.68% = D6←R15); stub scales Y1 FCFF × 64.66% | D6: =R15 -> 0.076241835 | E6: WACC sources → scroll to col U (Rf/ERP/β/Rd links) | F6: Damodaran ERP | G6: SEC 8-K Rd 6.250% | L6: MCO | M6: Moody's | N6: 22.2 | O6: VCP Scanner peer set | Q6: Risk-free rate (Rf) | R6: 0.0467 | S6: US 10Y Treasury yield | T6: CAPM input | U6: FRED DGS10 (US 10Y) | V6: US Treasury Daily Par Yield Curve
B7: Perpetual Growth (g = 3.5% — Gordon cross-check) | C7: g unchanged vs Model17 (Previous: 3.5%) in Model18 | D7: 0.035 | L7: MSCI | M7: MSCI Inc. | N7: 23.74 | O7: VCP Scanner peer set | Q7: Equity risk premium (ERP) | R7: 0.0428 | S7: Damodaran implied ERP | T7: CAPM input | U7: Damodaran Online — Implied ERP | V7: Damodaran histimpl.xls / table
B8: Exit EV/EBITDA (BASE 23.0x — Yacktman premium) | C8: Exit unchanged vs Model17 (Previous: 23.0x) in Model18 (BASE 23.0x vs peer median 18.1x; Bull 27x / Bear 17.0x). | D8: 23 | E8: Rd source: SEC 8-K 6.250% notes | F8: Peer EV/EBITDA comps (click) | G8: FICO spot EV/EBITDA (click) | L8: Median | M8: Peer set | N8: 18.11 | O8: Sorted median (SPGI) | Q8: Beta (β_Yacktman) | R8: 0.854 | S8: 0.3×Blume(1.213)+0.7×AAA(0.70); Yahoo raw=1.32 | T8: CAPM input | U8: Yahoo Finance FICO Key Statistics (raw β) | V8: Blume 1971 β adjustment
B9: Valuation Date (stub clock; 2026-08-06) | C9: Updated from Model17 (Previous: hist FYE 2025-09-30) to Model18 (New: 2026-08-06; 129/365=35.34% elapsed) | D9: 46240 | L9: Base exit (D8) | N9: 23 | O9: Yacktman premium vs peer median; audit 23.0x | Q9: Ke = Rf + β × ERP | R9: =R6+R8*R7 -> 0.0832512 | S9: Cost of equity (Yacktman-adj CAPM) | T9: → WACC | U9: Derived: R6 + R8 × R7
B10: Stub FY End (first forward year end) | C10: Stub year ends 2027-03-29 | D10: 46475 | L10: Peer comps (click) | M10: FICO spot EV/EBITDA (click) | Q10: Pre-tax cost of debt (Rd) | R10: 0.0625 | S10: 6.250% Senior Notes due 2034 | T10: WACC input | U10: SEC 8-K — Notes closing (6.250%) | V10: SEC EX-99.1 — Notes pricing press release
B11: Current Price | D11: 1149 | Q11: Cash tax rate (t) | R11: =$D$5 -> 0.22873 | S11: D5 ← 3yr cash tax (IncomeTaxesPaid/EBT) | T11: Cash tax ≠ book J13 | U11: SEC 10-K FY2025 (tax / EBT) | V11: SEC companyfacts — IncomeTaxesPaidNet
B12: Shares Outstanding — starting (000s, post–Q3 ≈ 21,597.6k) | C12: Row 16: levered buybacks reduce shares; SBC add-back does NOT dilute | D12: 21597.635 | Q12: Rd_aftertax = Rd × (1 − t) | R12: =R10*(1-R11) -> 0.048204375 | S12: After-tax cost of debt | T12: → WACC | U12: Derived: R10 × (1 − R11)
B13: Debt (10-Q bridge — not 3S FY25 I49) | C13: See L39 for 3S FY25 debt ref | D13: 5582389 | Q13: Equity weight (We) | R13: 0.8 | S13: Target ~80% equity at market | T13: WACC weight | U13: SEC 10-Q Q3 FY2026 (debt / capital) | V13: Yahoo market cap for E/(D+E)
B14: Cash+mkt secs (10-Q bridge — not 3S FY25 I41) | C14: See L38 for 3S FY25 cash ref | D14: 304537 | Q14: Debt weight (Wd) | R14: 0.2 | S14: Target ~20% debt (We+Wd=100%) | T14: WACC weight | U14: SEC 10-Q — total debt $5,582,389k | V14: SEC 10-K — senior notes footnote
B15: Capex FY1 (linked to 3S J68; stub scales FCFF not CapEx cell) | D15: ='3 Statement Model'!J68 -> 21999.102 | Q15: WACC = We×Ke + Wd×Rd_aftertax | R15: =R13*R9+R14*R12 -> 0.076241835 | S15: PRIMARY discount rate → cell D6 (Yacktman-adj CAPM) | T15: → D6 | U15: SEC filings (tax, debt coupons) | V15: Damodaran (ERP methodology)
B16: Shares Outstanding — buyback-adjusted (000s) | C16: Shares_t = prior + EquityCF/Price; Y1 EquityCF × 64.66% stub | D16: =$D$12 -> 21597.635 | E16: =MAX(1000,D16+0.646575*'3 Statement Model'!J20/$D$11) -> 20672.523 | F16: =MAX(1000,E16+'3 Statement Model'!K20/$D$11) -> 18804.908 | G16: =MAX(1000,F16+'3 Statement Model'!L20/$D$11) -> 16531.117 | H16: =MAX(1000,G16+'3 Statement Model'!M20/$D$11) -> 13888.655 | I16: =MAX(1000,H16+'3 Statement Model'!N20/$D$11) -> 10952.447
B17: Discounted Cash Flow | D17: Entry | E17: =YEAR(E18) -> 2026 | F17: =YEAR(F18) -> 2027 | G17: =YEAR(G18) -> 2028 | H17: =YEAR(H18) -> 2029 | I17: =YEAR(I18) -> 2030 | J17: Exit | L17: Terminal value & scenarios (vengeanceaiUSCMODEL18.0) | Q17: 2) Unlevered Free Cash Flow
B18: Date (Y1 mid-stub +118d; Y2–Y5 EDATE mid-year) | D18: =$D$9 -> 46240 | E18: 46358 | F18: =EDATE(DATE(2027,3,30),6) -> 46660 | G18: =EDATE(DATE(2028,3,30),6) -> 47026 | H18: =EDATE(DATE(2029,3,30),6) -> 47391 | I18: =EDATE(DATE(2030,3,30),6) -> 47756 | J18: =I18 -> 47756 | L18: Exit EV/EBITDA @ D8 (BASE 23.0x) | M18: =J27 -> 66379198 | N18: ← used in XNPV | Q18: FCFF = EBIT − EBIT×t_cash + D&A + SBC − CapEx − ΔOpNWC + ΔDeferred | U18: Drivers from SEC XBRL → 3-statement | V18: SEC 10-K historical IS/CF
B19: Time Periods | E19: 0 | F19: =E19+1 -> 1 | G19: =F19+1 -> 2 | H19: =G19+1 -> 3 | I19: =H19+1 -> 4 | L19: Gordon cross-check (g=D7) | M19: =IF(($D$6-$D$7)<=0,"WACC must exceed g",$I$26*(1+$D$7)/($D$6-$D$7)) -> 64866244 | N19: ← sanity check | Q19: Excel (col E example) | R19: =E21-E22+E23-E24-E25 -> 1089358.9
B20: Year Fraction (display only; XNPV uses exact dates below) | E20: =YEARFRAC(D18,E18) -> 0.32222222 | F20: =YEARFRAC(E18,F18) -> 0.82777778 | G20: =YEARFRAC(F18,G18) -> 1 | H20: =YEARFRAC(G18,H18) -> 1 | I20: =YEARFRAC(H18,I18) -> 1 | L20: Implied Gordon exit multiple | M20: =IF(($I$21+$I$23)=0,0,M19/($I$21+$I$23)) -> 22.47577 | N20: ← ~bear check | Q20: Tax on EBIT (unlevered) | R20: =E21*$D$5 -> 325984.63 | S20: NOT levered IS tax dollars | U20: Tax rate from SEC 10-K effective rate
B21: EBIT (3S: EBT + Interest) | C21: EBIT | E21: ='3 Statement Model'!J33+'3 Statement Model'!J31 -> 1425194 | F21: ='3 Statement Model'!K33+'3 Statement Model'!K31 -> 1790756.5 | G21: ='3 Statement Model'!L33+'3 Statement Model'!L31 -> 2175252.7 | H21: ='3 Statement Model'!M33+'3 Statement Model'!M31 -> 2541507.2 | I21: ='3 Statement Model'!N33+'3 Statement Model'!N31 -> 2850630 | L21: BASE TV @ 23.0x (primary) | M21: =($I$21+$I$23)*23 -> 66379198 | N21: ← = D8 policy | Q21: FCFF check (FY5 / col I) | R21: =I26 -> 2584737.2 | S21: Must equal I21−I22+I23−I24−I25
B22: Less: Unlevered Cash Taxes (EBIT × cash tax rate D5) | C22: EBIT×t | E22: =E21*$D$5 -> 325984.63 | F22: =F21*$D$5 -> 409599.73 | G22: =G21*$D$5 -> 497545.56 | H22: =H21*$D$5 -> 581318.94 | I22: =I21*$D$5 -> 652024.61 | L22: BULL TV @ 27.0x (spot/policy) | M22: =($I$21+$I$23)*27 -> 77923407 | N22: ← sensitivity only
B23: Plus: D&A (3S IS row 30) | C23: +D&A | E23: ='3 Statement Model'!J30 -> 21768.759 | F23: ='3 Statement Model'!K30 -> 25687.136 | G23: ='3 Statement Model'!L30 -> 29411.77 | H23: ='3 Statement Model'!M30 -> 32647.065 | I23: ='3 Statement Model'!N30 -> 35422.065 | L23: BEAR TV @ 17.0x (Gordon-implied) | M23: =($I$21+$I$23)*17 -> 49062886 | N23: ← sensitivity only | Q23: 3) Terminal Value
B24: Less: Capex (3S CF row 68) | C24: −CapEx | E24: ='3 Statement Model'!J68 -> 21999.102 | F24: ='3 Statement Model'!K68 -> 21377.951 | G24: ='3 Statement Model'!L68 -> 19232.521 | H24: ='3 Statement Model'!M68 -> 17466.626 | I24: ='3 Statement Model'!N68 -> 14739.892 | L24: Reconciliation: Bull 27x → Base 23.0x (Yacktman premium vs peer median ~18.1x) → Bear 17.0x | Q24: TV_exit = EBITDA_n × ExitMultiple [PRIMARY]
B25: Less: ΔOpNWC − ΔDeferred (3S 90 − 81; AR≠Deferred) | C25: −ΔOpNWC+ΔDef | E25: ='3 Statement Model'!J90-('3 Statement Model'!J88-'3 Statement Model'!I88) -> 9620.1401 | F25: ='3 Statement Model'!K90-('3 Statement Model'!K88-'3 Statement Model'!J88) -> -54386.723 | G25: ='3 Statement Model'!L90-('3 Statement Model'!L88-'3 Statement Model'!K88) -> -89654.73 | H25: ='3 Statement Model'!M90-('3 Statement Model'!M88-'3 Statement Model'!L88) -> -123912.99 | I25: ='3 Statement Model'!N90-('3 Statement Model'!N88-'3 Statement Model'!M88) -> -154879.67 | Q25: Excel | R25: =($I$21+$I$23)*$D$8 -> 66379198 | T25: =J27 -> 66379198 | U25: Exit multiple policy vs Yahoo / market multiples
B26: Unlevered FCF (Y1 × 64.66% stub remaining; SBC + Deferred) | C26: FCFF=EBIT−cashTax+DA+SBC−CapEx−ΔOpNWC+ΔDeferred | E26: =0.646575*(E21-E22+E23+'3 Statement Model'!J64-E24-E25) -> 821491.63 | F26: =F21-F22+F23+'3 Statement Model'!K64-F24-F25 -> 1638362.2 | G26: =G21-G22+G23+'3 Statement Model'!L64-G24-G25 -> 1987350.5 | H26: =H21-H22+H23+'3 Statement Model'!M64-H24-H25 -> 2312762.7 | I26: =I21-I22+I23+'3 Statement Model'!N64-I24-I25 -> 2584737.2 | L26: vengeanceaiUSCMODEL18.0 — DCF ← 3-Statement linkage audit | Q26: TV_gordon = FCFF_n×(1+g)/(WACC−g) [CHECK]
B27: (Entry)/Exit TV — Exit EV/EBITDA (BASE 23.0x) | D27: =-I35 -> -30093535 | J27: =($I$21+$I$23)*$D$8 -> 66379198 | L27: DCF item | M27: Value / link | N27: 3-Statement source | O27: Notes | Q27: Excel | R27: =IF(($D$6-$D$7)<=0,"err",$I$26*(1+$D$7)/($D$6-$D$7)) -> 64866244 | T27: =M19 -> 64866244 | U27: Gordon g vs Damodaran long-run growth framing
B28: Transaction CF | D28: 0 | E28: =E27+E26 -> 821491.63 | F28: =F27+F26 -> 1638362.2 | G28: =G27+G26 -> 1987350.5 | H28: =H27+H26 -> 2312762.7 | I28: =I27+I26 -> 2584737.2 | J28: =J27+J26 -> 66379198 | L28: Cash tax rate (D5) | M28: =$D$5 -> 0.22873 | N28: 22.87% | O28: 3yr avg IncomeTaxesPaidNet/EBT (not book J13) | Q28: Implied Gordon exit multiple | R28: =IF(($I$21+$I$23)=0,0,T27/($I$21+$I$23)) -> 22.47577 | S28: Gordon TV / EBITDA_n
B29: Transaction CF | D29: =D27+D26 -> -30093535 | E29: =E27+E26 -> 821491.63 | F29: =F27+F26 -> 1638362.2 | G29: =G27+G26 -> 1987350.5 | H29: =H27+H26 -> 2312762.7 | I29: =I27+I26 -> 2584737.2 | J29: =J27 -> 66379198 | L29: DSO (AR days) | M29: ='3 Statement Model'!J15 -> 83.2 | N29: ='3 Statement Model'!J15 -> 83.2 | O29: Phased DSO hist→45d; Op NWC excludes Deferred
L30: SBC % of sales | M30: ='3 Statement Model'!J21 -> 0.07 | N30: ='3 Statement Model'!J21 -> 0.07 | O30: SBC add-back in CFO row 64 and FCFF | Q30: 4) Enterprise → Equity → $/share
B31: Intrinsic Value | G31: Market Value | L31: CapEx % (FY1) | M31: ='3 Statement Model'!J18 -> 0.0085 | N31: ='3 Statement Model'!J18 -> 0.0085 | O31: CapEx% fade path → CF CapEx $ | Q31: EV = XNPV(WACC, TransactionCF, mid-year dates)
B32: Enterprise Value (XNPV; Y1 mid-stub dates) | D32: =XNPV(D6,D28:J28,D18:J18) -> 56664816 | G32: Market Cap | I32: =D12*D11 -> 24815683 | L32: Revenue growth FY1 | M32: ='3 Statement Model'!J7 -> 0.3 | N32: ='3 Statement Model'!J7 -> 0.3 | O32: Policy path on 3S assumption row 7 | Q32: Excel | R32: =XNPV(D6,D28:J28,D18:J18) -> 56664816 | T32: =D32 -> 56664816
B33: Plus: Cash | D33: =+D14 -> 304537 | G33: Plus: Debt | I33: =D13 -> 5582389 | L33: EBIT FY1 (DCF E21) | M33: =$E$21 -> 1425194 | N33: ='3 Statement Model'!J33+'3 Statement Model'!J31 -> 1425194 | O33: EBT + Interest = GP − SG&A − R&D − D&A | Q33: Equity = EV + Cash − Debt | R33: =D35 -> 51386964 | S33: Net debt from 10-Q bridge | U33: SEC 10-Q — cash, mkt secs, total debt | V33: SEC 10-K — FY debt footnote
B34: Less: Debt | D34: =+D13 -> 5582389 | G34: Less: Cash | I34: =+D14 -> 304537 | L34: EBIT cross-check | M34: ='3 Statement Model'!J26-'3 Statement Model'!J28-'3 Statement Model'!J29-'3 Statement Model'!J30 -> 1425194 | N34: GP−SGA−R&D−DA | O34: Must equal E21 (live check) | Q34: $/share = Equity / Shares | R34: =D37 -> 4691.8249 | S34: Shares outstanding (Yahoo) | U34: Yahoo Finance — shares outstanding | V34: Yahoo FICO quote (price)
B35: Equity Value | D35: =D32+D33-D34 -> 51386964 | G35: Enterprise Value | I35: =I32+I33-I34 -> 30093535 | L35: D&A FY1 | M35: =$E$23 -> 21768.759 | N35: ='3 Statement Model'!J30 -> 21768.759 | O35: Rev × DA% (total D&A / sales) from 3S IS | Q35: Upside vs market | R35: =D37/D11-1 -> 3.0833985 | S35: Intrinsic / Current Price − 1
L36: SBC FY1 | M36: ='3 Statement Model'!J64 -> 181169.08 | N36: ='3 Statement Model'!J64 -> 181169.08 | O36: Rev × SBC%; added in FCFF
B37: Equity Value/Share (÷ Y5 buyback-adjusted shares I16) | C37: MODEL18: SBC add-back in FCFF; 1.4×FCF buybacks cut shares (no SBC dilution) | D37: =$D$35/$I$16 -> 4691.8249 | G37: Equity Value/Share | I37: =D11 -> 1149 | L37: CapEx FY1 | M37: =$E$24 -> 21999.102 | N37: ='3 Statement Model'!J68 -> 21999.102 | O37: 3S CF CapEx (also D15) | Q37: 5) Op NWC + Deferred (feeds FCFF; AR ≠ Deferred)
L38: Net WC use FY1 | M38: =$E$25 -> 9620.1401 | N38: ='3 Statement Model'!J90-('3 Statement Model'!J88-'3 Statement Model'!I88) -> 9620.1401 | O38: ΔOpNWC − ΔDeferred (AR≠Deferred) | Q38: OpNWC = AR+Inv−AP; +ΔDeferred separate CFO source | U38: SEC 10-K — AR / AP / deferred revenue | V38: XBRL DeferredRevenueCurrent
L39: EBITDA FY5 (TV base) | M39: =$I$21+$I$23 -> 2886052.1 | N39: ='3 Statement Model'!N33+'3 Statement Model'!N31+'3 Statement Model'!N30 -> 2886052.1 | O39: EBIT+D&A; Exit TV = this × D8 | Q39: Net WC use = ΔOpNWC − ΔDeferred | S39: 3S row 90 − row 81 (Deferred growth = cash source) | T39: =I25 -> -154879.67
L40: 3S FY25 Cash (ref) | M40: ='3 Statement Model'!I41 -> 134136 | N40: ='3 Statement Model'!I41 -> 134136 | O40: FYE reference only — bridge uses 10-Q D14
...
