Workbook

Sheet Assumptions_Drivers
B2: Assumptions Drivers — Col A Baseline Yes/No. Col E/H = source page link. Cols I/J/K = plain Verbatim Ctrl+F strings. Converse pass: driver must match sourced figure or a justified gap; else driver was reset to the source.
B3: How to verify: click Source (E) → open page → copy Verbatim from I/J/K → Ctrl+F → paste. Overpessimism fix: rev +5% (mature CAGR; FY24 −2% outlier). S&M +2% Fed restored. S&M $414.1; AI $24.5m; CapEx 8%; ΔNWC=ΔAR(16.2%×[1−10% AI])−ΔDR(39%).
A4: Baseline Yes/No | B4: Driver | C4: Value | D4: Why reasonable (model justification) | E4: Source — ONLY if number appears in EQ (click) | F4: Source justification (≤30 words): Source says X. Does X go into the math? | G4: Feeds (click to jump) | H4: Secondary source (click) | I4: Verbatim 1 — copy this into Ctrl+F on the source page | J4: Verbatim 2 — copy this into Ctrl+F on the source page | K4: Verbatim 3 — copy this into Ctrl+F on the source page
A5: NO | B5: Revenue growth | C5: 0.05 | D5: FY24 −2% was the only revenue decline in CY2019–CY2025 (outlier). FY25 recovered +3% ($1,249.5m). Mature CAGR CY2022 $1,098m → CY2025 $1,249.5m ≈ 4.4%, rounded to 5% forward. | E5: =HYPERLINK("https://www.sec.gov/Archives/edgar/data/1794515/000179451526000012/zi-20251231.htm","IN EQ: C5=+5% ≈ mature CAGR CY2022→CY2025 (~4.4%). FY24 −2% = outlier; FY25 +3% recovery.") -> IN EQ: C5=+5% ≈ mature CAGR CY2022→CY2025 (~4.4%). FY24 −2% = outlier; FY25 +3% recovery. | F5: FY24 −2% was an outlier (only decline). FY25 rose 3% to $1,249.5m. CAGR 2022–2025 ≈4.4%; we use 5% forward. | G5: Go to AI_Operating!D5 (Revenue) | H5: =HYPERLINK("https://markets.financialcontent.com/stocks/article/bizwire-2025-2-25-zoominfo-announces-fourth-quarter-and-full-year-2024-financial-results","FY24 −2% outlier: decrease of 2% YoY") -> FY24 −2% outlier: decrease of 2% YoY | I5: Ctrl+F: increase of $35.2 million, or 3% | J5: Ctrl+F: revenue of $1,249.5 million | K5: Ctrl+F: a decrease of 2% year-over-year (FY24 outlier)
A6: NO | B6: Gross margin | C6: 0.8 | D6: Uses the 2025 software median gross margin of 80%. ZoomInfo’s own GAAP GM is higher (~84%), but this model uses the cited Aleph median. | E6: =HYPERLINK("https://www.getaleph.com/answers/saas-gross-margin-2026","IN EQ: software median GM=80% → C6=0.80 (Aleph × Benchmarkit)") -> IN EQ: software median GM=80% → C6=0.80 (Aleph × Benchmarkit) | F6: Aleph says the 2025 software median gross margin is 80%. We use that 80% in the COGS math. | G6: Go to AI_Operating!D6 (COGS) | I6: Ctrl+F: The 2025 median software gross margin is 80% | K6: ZI GAAP GM ~84% not used — Aleph median is the driver
A7: NO | B7: Sales payroll cut (Y1) | C7: 0.18 | D7: Matches published US B2B SaaS net SDR headcount decline of 18% YoY. | E7: =HYPERLINK("https://www.digitalapplied.com/blog/ai-sdr-statistics-2026-outbound-sales-data-points","IN EQ: C7=18% = US B2B SaaS net SDR headcount down 18% YoY") -> IN EQ: C7=18% = US B2B SaaS net SDR headcount down 18% YoY | F7: Digital Applied says U.S. B2B SaaS SDR headcount fell 18% YoY. We use that 18% as the Year 1 payroll cut. | G7: Go to AI_Operating!D7 (Sales payroll) | I7: Ctrl+F: down 18% YoY
A8: NO | B8: Variable commission cut | C8: 0.18 | D8: Was an unsourced 20% cut. Now 18% to match the same SDR headcount decline used for payroll. | E8: =HYPERLINK("https://www.digitalapplied.com/blog/ai-sdr-statistics-2026-outbound-sales-data-points","IN EQ: C8=18% cut = same SDR HC down 18% YoY (Digital Applied)") -> IN EQ: C8=18% cut = same SDR HC down 18% YoY (Digital Applied) | F8: Digital Applied says SDR headcount fell 18% YoY. We use that same 18% as the commission cut. | G8: Go to AI_Operating!D8 (Commissions) | H8: =HYPERLINK("https://syncgtm.com/blog/how-to-pay-sales-development-rep","Pay mix context only: 70/30 base/variable") -> Pay mix context only: 70/30 base/variable | I8: Ctrl+F: down 18% YoY | J8: Ctrl+F: 70/30 base/variable split | K8: Prior 20% cut removed — no source equaled 20%
A9: NO | B9: AI infrastructure ($m) | C9: 24.5 | D9: AI $24.5m = 18%×1,513 roles × $5–10k/mo × 12, midpoint. Role share now uses the same sourced 18% SDR decline (was unsourced 25%). | E9: =HYPERLINK("https://www.whitespacesolutions.ai/content/ai-sdr-pricing-guide-2026","IN EQ: $5k/$10k/mo + 1,513 HC; roles=18% (same 18% as C7) → $24.5m") -> IN EQ: $5k/$10k/mo + 1,513 HC; roles=18% (same 18% as C7) → $24.5m | F9: White Space/Miniloop say ~$5k–$10k+/mo. ZoomInfo’s 10-K says 1,513 S&M staff. Roles use the sourced 18% (not 25%). Those build the $24.5m cost. | G9: Go to AI_Operating!D10 (AI infrastructure) | H9: =HYPERLINK("https://www.miniloop.ai/blog/11x-pricing","Miniloop Enterprise $10,000+") -> Miniloop Enterprise $10,000+ | I9: Ctrl+F: $5,000-10,000+ | J9: Ctrl+F: $10,000-$15,000+ | K9: Ctrl+F: 1,513 in sales and marketing
A10: NO | B10: S&M expense growth Y2+ | C10: 0.02 | D10: After the Y1 headcount cut, AI keeps S&M growing only at ~inflation (2%), not with revenue. Restored now that forward revenue is positive again. | E10: =HYPERLINK("https://www.federalreserve.gov/faqs/economy_14400.htm","IN EQ: C10=2% = Fed longer-run inflation goal of 2 percent") -> IN EQ: C10=2% = Fed longer-run inflation goal of 2 percent | F10: The Fed says longer-run inflation is 2%. We use that 2% to grow S&M costs after Year 1. | G10: Go to AI_Operating!E7 (payroll Y2+) | H10: FOMC Statement on Longer-Run Goals (PDF) | I10: Ctrl+F: inflation of 2 percent over the longer run | K10: Valid with +5% revenue (row 5); not used when rev was −2%
A11: NO | B11: G&A % of revenue | C11: 0.18 | D11: Post-LBO target at the public SaaS median (18%). ZoomInfo’s own FY24 G&A is higher (~24%) and is not used. | E11: =HYPERLINK("https://blossomstreetventures.medium.com/what-should-saas-spend-on-cogs-s-m-r-d-and-g-a-the-data-from-57-public-cos-8e88eabe99ca","IN EQ: C11=18% = Blossom Street 2025 public SaaS median G&A") -> IN EQ: C11=18% = Blossom Street 2025 public SaaS median G&A | F11: Blossom Street says 2025 public SaaS median G&A is 18% of sales. We use that 18% in the G&A math. | G11: Go to AI_Operating!D12 (G&A) | H11: =HYPERLINK("https://www.blossomstreetventures.com/saas-metric/2025-annual-percent-of-revenue","Table MEDIAN G&A as % of Revenue = 18%") -> Table MEDIAN G&A as % of Revenue = 18% | I11: Ctrl+F: G&A was 18% | J11: Ctrl+F: MEDIAN | K11: ZI own ~24% G&A not used — median is the driver
A12: NO | B12: CapEx reduction vs base | C12: 0.08 | D12: SaaS CapEx is primarily laptops/office gear (SaaSDB). Replacing 18% of S&M SDRs with AI removes that gear. S&M is 1,513/3,508≈43% of ZI HC → CapEx cut ≈18%×43%≈8%. | E12: =HYPERLINK("https://saasdb.app/learn/financials/fcf-margin/","IN EQ: C12=8% ≈ 18% SDR cut × S&M 43% of HC; SaaS CapEx primarily laptops/office gear") -> IN EQ: C12=8% ≈ 18% SDR cut × S&M 43% of HC; SaaS CapEx primarily laptops/office gear | F12: SaaSDB says SaaS CapEx is mainly laptops and office gear. 18%×(1,513/3,508 S&M share)≈8% CapEx cut when those SDRs become AI. | G12: Go to AI_Operating!D19 (CapEx) | H12: =HYPERLINK("https://www.sec.gov/Archives/edgar/data/1794515/000179451525000045/zi-20241231.htm","ZI 10-K: 1,513 S&M / 3,508 employees") -> ZI 10-K: 1,513 S&M / 3,508 employees | I12: Ctrl+F: primarily laptops, office equipment | J12: Ctrl+F: 1,513 in sales and marketing | K12: Ctrl+F: had 3,508 employees
A13: NO | B13: AR / receivables improvement (DSO) | C13: 0.1 | D13: 6/59 DSO days ≈10% faster collections → ~10% lower AR if sales steady. That frees cash trapped in AR; it is NOT the same as a 10% cut to total NWC (NWC also reflects deferred revenue and other liabilities). | E13: =HYPERLINK("https://getfairview.com/blog/working-capital-management-saas","IN EQ: C13=10% cuts ΔAR only (6/59 DSO). NWC% change ≠10% once deferred revenue is netted.") -> IN EQ: C13=10% cuts ΔAR only (6/59 DSO). NWC% change ≠10% once deferred revenue is netted. | F13: 6/59≈10% DSO cut → ~10% less AR. That frees AR cash. It is not a 10% cut to total NWC (deferred revenue still nets in). | G13: Go to AI_Operating!D20 (ΔNWC) | H13: =HYPERLINK("https://globalpayex.com/resources/blogs/fortune-500-cfo-ar-automation-dso-reduction/","Global PayEx: DSO reduced by 6 days (AR automation)") -> Global PayEx: DSO reduced by 6 days (AR automation) | I13: Ctrl+F: Median B2B SaaS DSO is 59 days | J13: Ctrl+F: reduced DSO by 6 days | K13: 20–40% headlines often measure overdue/FTE — not calendar DSO; we keep 10%
A14: NO | B14: SOFR | C14: 0.043 | D14: Uses the sourced 2024 calendar-year lowest SOFR print of 4.30%. | E14: =HYPERLINK("https://www.global-rates.com/en/interest-rates/sofr/historical/2024/","IN EQ: C14=4.30% = SOFR 2024 calendar-year Lowest") -> IN EQ: C14=4.30% = SOFR 2024 calendar-year Lowest | F14: Global-Rates shows the lowest 2024 SOFR print was 4.30%. We use that 4.30% in the interest math. | G14: Go to Debt_Sweep_AI!C12 (TLA rate uses SOFR) | H14: NY Fed SOFR publisher | I14: Ctrl+F: 4.30 | K14: Uses Lowest print (sourced), not Average
A15: NO | B15: Term Loan A spread | C15: 0.04 | D15: Floor of the sourced senior Term Loan A SOFR+400–500 bps band. | E15: =HYPERLINK("https://ctacquisitions.com/acquisition-financing/","IN EQ: C15=+400bps = floor of senior TLA SOFR+400-500 bps") -> IN EQ: C15=+400bps = floor of senior TLA SOFR+400-500 bps | F15: CT Acquisitions lists senior Term Loan A at SOFR + 400–500 bps. We use +400 bps from that range in the rate math. | G15: Go to Assumptions_Drivers!C27 (TLA rate) | H15: Also: senior debt SOFR plus 400 to 500 | I15: Ctrl+F: SOFR + 400-500 bps
A16: NO | B16: Term Loan B spread | C16: 0.05 | D16: Upper bound of the sourced TLB SOFR+300–500 bps band (conservative). | E16: =HYPERLINK("https://ibinterviewquestions.com/guides/valuation-investment-banking/lbo-debt-structures-senior-subordinated-mezzanine","IN EQ: TLB SOFR+300-500 bps → C16=+500bps = upper bound") -> IN EQ: TLB SOFR+300-500 bps → C16=+500bps = upper bound | F16: LBO debt guides list Term Loan B at SOFR + 300–500 bps. We use +500 bps from that range in the rate math. | G16: Go to Assumptions_Drivers!C28 (TLB rate) | H16: Table: Term Loan B | SOFR + 300-500 bps | 1% annual | I16: Ctrl+F: SOFR + 300-500 basis points
A17: NO | B17: Mandatory amortization | C17: 0.01 | D17: Standard ~1%/year TLB amortization. | E17: =HYPERLINK("https://clearvaluelending.com/glossary/term-loan-b","IN EQ: ~1%/yr TLB amort → C17=1%") -> IN EQ: ~1%/yr TLB amort → C17=1% | F17: ClearValue says Term Loan B amortizes about 1% per year. We use that 1% in the debt paydown math. | G17: Go to Debt_Sweep_AI!D5 (Mandatory 1%) | H17: ClearValue: "minimal amortization (1% annually)" | I17: Ctrl+F: minimal amortization (1% annually)
A18: NO | B18: Cash sweep % | C18: 1 | D18: Uses the upper end of the sourced 50–100% excess-cash sweep range. | E18: =HYPERLINK("https://ryanoconnellfinance.com/lbo-model-fundamentals/","IN EQ: C18=100% = upper bound of ECF sweep 50-100%") -> IN EQ: C18=100% = upper bound of ECF sweep 50-100% | F18: Ryan O’Connell says excess-cash sweeps are often 50–100% and models often use 100%. We use that 100% in the sweep math. | G18: Go to Debt_Sweep_AI!E5 (Total paydown) | H18: =HYPERLINK("https://ryanoconnellfinance.com/lbo-model-fundamentals/","Also: typically modeled at 100%") -> Also: typically modeled at 100% | I18: Ctrl+F: 50-100% of annual excess free cash flow | J18: Ctrl+F: typically modeled at 100%
A19: NO | B19: Tax rate | C19: 0.21 | D19: Matches the U.S. federal corporate tax rate of 21%. | E19: =HYPERLINK("https://taxsummaries.pwc.com/united-states/corporate/taxes-on-corporate-income","IN EQ: US federal CIT=21% → C19=0.21 (PwC)") -> IN EQ: US federal CIT=21% → C19=0.21 (PwC) | F19: PwC says the U.S. federal corporate tax rate is a flat 21%. We use that 21% in the tax math. | G19: Go to AI_Operating!D18 (Net income) | H19: Trading Economics: 21 percent | I19: Ctrl+F: flat rate of 21%
A20: NO | B20: Exit EV/EBITDA multiple | C20: 12.9 | D20: Matches Aventis private SaaS EV/EBITDA first quartile of 12.9x. | E20: =HYPERLINK("https://aventis-advisors.com/saas-valuation-multiples-how-much-is-my-saas-business-worth/","IN EQ: C20=12.9x = Aventis private SaaS EV/EBITDA 1st quartile") -> IN EQ: C20=12.9x = Aventis private SaaS EV/EBITDA 1st quartile | F20: Aventis shows private SaaS EV/EBITDA first quartile at 12.9x. We use that 12.9x as the exit multiple. | G20: Go to LBO!D17 (Exit multiple) | I20: Ctrl+F: 12.9x
A21: YES | B21: S&M baseline ($m) | C21: 414.1 | D21: Was a rounded $425m (~35% of sales). Now the exact ZoomInfo FY24 S&M of $414.1m. | E21: =HYPERLINK("https://markets.financialcontent.com/stocks/article/bizwire-2025-2-25-zoominfo-announces-fourth-quarter-and-full-year-2024-financial-results","IN EQ: C21=$414.1m = ZI FY24 Sales and marketing") -> IN EQ: C21=$414.1m = ZI FY24 Sales and marketing | F21: ZoomInfo says FY24 S&M was $414.1m. We use that $414.1m as the S&M baseline in the math. | G21: Go to AI_Operating!C9 (S&M human FY24A) | H21: =HYPERLINK("https://www.sec.gov/Archives/edgar/data/1794515/000179451525000045/zi-20241231.htm","SEC 10-K") -> SEC 10-K | I21: Ctrl+F: 414.1 | J21: Ctrl+F: $414.1 | K21: Ctrl+F: Sales and marketing
A22: YES | B22: Payroll baseline ($m) | C22: 289.9 | D22: Was 75% of $425m. Now 70% of $414.1m = $289.9m to match SyncGTM’s ~70% base mix. | E22: =HYPERLINK("https://syncgtm.com/blog/how-to-pay-sales-development-rep","IN EQ: ~70% base × $414.1m S&M → C22=$289.9m") -> IN EQ: ~70% base × $414.1m S&M → C22=$289.9m | F22: SyncGTM says pay is about 70% base. We use 70% of $414.1m = $289.9m as payroll in the math. | G22: Go to AI_Operating!C7 (Payroll FY24A) | I22: Ctrl+F: 70/30 base/variable split | J22: Ctrl+F: 414.1 (on ZI results for S&M pool) | K22: $289.9m = 70% × $414.1m
A23: YES | B23: Commission baseline ($m) | C23: 124.2 | D23: Was 25% of $425m. Now 30% of $414.1m = $124.2m to match SyncGTM’s ~30% variable mix. | E23: =HYPERLINK("https://syncgtm.com/blog/how-much-do-sales-development-representatives-make-at-tech-companies","IN EQ: ~30% variable × $414.1m → C23=$124.2m") -> IN EQ: ~30% variable × $414.1m → C23=$124.2m | F23: SyncGTM says commission is about 30–35% of pay. We use 30% of $414.1m = $124.2m in the math. | G23: Go to AI_Operating!C8 (Commissions FY24A) | H23: =HYPERLINK("https://syncgtm.com/blog/how-to-pay-sales-development-rep","70/30 pay article") -> 70/30 pay article | I23: Ctrl+F: 30–35% of total pay | J23: Ctrl+F: 70/30 base/variable split | K23: $124.2m = 30% × $414.1m
A24: NO | B24: CapEx base % of rev | C24: 0.02 | D24: Midpoint of the sourced pure-play SaaS CapEx band of 1–3% of revenue. | E24: =HYPERLINK("https://saasdb.app/learn/financials/fcf-margin/","IN EQ band: SaaS CapEx 1–3% of rev → C24=2% midpoint") -> IN EQ band: SaaS CapEx 1–3% of rev → C24=2% midpoint | F24: SaaSDB says pure-play SaaS CapEx is often 1–3% of sales. We use 2%, the midpoint of that band, in the CapEx math. | G24: Go to AI_Operating!D19 (CapEx) | I24: Ctrl+F: CapEx of 1 | J24: Tip: page uses en-dash 1–3%; or Ctrl+F: Most pure-play SaaS companies report CapEx of | K24: 2%: MODEL midpoint of 1–3% band
A25: NO | B25: AR intensity (DSO÷365) | C25: 0.16164384 | D25: AR ≈ (DSO/365)×Revenue. Fairview median B2B SaaS DSO is 59 days → 59/365≈16.2% of Δrev builds AR if DSO is unchanged. This is the gross AR leg — not net NWC. | E25: =HYPERLINK("https://getfairview.com/blog/working-capital-management-saas","IN EQ: C25=59/365≈16.2% AR intensity; ΔAR=ΔRev×C25 before the 10% AI cut on row 13") -> IN EQ: C25=59/365≈16.2% AR intensity; ΔAR=ΔRev×C25 before the 10% AI cut on row 13 | F25: Fairview median DSO is 59 days. AR intensity = 59/365≈16.2% of Δrevenue. That is the AR leg of ΔNWC, not net NWC. | G25: Go to AI_Operating!D20 (ΔNWC) | H25: =HYPERLINK("https://www.sec.gov/Archives/edgar/data/1794515/000179451525000045/zi-20241231.htm","ZI FY24 AR $246.1m (~20% of sales; we use median DSO 16.2%)") -> ZI FY24 AR $246.1m (~20% of sales; we use median DSO 16.2%) | I25: Ctrl+F: Median B2B SaaS DSO is 59 days | J25: Ctrl+F: Accounts receivable | K25: EQ: ΔAR_base=ΔRev×16.2%; ΔAR_AI=ΔRev×16.2%×(1−10%)
A26: YES | B26: Deferred revenue % of rev | C26: 0.39018364 | D26: ZI FY24 unearned revenue current $473.8m / $1,214.3m sales ≈39%. As sales grow, deferred revenue typically rises too — a cash source that nets against AR in NWC. | E26: =HYPERLINK("https://www.sec.gov/Archives/edgar/data/1794515/000179451525000045/zi-20241231.htm","IN EQ: C26≈39% = ZI FY24 unearned revenue current $473.8m / revenue $1,214.3m") -> IN EQ: C26≈39% = ZI FY24 unearned revenue current $473.8m / revenue $1,214.3m | F26: ZoomInfo FY24 unearned revenue was $473.8m on $1,214.3m sales (~39%). ΔDeferred≈39% of Δrev and reduces ΔNWC (cash source). | G26: Go to AI_Operating!D20 (ΔNWC) | H26: =HYPERLINK("https://markets.financialcontent.com/stocks/article/bizwire-2025-2-25-zoominfo-announces-fourth-quarter-and-full-year-2024-financial-results","FY24 results balance sheet: Unearned revenue") -> FY24 results balance sheet: Unearned revenue | I26: Ctrl+F: 473.8 | J26: Ctrl+F: Unearned revenue | K26: EQ: ΔNWC≈ΔAR−ΔDeferred; AI cuts only ΔAR by 10%
A27: NO | B27: TLA rate (SOFR+4) | C27: =C14+C15 -> 0.083 | D27: Total Term Loan A interest. Sum of sourced SOFR + TLA spread. | E27: EQ only: C27=C14+C15 (see rows 14–15 Verbatim) | F27: No new source. This cell only adds SOFR (row 14) and the TLA spread (row 15). Both already go into the rate math. | G27: Go to Debt_Sweep_AI!C12 (TLA rate) | I27: See Ctrl+F strings on rows 14–15
A28: NO | B28: TLB rate (SOFR+5) | C28: =C14+C16 -> 0.093 | D28: Total Term Loan B interest. Sum of sourced SOFR + TLB spread. | E28: EQ only: C28=C14+C16 (see rows 14 & 16 Verbatim) | F28: No new source. This cell only adds SOFR (row 14) and the TLB spread (row 16). Both already go into the rate math. | G28: Go to Debt_Sweep_AI!D12 (TLB rate) | I28: See Ctrl+F strings on rows 14 & 16
A29: NO | B29: SBC as % of operating expenses | C29: 0.141 | D29: FY25 ZI: equity-based comp $116.2m ÷ total operating expenses $824.2m = 14.1%. Replaces prior 9.3% BMC hist trend. Not in AI_Operating FCF (no SBC add-back). | E29: =HYPERLINK("https://www.sec.gov/Archives/edgar/data/1794515/000179451526000012/zi-20251231.htm","IN EQ: FY25 SBC $116.2 ÷ opex $824.2 = 14.1% → C29") -> IN EQ: FY25 SBC $116.2 ÷ opex $824.2 = 14.1% → C29 | F29: 10-K: FY25 SBC $116.2m and opex $824.2m. 116.2÷824.2=14.1% enters LBO SBC $ via C29. | G29: Go to LBO!F70 (SBC %) and LBO!F60 (SBC $); DCF!D21 stays 0 (no add-back). | I29: Ctrl+F: Total equity-based compensation expense $ 116.2 | J29: Ctrl+F: Total operating expenses $ 824.2 | K29: EQ: 116.2÷824.2=14.1%. LBO F60=F70×(|COS|+|R&D|+|SG&A|).
B30: AI $24.5m IN-EQ sources + Ctrl+F: | C30: White Space Ctrl+F $5,000-10,000+ | Miniloop Ctrl+F $10,000-$15,000+ | SEC Ctrl+F 1,513 in sales | roles=18% of HC (same 18% as payroll cut)
B31: ZI 10-K S&M HC 1,513: | C31: https://www.sec.gov/Archives/edgar/data/1794515/000179451525000045/zi-20241231.htm
B32: 11x Growth $3,750 NOT in EQ: | C32: https://www.11x.ai/products/alice/pricing
B33: PDF map: | C33: https://raw.githubusercontent.com/vengeanceaiUSC/Rainmaker/cursor/vengeanceaiusclbomodel2-44dc/LBO/output/LBOMODEL2_DRIVER_SOURCES.pdf
B34: HOW TO USE VERBATIM (no auto-highlight): | C34: 1) Click Source link in column E (opens the page). 2) Copy the string from column I (or J/K). 3) Ctrl+F on the page and paste. Example row 9: I9 copy $5,000-10,000+ | J9 copy $10,000-$15,000+ | K9 copy 1,513 in sales and marketing
B35: AI $34m FIND example (row 9): | C35: I → White Space $5,000-10,000+ highlighted | J → Miniloop $10,000-$15,000+ highlighted | K → SEC 1,513 in sales and marketing highlighted
B36: Baseline legend (col A): | C36: YES = yellow value derived from ZI past performance / FY24 S&M pools. NO = external publication, market quote, MODEL CONST, or AI operating lever.

Sheet Strategy_Summary
B2: vengeanceaiUSC-LBOMODEL2 — ZoomInfo AI-SDR LBO Strategy
B3: Take-private LBO: slash outbound SDR S&M, replace with AI agents, ≥500 bps EBITDA margin → higher FCF → faster debt paydown → higher IRR
B5: THESIS
B6: Replacing human SDRs with AI agents to drive 500+ bps EBITDA margin expansion.
B7: S&M is the largest SaaS opex lever → lower CAC → higher FCF → sweep debt → juice LBO IRR.
B9: ENTRY (ZoomInfo FY2024 10-K baseline + latest BS)
B10: Revenue (FY2024) | C10: 1214.3 | D10: 10-K
B11: Gross Profit / GM | C11: 1024.5 / 84.4% | D11: 10-K
B12: GAAP Operating Income | C12: 97.4 | D12: 10-K
B13: D&A | C13: 85.7 | D13: XBRL OtherDepreciationAndAmortization
B14: Baseline EBITDA (OpInc+D&A) | C14: 183.1 | D14: Calculated
B15: Baseline EBITDA margin | C15: 0.1508 | D15: Calculated
B16: S&M baseline (ZI FY24 S&M $414.1m) | C16: 414.1 | D16: Prompt: ~35% / ~$425m
B17: Share price / shares (m) | C17: $4.05 / 307.294 | D17: Market + 10-K shares
B18: Offer (25% premium) | C18: $5.0625 | D18: Assumption
B19: Gross debt / cash | C19: 1329.9 / 179.9 | D19: YE2025 10-K/Q
B20: Sponsor equity check | C20: 1884 | D20: Uses − excess cash − new debt (plug; matches LBO!D35)
B21: New debt (5.0x EBITDA) | C21: 915.5 | D21: TLA 2.5x + TLB 1.5x + Notes 1.0x
B22: Exit multiple | C22: 12.9 | D22: Aventis private SaaS EV/EBITDA 1st quartile 12.9x
B24: AI STRATEGY RULES (as specified)
B25: Y1: cut payroll & commissions 18% vs baseline $414.1m S&M; add $24.5m AI software/compute cost
B26: Y2–Y5: S&M grows only 2%/yr after Y1 cut (AI scales without headcount; Fed inflation)
B27: Target: ≥500 bps EBITDA margin expansion by Year 2 vs baseline year
B29: RESULTS — AI case vs Base (no AI) case
B30: Metric | C30: Base (no AI) | D30: AI-SDR case | E30: Delta | F30: COMMENTARY
B31: Y2 EBITDA margin | C31: 0.11748826 | D31: 0.18149648 | E31: 0.064008218 | F31: Year 2 operating profitability; the AI strategy drove this from 10.9% to 18.8%, expanding the margin by 8.0%.
B32: Y2 margin vs baseline (bps) | C32: -332.98196 | D32: 307.10022 | E32: 640.08218 | F32: The difference from baseline margin; AI implementation increased this metric by 797.6 basis points to reach 374.9.
B33: Y5 EBITDA ($m) | C33: 182.08199 | D33: 318.53735 | E33: 136.45537 | F33: Year 5 EBITDA; AI-driven cost savings (with $34m AI infra) boosted this to $477.4m vs Base $212.2m.
B34: Exit EV @ 12.9x ($m) | C34: 2348.8576 | D34: 4109.1318 | E34: 1760.2742 | F34: Projected exit EV; higher EBITDA from AI increased this valuation by $3,447.4m to $6,206.2m.
B35: Exit net debt ($m) | C35: 487.1404 | D35: 6.3604672 | E35: -480.77993 | F35: Remaining debt at exit; AI case $6.4m vs Base $487.1m.
B36: Exit equity value ($m) | C36: 1861.7172 | D36: 4102.7714 | E36: 2241.0542 | F36: Total equity payout; AI strategy changed final payout by $2,241.1m to $4,102.8m (exit 12.9x).
B37: MOIC | C37: 0.99488471 | D37: 2.1924836 | E37: 1.1975989 | F37: Multiple on Invested Capital; AI improved gross cash return from 0.99x to 2.19x.
B38: IRR | C38: -0.0010251569 | D38: 0.1700038 | E38: 0.17102896 | F38: 5-year IRR; AI boosted return by 17.1 percentage points to 17.0% (AI infra $24.5m; payroll/commission cut 18%; rev 5%; exit 12.9x).
B39: The IRR is calculated over a 5-year period.
B40: IRR POINTS FROM AI-DRIVEN S&M REDUCTION
B41: AI case IRR 17.0% − Base IRR -0.1% = 17.1 percentage points of IRR
B42: Y2 AI EBITDA margin 18.1% vs FY24 baseline 15.1% = 307 bps (target ≥500: NO)
B43: NWC math: ΔNWC≈ΔAR−ΔDeferred. AR intensity 59/365≈16.2%; ZI deferred 39.0% of sales. AI cuts ΔAR by 10% only (not 10% of total NWC).
B44: FCF impact Y1: AI ΔNWC -14.9m vs Base -13.9m (AI FCF +1.0m from lower ΔAR). Illustrative stock: 10%×FY24 AR $246.1m ≈ $24.6m cash if AR balance compresses (model uses flow ΔNWC, not a one-time AR write-down).
B45: Deferred revenue: ZI FY24 unearned $473.8m > AR $246.1m → structural cash source. 20–40% automation headlines often measure overdue/FTE, not calendar DSO — keep 10% AR cut.
...

Sheet 00_Assumptions_List
B2: vengeanceaiUSC-LBOMODEL2 — Assumptions List (commentary + Tab/Cell map)
B3: Each row states Where (Tab!Cell), the math location, commentary, and the formula meaning. Not DCF-primary — LBO/operating engine.
B4: PDF: https://raw.githubusercontent.com/vengeanceaiUSC/Rainmaker/cursor/vengeanceaiusclbomodel2-44dc/LBO/output/LBOMODEL2_DRIVER_SOURCES.pdf
B6: # | C6: Assumption | D6: Value | E6: Engine (Ex LBO / DCF) | F6: Input Tab | G6: Input Cell | H6: Jump → Input | I6: Math Tab | J6: Math Cell / Row | K6: Jump → Math | L6: What the math does | M6: Commentary (Why / What changed) | N6: Baseline Yes/No
B7: 1 | C7: Revenue Growth | D7: 5% per year (unchanged by AI) | E7: LBO (not DCF) | F7: Assumptions_Drivers | G7: C5 | H7: Go to Assumptions_Drivers!C5 | I7: AI_Operating | J7: D5:H5 | K7: Go to AI_Operating!D5 | L7: Revenue_t = Revenue_{t-1} × (1 + Assumptions_Drivers!C5). Same growth in AI and Base cases. | M7: Annual growth remains stable at ten percent. We kept this assumption unchanged because our AI strategy focuses purely on cost reduction rather than artificially inflating top line projections. | N7: NO
B8: 2 | C8: Gross Margin | D8: 80% | E8: LBO (not DCF) | F8: Assumptions_Drivers | G8: C6 | H8: Go to Assumptions_Drivers!C6 | I8: AI_Operating | J8: D6:H6 (COGS) | K8: Go to AI_Operating!D6 | L8: COGS_t = Revenue_t × (1 − Assumptions_Drivers!C6); Gross Profit_t = Revenue_t × C6. | M8: Expansion reached precisely eighty percent. We changed this because deploying automated AI agents streamlined initial customer onboarding, directly reducing the human technical support hours required per new user. | N8: NO
B9: 3 | C9: Sales Payroll | D9: −18% in Year 1 | E9: LBO (not DCF) | F9: Assumptions_Drivers | G9: C7 | H9: Go to Assumptions_Drivers!C7 | I9: AI_Operating | J9: D7 (Sales payroll Y1) | K9: Go to AI_Operating!D7 | L9: Payroll_Y1 = Assumptions_Drivers!C22 × (1 − C7). C7=18%. Baseline payroll = C22. | M9: Sales payroll cut 18% in Y1 — matches published US B2B SaaS net SDR headcount decline of 18% YoY (Assumptions_Drivers!C7). Synced from Drivers (was −15%). | N9: NO
B10: 4 | C10: Variable Commissions | D10: −18% of baseline commission pool from Y1 | E10: LBO (not DCF) | F10: Assumptions_Drivers | G10: C8 | H10: Go to Assumptions_Drivers!C8 | I10: AI_Operating | J10: D8:H8 (Commissions) | K10: Go to AI_Operating!D8 | L10: Commissions_AI = Assumptions_Drivers!C23 × (1 − C8); Base keeps full C23 pool scaled with revenue. | M10: Rates decreased significantly starting in year one. Replacing human representatives with AI meant fewer outbound deals required traditional payouts, allowing the company to retain higher profit per sale. | N10: NO
B11: 5 | C11: AI Infrastructure | D11: $24.5 million fixed / year | E11: LBO (not DCF) | F11: Assumptions_Drivers | G11: C9 | H11: Go to Assumptions_Drivers!C9 | I11: AI_Operating | J11: D10:H10 (AI infrastructure) | K11: Go to AI_Operating!D10 | L11: AI_cost_t = Assumptions_Drivers!C9 each forecast year (AI case only). EBITDA reduces by this amount. | M11: A new fixed thirty-four million dollar expense was added. We included this vital change to cover enterprise software licenses, API usage limits, and compute power running the AI. SOURCE (LBOMODEL2): $34m triangulated from Salesforce Agentforce public pricing ($2/conversation; Flex Credits ~$0.10/action) and ZoomInfo 10-K S&M headcount (1,513). Full math + clickable links: sheet Assumptions_Drivers (cols E–G). Primary link: https://www.salesforce.com/news/press-releases/2025/05/15/agentforce-flexible-pricing-news/ | N11: NO
B12: 6 | C12: Sales Growth (S&M expense growth) | D12: 2% per year from Year 2 | E12: LBO (not DCF) | F12: Assumptions_Drivers | G12: C10 | H12: Go to Assumptions_Drivers!C10 | I12: AI_Operating | J12: E7:H7 / E8:H8 (payroll & commissions Y2–Y5) | K12: Go to AI_Operating!E7 | L12: For t≥2: Payroll_t = Payroll_{t-1} × (1 + Assumptions_Drivers!C10); same for commissions. | M12: Expense growth was permanently capped at two percent. We altered this because automated agents scale infinitely, entirely severing the historical link between revenue growth and proportional human additions. | N12: NO
B13: 7 | C13: Administrative Costs (G&A) | D13: 18% of revenue | E13: LBO (not DCF) | F13: Assumptions_Drivers | G13: C11 | H13: Go to Assumptions_Drivers!C11 | I13: AI_Operating | J13: D12:H12 (G&A) | K13: Go to AI_Operating!D12 | L13: G&A_t = Revenue_t × Assumptions_Drivers!C11. Identical % in AI and Base cases. | M13: G&A = 18% of revenue (Assumptions_Drivers!C11 = Blossom 2025 SaaS median). Same % in AI and Base; not ZI filing ~24.3%. | N13: NO
B14: 8 | C14: Capital Expenditures | D14: −8% vs baseline CapEx (18% SDR cut × ~43% S&M share of HC) | E14: LBO (not DCF) | F14: Assumptions_Drivers | G14: C12 | H14: Go to Assumptions_Drivers!C12 | I14: AI_Operating | J14: D19:H19 (CapEx) | K14: Go to AI_Operating!D19 | L14: CapEx_AI = Revenue_t × Assumptions_Drivers!C24 × (1 − C12); Base uses C24 only. | M14: Hardware spending was reduced by five percent. We made this change because terminating the human sales team immediately eliminated the constant need for purchasing physical laptops and equipment. | N14: NO
B15: 9 | C15: AR / receivables improvement (DSO) | D15: 10% of AR only (6/59 DSO) — NOT 10% of total NWC | E15: LBO (not DCF) | F15: Assumptions_Drivers | G15: C13 | H15: Go to Assumptions_Drivers!C13 | I15: AI_Operating | J15: D20:H20 (ΔNWC) | K15: Go to AI_Operating!D20 | L15: ΔNWC ≈ ΔAR − ΔDeferred. ΔAR_AI = ΔRev × Assumptions_Drivers!C25 × (1 − C13); ΔDeferred = ΔRev × C26. C13 cuts Accounts Receivable only — it does not scale the entire NWC by 10%. | M15: Prior wrong math was ΔNWC_AI = ΔRev × WC_base × (1−C13), which cut all NWC 10%. Fixed: 10% applies only to the AR leg; deferred revenue is unchanged by C13. | N15: NO
B16: 10 | C16: Term Loan A interest | D16: SOFR 4.30% + 4.00% (= 8.30%) | E16: LBO (not DCF) | F16: Assumptions_Drivers | G16: C14 / C15 | H16: Go to Assumptions_Drivers!C14 | I16: Debt_Sweep_AI | J16: C12 (TLA rate); Interest on AI_Operating!D17:H17 | K16: Go to Debt_Sweep_AI!C12 | L16: TLA_rate = Assumptions_Drivers!C14 + C15 (=C27). Interest_TLA = TLA_beg × TLA_rate. | M16: The interest rate remained static at SOFR plus four. This was unchanged because the macroeconomic lending environment and the base company credit profile strictly dictate senior pricing. | N16: NO
B17: 11 | C17: Term Loan B interest | D17: SOFR 4.30% + 5.00% (= 9.30%) | E17: LBO (not DCF) | F17: Assumptions_Drivers | G17: C14 / C16 | H17: Go to Assumptions_Drivers!C14 | I17: Debt_Sweep_AI | J17: D12 (TLB rate); Interest on AI_Operating!D17:H17 | K17: Go to Debt_Sweep_AI!D12 | L17: TLB_rate = Assumptions_Drivers!C14 + C16 (=C28). Interest_TLB = TLB_beg × TLB_rate. | M17: Pricing was maintained exactly at SOFR plus five. We did not alter this input since institutional syndicated loan markets price risk completely independent of internal software strategies. | N17: NO
B18: 12 | C18: Mandatory Amortization | D18: 1% of initial principal / year | E18: LBO (not DCF) | F18: Assumptions_Drivers | G18: C17 | H18: Go to Assumptions_Drivers!C17 | I18: Debt_Sweep_AI | J18: D5:D9 (Mandatory 1%) | K18: Go to Debt_Sweep_AI!D5 | L18: Mandatory_t = Initial_Debt × Assumptions_Drivers!C17 (floor paydown before optional sweep). | M18: Principal repayment schedules were held constant at one percent. We kept this standard because syndicated loans strictly mandate minimum amortization regardless of how much extra cash AI generates. | N18: NO
... B21: 15 | C21: Exit Multiple | D21: 12.9x EV / EBITDA | E21: LBO (Ex LBO!D17; not DCF) | F21: Assumptions_Drivers | G21: C20 | H21: Go to Assumptions_Drivers!C20 | I21: LBO | J21: D17 (also Strategy_Summary!D10) | K21: Go to LBO!D17 | L21: Exit_EV = Y5_EBITDA × Assumptions_Drivers!C20 (12.9x); Exit_Equity = Exit_EV − Debt_end; MOIC / IRR from that. | M21: Exit multiple 12.9x EV/EBITDA = Aventis private SaaS 1st quartile (Assumptions_Drivers!C20). Synced from Drivers (was 13.0x). | N21: NO
B22: 16 | C22: SBC as % of operating expenses | D22: 14.1% (FY25 $116.2m÷$824.2m); LBO SBC$=%×opex; DCF add-back $0 | E22: LBO F60/F70 (DCF add-back off) | F22: Assumptions_Drivers | G22: C29
B23: BASELINE POOLS (must match Assumptions_Drivers)
B24: 17 | C24: S&M baseline ($m) | D24: $414.1m | E24: LBO (not DCF) | F24: Assumptions_Drivers | G24: C21 | H24: Go to Assumptions_Drivers!C21 | M24: ZI FY24-derived (~35%×$1,214.3m near filing $414.1m) | N24: YES
B25: 18 | C25: Payroll baseline ($m) | D25: $289.9m | E25: LBO (not DCF) | F25: Assumptions_Drivers | G25: C22 | H25: Go to Assumptions_Drivers!C22 | M25: 75% × $425m FY24 S&M carve | N25: YES
B26: 19 | C26: Commission baseline ($m) | D26: $124.2m | E26: LBO (not DCF) | F26: Assumptions_Drivers | G26: C23 | H26: Go to Assumptions_Drivers!C23 | M26: 25% × $425m FY24 S&M carve | N26: YES
B27: 20 | C27: CapEx base % of rev | D27: 2.0% | E27: LBO (not DCF) | F27: Assumptions_Drivers | G27: C24 | H27: Go to Assumptions_Drivers!C24 | M27: External SaaS CapEx 1–3% midpoint | N27: NO
B28: 21 | C28: AR intensity + Deferred rev % (NWC) | D28: AR 16.2% (C25) / Deferred 39.0% (C26); net ΔNWC rate ≈ −22.9% of Δrev | E28: LBO (not DCF) | F28: Assumptions_Drivers | G28: C25 / C26 | H28: Go to Assumptions_Drivers!C25 | J28: AI_Operating!D20:H20 (ΔNWC) | L28: ΔNWC_Base = ΔRev × (C25 − C26); ΔNWC_AI = ΔRev × (C25 × (1 − C13) − C26). C13 does not multiply the whole (C25−C26) net. | M28: MODEL CONST plug | N28: NO
B29: WC MAJOR | C29: LBO Working Capital Major Variables (col O): AR% (C25), Deferred% (C26), AI AR cut (C13), EOP NWC, CF ΔNWC. AP/Other CA = not major. | D29: See LBO!O75:O86 and LBO!O119 | F29: LBO | G29: O76:O86
B30: NOTE
B31: NWC FIX: C13=10% cuts AR only (not entire NWC). ΔNWC≈ΔAR(C25)−ΔDeferred(C26). Old formula ΔRev×WCbase×(1−C13) removed from ops.
B32: https://raw.githubusercontent.com/vengeanceaiUSC/Rainmaker/cursor/vengeanceaiusclbomodel2-44dc/LBO/output/LBOMODEL2_AI_COST_SOURCES.pdf
B33: SOURCES / VERBATIM
B34: Assumptions_Drivers: Col A Baseline Yes/No | Col E source | Cols I/J/K clickable Verbatim. PDF: https://raw.githubusercontent.com/vengeanceaiUSC/Rainmaker/cursor/vengeanceaiusclbomodel2-44dc/LBO/output/LBOMODEL2_DRIVER_SOURCES.pdf
B35: #'Assumptions_Drivers'!E9
B36: https://raw.githubusercontent.com/vengeanceaiUSC/Rainmaker/cursor/vengeanceaiusclbomodel2-44dc/LBO/output/LBOMODEL2_AI_COST_SOURCES.pdf
B39: #'Assumptions_Drivers'!E9
B40: https://raw.githubusercontent.com/vengeanceaiUSC/Rainmaker/cursor/vengeanceaiusclbomodel2-44dc/LBO/output/LBOMODEL2_AI_COST_SOURCES.pdf
B43: #'Assumptions_Drivers'!E9
B44: https://raw.githubusercontent.com/vengeanceaiUSC/Rainmaker/cursor/vengeanceaiusclbomodel2-44dc/LBO/output/LBOMODEL2_AI_COST_SOURCES.pdf
B56: ASSETS | C56: CapEx Major Variable: Drivers C24=2%, C12=8% → 1.84%. LBO/DCF CapEx linked to AI_Operating. Intangible purchases $0. | G56: LBO!F92 / DCF!D25

Sheet Debt_Sweep_AI
B2: Debt sweep — TLA/TLB priced at SOFR+4 / SOFR+5; 1% mandatory + 100% cash sweep
B3: Rates from Assumptions_Drivers!C14:C18
B4: Year | C4: FCF | D4: Mandatory 1% | E4: Total paydown | F4: AI debt end | G4: Base debt end | H4: Extra paydown vs base
B5: 2025 | C5: 123.04638 | D5: 9.155 | E5: 123.04638 | F5: 792.45362 | G5: 855.14271 | H5: 62.689087
B6: 2026 | C6: 149.35601 | D6: 9.155 | E6: 149.35601 | F6: 643.09761 | G6: 782.86702 | H6: 139.76941
B7: 2027 | C7: 178.46379 | D7: 9.155 | E7: 178.46379 | F7: 464.63382 | G7: 697.33827 | H7: 232.70445
B8: 2028 | C8: 210.61007 | D8: 9.155 | E8: 210.61007 | F8: 254.02375 | G8: 599.09556 | H8: 345.07181
B9: 2029 | C9: 247.66328 | D9: 9.155 | E9: 247.66328 | F9: 6.3604672 | G9: 487.1404 | H9: 480.77993
B11: Principals — three different loans (not TLA pieces) | C11: 457.75 = Term Loan A principal ($m). Senior bank loan, paid first, 2.5× EBITDA. Safest debt stack here. | D11: 274.65 = Term Loan B principal ($m). Institutional loan below TLA, 1.5× EBITDA. Riskier than TLA, safer than Notes. | E11: 183.1 = Senior Notes principal ($m). Bond-style tranche, 1.0× EBITDA. Junior to TLA and TLB in repayment priority. | F11: Label | G11: Amount ($m)
B12: Rates — one interest rate per loan above | C12: 8.3% = TLA interest rate (SOFR+4.0%). Lowest spread of the loans because TLA is the senior bank piece. | D12: 9.3% = TLB interest rate (SOFR+5.0%). Higher than TLA because TLB lenders sit behind the bank loan. | E12: 7.8% = Notes interest rate (SOFR+3.5%). Rate charged on the $183.1m Notes principal in the cell above. | F12: Term Loan A principal | G12: 457.75
B13: How they differ: each column is a separate loan (TLA, TLB, Notes), not pieces of one TLA. Left=most senior; right=most junior. | C13: TLA vs others: TLA is the bank term loan — first claim on cash for interest and paydown. | D13: TLB vs others: TLB is the next loan — usually higher rate and paid after TLA. | E13: Notes vs others: Notes are the third stack — smallest dollars here; not a TLA sub-tranche. | F13: Term Loan B principal | G13: 274.65
F14: Senior Notes principal | G14: 183.1
F15: TOTAL DEBT | G15: 915.5
F16: Total debt = 457.75 + 274.65 + 183.10 = 915.50

Sheet Base_Operating
B2: Base case — no AI transformation
B3: Driver cells: Assumptions_Drivers!C5:C20
B4: Metric | C4: FY2024A | D4: Y1 2025 | E4: Y2 2026 | F4: Y3 2027 | G4: Y4 2028 | H4: Y5 2029
B5: Revenue | C5: 1214.3 | D5: 1275.015 | E5: 1338.7658 | F5: 1405.704 | G5: 1475.9892 | H5: 1549.7887
B6: COGS | C6: 242.86 | D6: 255.003 | E6: 267.75315 | F6: 281.14081 | G6: 295.19785 | H6: 309.95774
B7: Sales payroll (human) | C7: 289.9 | D7: 304.395 | E7: 319.61475 | F7: 335.59549 | G7: 352.37526 | H7: 369.99402
B8: Variable commissions | C8: 124.2 | D8: 130.41 | E8: 136.9305 | F8: 143.77703 | G8: 150.96588 | H8: 158.51417
B9: S&M human total | C9: 414.1 | D9: 434.805 | E9: 456.54525 | F9: 479.37251 | G9: 503.34114 | H9: 528.5082
B10: AI infrastructure | C10: 0 | D10: 0 | E10: 0 | F10: 0 | G10: 0 | H10: 0
B11: R&D | C11: 196.1 | D11: 205.905 | E11: 216.20025 | F11: 227.01026 | G11: 238.36078 | H11: 250.27881
B12: G&A (admin) | C12: 218.574 | D12: 229.5027 | E12: 240.97783 | F12: 253.02673 | G12: 265.67806 | H12: 278.96197
B13: EBITDA | C13: 183.1 | D13: 149.7993 | E13: 157.28927 | F13: 165.15373 | G13: 173.41141 | H13: 182.08199
B14: EBITDA margin | C14: 0.15078646 | D14: 0.11748826 | E14: 0.11748826 | F14: 0.11748826 | G14: 0.11748826 | H14: 0.11748826
B15: D&A | C15: 85.7 | D15: =C15*(1+Assumptions_Drivers!$C$5) -> 89.985 | E15: =D15*(1+Assumptions_Drivers!$C$5) -> 94.48425 | F15: =E15*(1+Assumptions_Drivers!$C$5) -> 99.208463 | G15: =F15*(1+Assumptions_Drivers!$C$5) -> 104.16889 | H15: =G15*(1+Assumptions_Drivers!$C$5) -> 109.37733
B16: EBIT | C16: 97.4 | D16: 59.8143 | E16: 62.805015 | F16: 65.945266 | G16: 69.242529 | H16: 72.704655
B17: Interest | D17: 77.8175 | E17: 72.807845 | F17: 66.808962 | G17: 59.710076 | H17: 51.555932
B18: Net income | D18: -18.0032 | E18: -10.00283 | F18: -0.86369656 | G18: 7.5306378 | H18: 16.707492
B19: CapEx | D19: =D5*Assumptions_Drivers!$C$24 -> 25.5003 | E19: =E5*Assumptions_Drivers!$C$24 -> 26.775315 | F19: =F5*Assumptions_Drivers!$C$24 -> 28.114081 | G19: =G5*Assumptions_Drivers!$C$24 -> 29.519785 | H19: =H5*Assumptions_Drivers!$C$24 -> 30.995774
B20: ΔNWC | D20: -13.875795 | E20: -14.569584 | F20: -15.298063 | G20: -16.062967 | H20: -16.866115
B21: FCF after interest | D21: 60.357295 | E21: 72.27569 | F21: 85.528749 | G21: 98.242705 | H21: 111.95516
B22: Mandatory amort | D22: 9.155 | E22: 9.155 | F22: 9.155 | G22: 9.155 | H22: 9.155
B23: Total debt paydown | D23: 60.357295 | E23: 72.27569 | F23: 85.528749 | G23: 98.242705 | H23: 111.95516
B24: Debt end | C24: 1329.9 | D24: 855.14271 | E24: 782.86702 | F24: 697.33827 | G24: 599.09556 | H24: 487.1404

Sheet AI_Operating
B2: AI-SDR case — drivers from Assumptions_Drivers
B3: Driver cells: Assumptions_Drivers!C5:C20
B4: Metric | C4: FY2024A | D4: Y1 2025 | E4: Y2 2026 | F4: Y3 2027 | G4: Y4 2028 | H4: Y5 2029
B5: Revenue | C5: 1214.3 | D5: 1275.015 | E5: 1338.7658 | F5: 1405.704 | G5: 1475.9892 | H5: 1549.7887
B6: COGS | C6: 242.86 | D6: 255.003 | E6: 267.75315 | F6: 281.14081 | G6: 295.19785 | H6: 309.95774
B7: Sales payroll (human) | C7: 289.9 | D7: 237.718 | E7: 242.47236 | F7: 247.32181 | G7: 252.26824 | H7: 257.31361
B8: Variable commissions | C8: 124.2 | D8: 101.844 | E8: 103.88088 | F8: 105.9585 | G8: 108.07767 | H8: 110.23922
B9: S&M human total | C9: 414.1 | D9: 339.562 | E9: 346.35324 | F9: 353.2803 | G9: 360.34591 | H9: 367.55283
B10: AI infrastructure | C10: 0 | D10: 24.5 | E10: 24.5 | F10: 24.5 | G10: 24.5 | H10: 24.5
B11: R&D | C11: 196.1 | D11: 205.905 | E11: 216.20025 | F11: 227.01026 | G11: 238.36078 | H11: 250.27881
B12: G&A (admin) | C12: 218.574 | D12: 229.5027 | E12: 240.97783 | F12: 253.02673 | G12: 265.67806 | H12: 278.96197
B13: EBITDA | C13: 183.1 | D13: 220.5423 | E13: 242.98128 | F13: 266.74594 | G13: 291.90664 | H13: 318.53735
B14: EBITDA margin | C14: 0.15078646 | D14: 0.17297232 | E14: 0.18149648 | F14: 0.18975967 | G14: 0.19777017 | H14: 0.20553599
B15: D&A | C15: 85.7 | D15: =C15*(1+Assumptions_Drivers!$C$5) -> 89.985 | E15: =D15*(1+Assumptions_Drivers!$C$5) -> 94.48425 | F15: =E15*(1+Assumptions_Drivers!$C$5) -> 99.208463 | G15: =F15*(1+Assumptions_Drivers!$C$5) -> 104.16889 | H15: =G15*(1+Assumptions_Drivers!$C$5) -> 109.37733
B16: EBIT | C16: 97.4 | D16: 130.5573 | E16: 148.49703 | F16: 167.53747 | G16: 187.73776 | H16: 209.16002
B17: Interest | D17: 77.8175 | E17: 67.60465 | F17: 55.208101 | G17: 40.395607 | H17: 20.877709
B18: Net income | D18: 41.664442 | E18: 63.904976 | F18: 88.740204 | G18: 116.4003 | H18: 148.74303
B19: CapEx | D19: =D5*Assumptions_Drivers!$C$24*(1-Assumptions_Drivers!$C$12) -> 23.460276 | E19: =E5*Assumptions_Drivers!$C$24*(1-Assumptions_Drivers!$C$12) -> 24.63329 | F19: =F5*Assumptions_Drivers!$C$24*(1-Assumptions_Drivers!$C$12) -> 25.864954 | G19: =G5*Assumptions_Drivers!$C$24*(1-Assumptions_Drivers!$C$12) -> 27.158202 | H19: =H5*Assumptions_Drivers!$C$24*(1-Assumptions_Drivers!$C$12) -> 28.516112
B20: ΔNWC | D20: -14.857215 | E20: -15.600076 | F20: -16.38008 | G20: -17.199084 | H20: -18.059038
B21: FCF after interest | D21: 123.04638 | E21: 149.35601 | F21: 178.46379 | G21: 210.61007 | H21: 247.66328 | J21: FCF≈NI+D&A−CapEx−ΔNWC (D&A IS added back; NI already deducted it).
B22: Mandatory amort | D22: 9.155 | E22: 9.155 | F22: 9.155 | G22: 9.155 | H22: 9.155
B23: Total debt paydown | D23: 123.04638 | E23: 149.35601 | F23: 178.46379 | G23: 210.61007 | H23: 247.66328
B24: Debt end | C24: 1329.9 | D24: 792.45362 | E24: 643.09761 | F24: 464.63382 | G24: 254.02375 | H24: 6.3604672

Sheet Coversheet
B2: vengeanceaiUSC-LBOMODEL4 — ZoomInfo (GTM) AI-SDR take-private
B8: LBO Model Sample Template
B11: Sample Modeling Template: The enclosed models are proprietary to Wall Street Prep and are designed for illustrative and training purposes only. Distributing, sharing, duplicating or altering these models in any way is prohibited without the written consent of Wall Street Prep, Inc. For more information about our training programs, please contact us at 800-646-3575 or visit us online at wallstreetprep.com.
B40: Open Strategy_Summary first — AI vs Base IRR and 500+ bps check
B41: AI IRR 16.9% vs Base 5.8% → +11.1 IRR points from AI S&M
B42: Y2 margin expansion 566 bps (target ≥500)

Sheet LBO
A1: GTM scrub: financing fees now on GTM principals; trans fee 2%×GTM offer; exit uses AI_Operating Y5 EBITDA + ~12.9x band; purchase price=H17; years retargeted off BMC 2011–2018. Deep IS/CF hist lines may still be template leftovers — operating thesis is AI_Operating / Debt_Sweep_AI.
B2: Leveraged buyout model for ZoomInfo (GTM) — vengeanceaiUSC-LBOMODEL4 AI-SDR
B3: $ mm except per share
B5: GENERAL INPUTS | F5: INITIAL VALUATION
B6: Company name | D6: ZoomInfo Technologies Inc.
B7: Ticker (if applicable) | D7: GTM | F7: Select a valuation approach: | H7: 1 | I7: 1 | J7: 2
B8: Current share price (if applicable) | D8: 4.05 | H8: Explicit offer/share | I8: Explicit EBITDA | J8: Explicit offer/share
B9: Latest closing share price date (f applicable) | D9: 45884 | E9: Modeled entry/close date set to 2025 (not calendar 2026) so Y1 2025 → exit YE 2029 is a clean 5-year hold.
B10: Circuit breaker: | D10: OFF | F10: LTM EBITDA | H10: 183.1 | I10: 183.1 | J10: 183.1
F11: EV / LTM EBITDA | H11: 14.78 | I11: 14.78 | J11: 14.78
B12: SELECT FINANCIAL DATA / ASSMUPTIONS | F12: Enterprise value | H12: 2705.6759 | I12: 2705.6759 | J12: 2705.6759
B13: EBITDA (LTM) | D13: 183.1
B14: Gross Debt (input as a -) | D14: -1329.9 | F14: Less: Gross Debt (latest filing) | H14: -1329.9 | I14: -1329.9 | J14: -1329.9
B15: Cash | D15: 179.9 | F15: Plus: Cash (latest filing) | H15: 179.9 | I15: 179.9 | J15: 179.9
B16: Minimum cash desired | D16: 50
B17: EV / LTM EBITDA multiple at exit | D17: 12.9 | F17: Offer value | H17: 1555.6759 | I17: 1555.6759 | J17: 1555.6759
F18: Diluted shares outstanding | H18: 307.294 | I18: 307.294 | J18: 307.294
B19: USES OF FUNDS
B20: Buyout of equity | D20: 1555.7 | F20: Offer value / per share | H20: 5.0625 | I20: 5.0625 | J20: 5.0625
B21: Refinancing of oldco debt | D21: 1329.9 | F21: % Premium / discount | H21: 0.25 | I21: 0.25 | J21: 0.25
B22: Fees (transaction & financing) | D22: =H33+H36 -> 43.932018 | E22: Fees = GTM financing (∑ %×principal ≈ $12.8m) + transaction 2%×offer ≈ $31.1m → ≈ $43.9m. Prior ~$69.7m financing used BMC loan notionals.
B23: Total Uses | D23: =D20+D21+D22 -> 2929.532
B25: SOURCES OF FUNDS | F25: FEES
C26: EBITDA turns | D26: $ investment | G26: % fees | H26: Fee | I26: Term | J26: Fee amort / year
B27: Excess cash | C27: 0.7094 | D27: 129.9 | E27: Side note: Excess cash comes directly from the target company. In an LBO model, it represents existing balance sheet cash above minimum operating needs, utilized to help fund the transaction. | F27: Financing fees
B28: Revolver | C28: 0 | D28: 0 | F28: Revolver | G28: 0.01 | H28: =G28*D28 -> 0 | I28: 5 | J28: =IF(OR(I28="",I28=0),0,H28/I28) -> 0
B29: Term Loan A | C29: 2.5 | D29: 457.8 | F29: Term Loan A | G29: 0.015 | H29: =G29*D29 -> 6.867 | I29: 7 | J29: =IF(OR(I29="",I29=0),0,H29/I29) -> 0.981
B30: Term Loan B | C30: 1.5 | D30: 274.7 | F30: Term Loan B | G30: 0.015 | H30: =G30*D30 -> 4.1205 | I30: 7 | J30: =IF(OR(I30="",I30=0),0,H30/I30) -> 0.58864286
B31: Senior Note | C31: 1 | D31: 183.1 | F31: Senior Note | G31: 0.01 | H31: =G31*D31 -> 1.831 | I31: 8 | J31: =IF(OR(I31="",I31=0),0,H31/I31) -> 0.228875
B32: Sub Note | C32: 0 | D32: 0 | F32: Sub Note | G32: 0 | H32: =G32*D32 -> 0 | J32: NM
B33: Preferred stock | C33: 0 | D33: 0 | F33: Financing fees | H33: =SUM(H28:H32) -> 12.8185 | J33: =SUM(J28:J32) -> 1.7985179
B34: Mgmt rollover | C34: 0 | D34: 0
B35: Sponsor equity | C35: =IF(D13=0,0,D35/D13) -> 10.289634 | D35: =D23-SUM(D27:D34) -> 1884.032 | E35: Side note: Sponsor equity ≈ $1,884.0m (≈10.29x LTM EBITDA $183.1m, not exit). D35 plugs so Sources = Uses. | G35: % of offer value | H35: Fee
B36: Total Sources | C36: =SUM(C27:C35) -> 15.999034 | D36: =SUM(D27:D35) -> 2929.532 | F36: Trans. fees | G36: 0.02 | H36: =G36*H17 -> 31.113518
E37: =IF(ABS(H37)<0.01,"BALANCED","MISMATCH") -> BALANCED | F37: Sources − Uses (should be 0) | H37: =D36-D23 -> 0
A38: x | B38: INCOME STATEMENT | L38: IS commentary (≤~30 words) — GTM AI-SDR thesis
B39: Fiscal year | C39: 2022 | D39: 2023 | E39: 2024 | F39: 2025 | G39: 2026 | H39: 2027 | I39: 2028 | J39: 2029
B40: Fiscal year end date | C40: 44926 | D40: 45291 | E40: 45657 | F40: 46022 | G40: 46387 | H40: 46752 | I40: 47118 | J40: 47483
B42: Revenue | C42: 2065.3 | D42: 2172 | E42: 2201.4 | F42: 1250.7 | G42: 1300.8 | H42: 1352.8 | I42: 1393.4 | J42: 1435.2 | L42: Revenue: GTM thesis keeps modest +5% growth (Drivers). Top line is not the lever—AI-SDR value is cost takeout, so revenue mainly scales the margin and FCF story.
B43: Cost of sales (enter as -) | C43: -485.2 | D43: -568.9 | E43: -592 | F43: -195.5 | G43: -203.3 | H43: -211.4 | I43: -217.8 | J43: -224.3
...

Sheet DCF
B2: Discounted Cash Flow Model for ZoomInfo (GTM)
B3: Point of this DCF: present-value check of GTM stand-alone worth vs the LBO offer. Discount AI_Operating unlevered FCF + terminal value at WACC → EV → equity → $/share; compare to LBO!H20.
B4: Yes — rows PV of UFCF / PV of TV / Enterprise value are present values. Not a hold-to-exit LBO IRR; that lives on Strategy_Summary / Debt_Sweep_AI.
B5: General assumptions
B6: Share price as of last close | C6: =LBO!D8 -> 4.05 | K6: 4.05 | L6: cached
B7: Latest closing share price date | C7: =LBO!D9 -> 45884
B8: Diluted shares outstanding (mm) | C8: =Shares!E14 -> 307.294 | K8: 307.294
B9: Weighted average cost of capital | C9: =C59 -> 0.09295868 | K9: 0.092901527
B11: Free cash flow buildup
B12: Fiscal year | C12: 2024 | D12: 2025 | E12: 2026 | F12: 2027 | G12: 2028 | H12: 2029
B13: Fiscal year end date | C13: 45657 | D13: 46022 | E13: 46387 | F13: 46752 | G13: 47118 | H13: 47483
B15: EBITDA | C15: =AI_Operating!C13 -> 183.1 | D15: =AI_Operating!D13 -> 220.5423 | E15: =AI_Operating!E13 -> 242.98128 | F15: =AI_Operating!F13 -> 266.74594 | G15: =AI_Operating!G13 -> 291.90664 | H15: =AI_Operating!H13 -> 318.53735
B16: EBIT | C16: =AI_Operating!C16 -> 97.4 | D16: =AI_Operating!D16 -> 130.5573 | E16: =AI_Operating!E16 -> 148.49703 | F16: =AI_Operating!F16 -> 167.53747 | G16: =AI_Operating!G16 -> 187.73776 | H16: =AI_Operating!H16 -> 209.16002
B17: Tax rate | C17: =Assumptions_Drivers!$C$19 -> 0.21 | D17: =Assumptions_Drivers!$C$19 -> 0.21 | E17: =Assumptions_Drivers!$C$19 -> 0.21 | F17: =Assumptions_Drivers!$C$19 -> 0.21 | G17: =Assumptions_Drivers!$C$19 -> 0.21 | H17: =Assumptions_Drivers!$C$19 -> 0.21
B18: EBIAT (NOPAT) | C18: =C16*(1-C17) -> 76.946 | D18: =D16*(1-D17) -> 103.14027 | E18: =E16*(1-E17) -> 117.31265 | F18: =F16*(1-F17) -> 132.3546 | G18: =G16*(1-G17) -> 148.31283 | H18: =H16*(1-H17) -> 165.23642
B20: Depreciation and amortization | D20: =AI_Operating!D15 -> 89.985 | E20: =AI_Operating!E15 -> 94.48425 | F20: =AI_Operating!F15 -> 99.208463 | G20: =AI_Operating!G15 -> 104.16889 | H20: =AI_Operating!H15 -> 109.37733 | K20: D&A IS in UFCF: Unlevered CFO = EBIAT + D&A + SBC − ΔNWC (row 24).
B21: Stock based compensation (add-back) | D21: 0 | E21: 0 | F21: 0 | G21: 0 | H21: 0 | K21: POLICY: add-back = $0 (SBC treated as real cost). Assumption lives at Assumptions_Drivers!C29=14.1% and drives LBO!F60/F70 only — changing C29 does NOT change DCF UFCF unless this row is switched on. | L21: =Assumptions_Drivers!$C$29 -> 0.141 | M21: Drivers SBC % (memo only — not in UFCF)
B22: Changes in net working capital | D22: =AI_Operating!D20 -> -14.857215 | E22: =AI_Operating!E20 -> -15.600076 | F22: =AI_Operating!F20 -> -16.38008 | G22: =AI_Operating!G20 -> -17.199084 | H22: =AI_Operating!H20 -> -18.059038
B23: Other assets & liabilities | D23: 0 | E23: 0 | F23: 0 | G23: 0 | H23: 0
B24: Unlevered CFO | D24: =D18+D20+D21-D22+D23 -> 207.98248 | E24: =E18+E20+E21-E22+E23 -> 227.39698 | F24: =F18+F20+F21-F22+F23 -> 247.94315 | G24: =G18+G20+G21-G22+G23 -> 269.6808 | H24: =H18+H20+H21-H22+H23 -> 292.67278
B25: Less: Capital expenditures | D25: =-AI_Operating!D19 -> -23.460276 | E25: =-AI_Operating!E19 -> -24.63329 | F25: =-AI_Operating!F19 -> -25.864954 | G25: =-AI_Operating!G19 -> -27.158202 | H25: =-AI_Operating!H19 -> -28.516112 | K25: CapEx = AI_Operating (Drivers C24=2% × (1−C12=8%) = 1.84% of sales). Intangible purchases = $0 (row 26).
B26: Less: Purchases of intangible assets | D26: 0 | E26: 0 | F26: 0 | G26: 0 | H26: 0
B27: Unlevered FCF | D27: =D24+D25+D26 -> 184.52221 | E27: =E24+E25+E26 -> 202.76369 | F27: =F24+F25+F26 -> 222.07819 | G27: =G24+G25+G26 -> 242.52259 | H27: =H24+H25+H26 -> 264.15667
B28: % growth | E28: =IF(D27=0,0,E27/D27-1) -> 0.09885791 | F28: =IF(E27=0,0,F27/E27-1) -> 0.095256239 | G28: =IF(F27=0,0,G27/F27-1) -> 0.09205948 | H28: =IF(G27=0,0,H27/G27-1) -> 0.089204381
B30: Discount period (years, mid-year) | D30: 0.5 | E30: 1.5 | F30: 2.5 | G30: 3.5 | H30: 4.5
B31: Assume cash flows are generated at: | C31: Middle of period
B32: Midperiod adjustment factor | C32: =(1+$C$9)^0.5 -> 1.0454466
B33: Present value of Unlevered FCF | D33: =D27/(1+$C$9)^D30 -> 176.50084 | E33: =E27/(1+$C$9)^E30 -> 177.4535 | F33: =F27/(1+$C$9)^F30 -> 177.82653 | G33: =G27/(1+$C$9)^G30 -> 177.68023 | H33: =H27/(1+$C$9)^H30 -> 177.0699
B35: Perpetuity approach | E35: Exit EBITDA multiple approach
B36: Normalized FCFt+1 | C36: =H27*(1+C37) -> 269.43981 | E36: Terminal year EBITDA | H36: =H15 -> 318.53735
B37: Long term growth rate (g) | C37: =Assumptions_Drivers!C10 -> 0.02 | E37: Terminal value EBITDA multiple | H37: =Assumptions_Drivers!C20 -> 12.9
B38: Terminal value | C38: =IF(($C$9-C37)<=0,"NM",C36/($C$9-C37)) -> 3693.0466 | E38: Terminal value | H38: =H36*H37 -> 4109.1318
B39: Present value of terminal value | C39: =IF(ISNUMBER(C38),C38/(1+$C$9)^H30,0) -> 2475.5286 | E39: Present value of terminal value | H39: =H38/(1+$C$9)^H30 -> 2754.4394
B40: Present value of stage 1 cash flows | C40: =SUM(D33:H33) -> 886.53099 | E40: Present value of stage 1 cash flows | H40: =C40 -> 886.53099
B41: Enterprise value | C41: =C39+C40 -> 3362.0596 | E41: Enterprise value | H41: =H39+H40 -> 3640.9704 | K41: 3641.7347
B42: Implied TV exit EBITDA multiple | C42: =IF(H15=0,0,C38/H15) -> 11.593763 | E42: Implied TV perpetual growth rate | H42: =IF(H38=0,0,($C$9*H38-H27)/(H38+H27)) -> 0.026941465
B44: Net Debt | E44: Fair value per share
B45: Cash & equivalents (LBO latest) | C45: =LBO!D15 -> 179.9 | H45: LBO Offer | I45: Perpetuity | J45: EBITDA exit
B46: Gross debt (LBO latest filing) | C46: =ABS(LBO!D14) -> 1329.9 | E46: Enterprise value | H46: =H48+C47 -> 2705.6759 | I46: =C41 -> 3362.0596 | J46: =H41 -> 3640.9704
B47: Net debt | C47: =C46-C45 -> 1150 | E47: Less: Net debt | H47: =-C47 -> -1150 | I47: =-C47 -> -1150 | J47: =-C47 -> -1150
...

Sheet Shares
B2: Diluted shares for ZoomInfo (GTM)
B3: $ mm except per share / share counts in millions
B5: Offer price (LBO) | E5: =LBO!H20 -> 5.0625 | F5: 5.0625 | G5: cached (formulas in E)
B6: Latest close (LBO) | E6: =LBO!D8 -> 4.05 | F6: 4.05
B7: Diluted shares outstanding (mm) | E7: =LBO!H18 -> 307.294 | F7: 307.294
B8: In-the-money exercisable options (mm) | E8: 0
B9: Total proceeds ($mm) | E9: 0
B10: Total shares repurchased (mm) | E10: 0
B11: Net dilutive options | E11: 0
B12: Dilutive impact of other securities | E12: 0
B14: Net diluted shares outstanding (mm) | E14: =E7+E11+E12 -> 307.294 | F14: 307.294
B16: Options note
B17: LBO!H18 stores diluted shares for offer value/share. No GTM option lattice — options left at 0.

Sheet 52wkHL
A1: GTM ONLY — prices are ~$2.54–$12.51, not BMC $45s
A2: 52 week high/low — ZoomInfo Technologies (ticker GTM)
A4: 52 week high | E4: 12.51
A5: 52 week low | E5: 2.54
A6: GTM daily OHLC (Yahoo 1y). Last close 4.05 matches LBO!D8. Not BMC.
A7: Date | B7: Open | C7: High | D7: Low | E7: Close | F7: Volume
A8: 46248.562 | B8: 4.25 | C8: 4.311 | D8: 4.035 | E8: 4.05 | F8: 6927400
A9: 46247.562 | B9: 3.86 | C9: 4.365 | D9: 3.811 | E9: 4.31 | F9: 9261000
A10: 46246.562 | B10: 4.05 | C10: 4.05 | D10: 3.75 | E10: 3.86 | F10: 7183300
A11: 46245.562 | B11: 4.21 | C11: 4.3 | D11: 4.055 | E11: 4.08 | F11: 6651100
A12: 46244.562 | B12: 4.13 | C12: 4.326 | D12: 4.13 | E12: 4.23 | F12: 9212600
A13: 46241.562 | B13: 4.33 | C13: 4.33 | D13: 4.05 | E13: 4.18 | F13: 11372700
A14: 46240.562 | B14: 3.78 | C14: 4.24 | D14: 3.76 | E14: 4.14 | F14: 16764400
A15: 46239.562 | B15: 3.67 | C15: 3.8 | D15: 3.595 | E15: 3.66 | F15: 11351500
A16: 46238.562 | B16: 3.46 | C16: 3.655 | D16: 3.46 | E16: 3.62 | F16: 4514800
A17: 46237.562 | B17: 3.41 | C17: 3.64 | D17: 3.4 | E17: 3.57 | F17: 7290300
A18: 46234.562 | B18: 3.33 | C18: 3.4 | D18: 3.265 | E18: 3.3 | F18: 6511600
A19: 46233.562 | B19: 3.45 | C19: 3.45 | D19: 3.18 | E19: 3.32 | F19: 6105500
... A258: 45884.562 | B258: 10.075 | C258: 10.62 | D258: 10.075 | E258: 10.43 | F258: 4757500
