Workbook

Sheet Cover
B2: FICO Leveraged Buyout Model
B3: Educational / research — SEC-sourced inputs; open in Excel to recalculate
B5: Target | C5: Fair Isaac Corporation (FICO)
B6: CIK | C6: 0000814547
B7: Units | C7: $ millions except per share / multiples / rates
B9: Sheets
B10: 01_Assumptions — blue cells are editable inputs
B11: 02_Sources_Uses — purchase price, debt, sponsor equity
B12: 03_Operating — hist FY23–25 + 5-yr forecast
B13: 04_Debt_Schedule — interest + mandatory amort + cash sweep
B14: 05_Returns — exit equity, MoIC, IRR
B15: 06_Sensitivity — exit multiple × entry premium grid
B17: Primary SEC sources
B18: FY2025 10-K | C18: https://www.sec.gov/Archives/edgar/data/814547/000081454725000030/fico-20250930.htm
B19: Q3 FY2026 10-Q | C19: https://www.sec.gov/Archives/edgar/data/814547/000081454726000030/fico-20260630.htm
B20: Companyfacts | C20: https://data.sec.gov/api/xbrl/companyfacts/CIK0000814547.json

Sheet 01_Assumptions
B2: Assumptions (edit yellow / blue inputs)
B3: All formulas elsewhere link here — change inputs and open in Excel to recalc
B5: TRANSACTION
B6: Current share price ($) | C6: 1046.23
B7: Diluted shares (millions) | C7: 21.597635
B8: Acquisition premium | C8: 0.25
B9: Offer price / share | C9: =C6*(1+C8)
B10: Equity purchase price | C10: =C9*C7
B11: LTM EBITDA | C11: 939.802
B12: Gross debt (refinance) | C12: 5582.389
B13: Cash (latest) | C13: 304.537
B14: Minimum cash | C14: 150
B15: Excess cash to sources | C15: =MAX(0,C13-C14)
B16: Transaction fees % of offer equity | C16: 0.02
B17: Transaction fees $ | C17: =C10*C16
B18: Tax rate | C18: 0.188
B19: Hold period (years) | C19: 5
B20: Exit EV / EBITDA | C20: 18
B22: DEBT STRUCTURE (EBITDA turns)
B23: Revolver turns | C23: 0.5
B24: Term Loan A turns | C24: 2.5
B25: Term Loan B turns | C25: 2
B26: Senior Notes turns | C26: 1.5
B27: Revolver $ | C27: =C23*$C$11
B28: Term Loan A $ | C28: =C24*$C$11
B29: Term Loan B $ | C29: =C25*$C$11
B30: Senior Notes $ | C30: =C26*$C$11
B31: Total new debt | C31: =SUM(C27:C30)
B33: INTEREST / AMORT
B34: SOFR | C34: 0.043
B35: Revolver spread | C35: 0.025
B36: TLA spread | C36: 0.03
B37: TLB spread | C37: 0.035
B38: Senior Notes coupon | C38: 0.075
B39: TLA annual amort % of initial | C39: 0.05
B40: Revolver rate | C40: =C34+C35
B41: TLA rate | C41: =C34+C36
B42: TLB rate | C42: =C34+C37
B44: OPERATING FORECAST DRIVERS
B45: Metric | C45: 2026 | D45: 2027 | E45: 2028 | F45: 2029 | G45: 2030
...

Sheet 02_Sources_Uses
B2: Sources & Uses
B4: USES | E4: SOURCES
B5: Equity purchase price | C5: ='01_Assumptions'!C10 | E5: Excess cash | F5: ='01_Assumptions'!C15
B6: Refinance existing debt | C6: ='01_Assumptions'!C12 | E6: Revolver | F6: ='01_Assumptions'!C27
B7: Transaction fees | C7: ='01_Assumptions'!C17 | E7: Term Loan A | F7: ='01_Assumptions'!C28
B8: Total Uses | C8: =SUM(C5:C7) | E8: Term Loan B | F8: ='01_Assumptions'!C29
E9: Senior Notes | F9: ='01_Assumptions'!C30
E10: Sponsor equity (plug) | F10: =C8-SUM(F5:F9)
E11: Total Sources | F11: =SUM(F5:F10)
B13: Entry EV | C13: ='01_Assumptions'!C10+'01_Assumptions'!C12-'01_Assumptions'!C13
B14: Entry EV / LTM EBITDA | C14: =C13/'01_Assumptions'!C11
B15: Sources − Uses check | C15: =F11-C8
B16: Debt / EBITDA (entry) | C16: ='01_Assumptions'!C31/'01_Assumptions'!C11
B17: Equity contribution % of sources | C17: =F10/F11

Sheet 03_Operating
B2: Operating Model
B4: Fiscal year | C4: 2023 | D4: 2024 | E4: 2025 | F4: 2026 | G4: 2027 | H4: 2028 | I4: 2029 | J4: 2030
B5: Revenue | C5: ='01_Assumptions'!C53 | D5: ='01_Assumptions'!D53 | E5: ='01_Assumptions'!E53 | F5: =E5*(1+'01_Assumptions'!C46) | G5: =F5*(1+'01_Assumptions'!D46) | H5: =G5*(1+'01_Assumptions'!E46) | I5: =H5*(1+'01_Assumptions'!F46) | J5: =I5*(1+'01_Assumptions'!G46)
B6: Revenue growth | D6: =D5/C5-1 | E6: =E5/D5-1 | F6: =F5/E5-1 | G6: =G5/F5-1 | H6: =H5/G5-1 | I6: =I5/H5-1 | J6: =J5/I5-1
B7: EBITDA | C7: ='01_Assumptions'!C58 | D7: ='01_Assumptions'!D58 | E7: ='01_Assumptions'!E58 | F7: =F5*'01_Assumptions'!C47 | G7: =G5*'01_Assumptions'!D47 | H7: =H5*'01_Assumptions'!E47 | I7: =I5*'01_Assumptions'!F47 | J7: =J5*'01_Assumptions'!G47
B8: EBITDA margin | C8: =C7/C5 | D8: =D7/D5 | E8: =E7/E5 | F8: =F7/F5 | G8: =G7/G5 | H8: =H7/H5 | I8: =I7/I5 | J8: =J7/J5
B9: D&A | C9: ='01_Assumptions'!C57 | D9: ='01_Assumptions'!D57 | E9: ='01_Assumptions'!E57 | F9: =F5*0.008 | G9: =G5*0.008 | H9: =H5*0.008 | I9: =I5*0.008 | J9: =J5*0.008
B10: EBIT | C10: =C7-C9 | D10: =D7-D9 | E10: =E7-E9 | F10: =F7-F9 | G10: =G7-G9 | H10: =H7-H9 | I10: =I7-I9 | J10: =J7-J9
B11: Interest expense | C11: 95.546 | D11: 105.638 | E11: 133.647 | F11: ='04_Debt_Schedule'!F20 | G11: ='04_Debt_Schedule'!G20 | H11: ='04_Debt_Schedule'!H20 | I11: ='04_Debt_Schedule'!I20 | J11: ='04_Debt_Schedule'!J20
B12: EBT | C12: =C10-C11 | D12: =D10-D11 | E12: =E10-E11 | F12: =F10-F11 | G12: =G10-G11 | H12: =H10-H11 | I12: =I10-I11 | J12: =J10-J11
B13: Taxes | C13: =MAX(0,C12)*'01_Assumptions'!$C$18 | D13: =MAX(0,D12)*'01_Assumptions'!$C$18 | E13: =MAX(0,E12)*'01_Assumptions'!$C$18 | F13: =MAX(0,F12)*'01_Assumptions'!$C$18 | G13: =MAX(0,G12)*'01_Assumptions'!$C$18 | H13: =MAX(0,H12)*'01_Assumptions'!$C$18 | I13: =MAX(0,I12)*'01_Assumptions'!$C$18 | J13: =MAX(0,J12)*'01_Assumptions'!$C$18
B14: Net income | C14: =C12-C13 | D14: =D12-D13 | E14: =E12-E13 | F14: =F12-F13 | G14: =G12-G13 | H14: =H12-H13 | I14: =I12-I13 | J14: =J12-J13
B16: CapEx | F16: =F5*'01_Assumptions'!C48 | G16: =G5*'01_Assumptions'!D48 | H16: =H5*'01_Assumptions'!E48 | I16: =I5*'01_Assumptions'!F48 | J16: =J5*'01_Assumptions'!G48
B17: NWC | F17: =F5*'01_Assumptions'!C49 | G17: =G5*'01_Assumptions'!D49 | H17: =H5*'01_Assumptions'!E49 | I17: =I5*'01_Assumptions'!F49 | J17: =J5*'01_Assumptions'!G49
B18: ΔNWC (use of cash) | F18: =F17-E5*'01_Assumptions'!C49 | G18: =G17-F17 | H18: =H17-G17 | I18: =I17-H17 | J18: =J17-I17
B19: Free cash flow (pre-debt) | F19: =F14+F9-F16-F18 | G19: =G14+G9-G16-G18 | H19: =H14+H9-H16-H18 | I19: =I14+I9-I16-I18 | J19: =J14+J9-J16-J18
B20: Cash available for debt paydown | F20: =MAX(0,F19) | G20: =MAX(0,G19) | H20: =MAX(0,H19) | I20: =MAX(0,I19) | J20: =MAX(0,J19)

Sheet 04_Debt_Schedule
B2: Debt Schedule
B4: Item | F4: 2026 | G4: 2027 | H4: 2028 | I4: 2029 | J4: 2030
B5: Opening balances
B6: Revolver | F6: ='01_Assumptions'!C27 | G6: =F32 | H6: =G32 | I6: =H32 | J6: =I32
B7: Term Loan A | F7: ='01_Assumptions'!C28 | G7: =F33 | H7: =G33 | I7: =H33 | J7: =I33
B8: Term Loan B | F8: ='01_Assumptions'!C29 | G8: =F34 | H8: =G34 | I8: =H34 | J8: =I34
B9: Senior Notes | F9: ='01_Assumptions'!C30 | G9: =F35 | H9: =G35 | I9: =H35 | J9: =I35
B10: Total debt opening | F10: =SUM(F6:F9) | G10: =SUM(G6:G9) | H10: =SUM(H6:H9) | I10: =SUM(I6:I9) | J10: =SUM(J6:J9)
B12: Mandatory amortization
B13: TLA mandatory | F13: =MIN(F7,'01_Assumptions'!$C$28*'01_Assumptions'!$C$39) | G13: =MIN(G7,'01_Assumptions'!$C$28*'01_Assumptions'!$C$39) | H13: =MIN(H7,'01_Assumptions'!$C$28*'01_Assumptions'!$C$39) | I13: =MIN(I7,'01_Assumptions'!$C$28*'01_Assumptions'!$C$39) | J13: =MIN(J7,'01_Assumptions'!$C$28*'01_Assumptions'!$C$39)
B14: Notes / TLB mandatory | F14: 0 | G14: 0 | H14: 0 | I14: 0 | J14: 0
B15: Cash interest
B16: Interest expense | F16: =F6*'01_Assumptions'!$C$40+F7*'01_Assumptions'!$C$41+F8*'01_Assumptions'!$C$42+F9*'01_Assumptions'!$C$38 | G16: =G6*'01_Assumptions'!$C$40+G7*'01_Assumptions'!$C$41+G8*'01_Assumptions'!$C$42+G9*'01_Assumptions'!$C$38 | H16: =H6*'01_Assumptions'!$C$40+H7*'01_Assumptions'!$C$41+H8*'01_Assumptions'!$C$42+H9*'01_Assumptions'!$C$38 | I16: =I6*'01_Assumptions'!$C$40+I7*'01_Assumptions'!$C$41+I8*'01_Assumptions'!$C$42+I9*'01_Assumptions'!$C$38 | J16: =J6*'01_Assumptions'!$C$40+J7*'01_Assumptions'!$C$41+J8*'01_Assumptions'!$C$42+J9*'01_Assumptions'!$C$38
B20: Total interest (link to Op) | F20: =F16 | G20: =G16 | H20: =H16 | I20: =I16 | J20: =J16
B22: Cash flow sweep (optional paydown)
B23: Cash for paydown (from Op) | F23: ='03_Operating'!F20 | G23: ='03_Operating'!G20 | H23: ='03_Operating'!H20 | I23: ='03_Operating'!I20 | J23: ='03_Operating'!J20
B24: After mandatory | F24: =MAX(0,F23-F13-F14) | G24: =MAX(0,G23-G13-G14) | H24: =MAX(0,H23-H13-H14) | I24: =MAX(0,I23-I13-I14) | J24: =MAX(0,J23-J13-J14)
B25: Sweep to Revolver | F25: =MIN(F6,F24) | G25: =MIN(G6,G24) | H25: =MIN(H6,H24) | I25: =MIN(I6,I24) | J25: =MIN(J6,J24)
B26: Sweep to TLA | F26: =MIN(MAX(0,F7-F13),MAX(0,F24-F25)) | G26: =MIN(MAX(0,G7-G13),MAX(0,G24-G25)) | H26: =MIN(MAX(0,H7-H13),MAX(0,H24-H25)) | I26: =MIN(MAX(0,I7-I13),MAX(0,I24-I25)) | J26: =MIN(MAX(0,J7-J13),MAX(0,J24-J25))
B27: Sweep to TLB | F27: =MIN(F8,MAX(0,F24-F25-F26)) | G27: =MIN(G8,MAX(0,G24-G25-G26)) | H27: =MIN(H8,MAX(0,H24-H25-H26)) | I27: =MIN(I8,MAX(0,I24-I25-I26)) | J27: =MIN(J8,MAX(0,J24-J25-J26))
B28: Sweep to Notes | F28: =MIN(F9,MAX(0,F24-F25-F26-F27)) | G28: =MIN(G9,MAX(0,G24-G25-G26-G27)) | H28: =MIN(H9,MAX(0,H24-H25-H26-H27)) | I28: =MIN(I9,MAX(0,I24-I25-I26-I27)) | J28: =MIN(J9,MAX(0,J24-J25-J26-J27))
B30: Ending balances
B32: Revolver ending | F32: =MAX(0,F6-F25) | G32: =MAX(0,G6-G25) | H32: =MAX(0,H6-H25) | I32: =MAX(0,I6-I25) | J32: =MAX(0,J6-J25)
B33: TLA ending | F33: =MAX(0,F7-F13-F26) | G33: =MAX(0,G7-G13-G26) | H33: =MAX(0,H7-H13-H26) | I33: =MAX(0,I7-I13-I26) | J33: =MAX(0,J7-J13-J26)
B34: TLB ending | F34: =MAX(0,F8-F27) | G34: =MAX(0,G8-G27) | H34: =MAX(0,H8-H27) | I34: =MAX(0,I8-I27) | J34: =MAX(0,J8-J27)
B35: Notes ending | F35: =MAX(0,F9-F28) | G35: =MAX(0,G9-G28) | H35: =MAX(0,H9-H28) | I35: =MAX(0,I9-I28) | J35: =MAX(0,J9-J28)
B36: Total debt ending | F36: =SUM(F32:F35) | G36: =SUM(G32:G35) | H36: =SUM(H32:H35) | I36: =SUM(I32:I35) | J36: =SUM(J32:J35)

Sheet 05_Returns
B2: Returns Analysis
B4: Exit year EBITDA (Y5) | C4: ='03_Operating'!J7
B5: Exit EV / EBITDA | C5: ='01_Assumptions'!C20
B6: Exit enterprise value | C6: =C4*C5
B7: Exit net debt (debt ending − min cash) | C7: ='04_Debt_Schedule'!J36-'01_Assumptions'!C14
B8: Exit equity value | C8: =C6-C7
B10: Sponsor equity at entry (check) | C10: ='02_Sources_Uses'!F10
B11: MoIC | C11: =IF(C10>0,C8/C10,0)
B12: IRR (annual) | C12: =IF(C10>0,(C8/C10)^(1/'01_Assumptions'!C19)-1,0)
B14: Cash flow to sponsor
B15: Year 0 (entry) | C15: =-C10
B16: Year 5 (exit) | C16: =C8
B17: Excel IRR (same as above if no interim CF) | C17: =C12
B19: How to use
B20: 1. Edit yellow cells on 01_Assumptions (premium, leverage turns, exit multiple, growth).
B21: 2. Open this file in Excel / Google Sheets so formulas calculate.
B22: 3. Read MoIC and IRR on this sheet; stress on 06_Sensitivity.

Sheet 06_Sensitivity
B2: Sensitivity — Exit MoIC
B3: Rows = exit EV/EBITDA; Cols = acquisition premium
B5: MoIC | C5: 0.1 | D5: 0.15 | E5: 0.2 | F5: 0.25 | G5: 0.3 | H5: 0.4
B6: Exit \ Prem | C6: =$C$13*(14/$C$15)*((1+$C$14)/(1+0.1)) | D6: =$C$13*(14/$C$15)*((1+$C$14)/(1+0.15)) | E6: =$C$13*(14/$C$15)*((1+$C$14)/(1+0.2)) | F6: =$C$13*(14/$C$15)*((1+$C$14)/(1+0.25)) | G6: =$C$13*(14/$C$15)*((1+$C$14)/(1+0.3)) | H6: =$C$13*(14/$C$15)*((1+$C$14)/(1+0.4))
B7: 16 | C7: =$C$13*(16/$C$15)*((1+$C$14)/(1+0.1)) | D7: =$C$13*(16/$C$15)*((1+$C$14)/(1+0.15)) | E7: =$C$13*(16/$C$15)*((1+$C$14)/(1+0.2)) | F7: =$C$13*(16/$C$15)*((1+$C$14)/(1+0.25)) | G7: =$C$13*(16/$C$15)*((1+$C$14)/(1+0.3)) | H7: =$C$13*(16/$C$15)*((1+$C$14)/(1+0.4))
B8: 18 | C8: =$C$13*(18/$C$15)*((1+$C$14)/(1+0.1)) | D8: =$C$13*(18/$C$15)*((1+$C$14)/(1+0.15)) | E8: =$C$13*(18/$C$15)*((1+$C$14)/(1+0.2)) | F8: =$C$13*(18/$C$15)*((1+$C$14)/(1+0.25)) | G8: =$C$13*(18/$C$15)*((1+$C$14)/(1+0.3)) | H8: =$C$13*(18/$C$15)*((1+$C$14)/(1+0.4))
B9: 20 | C9: =$C$13*(20/$C$15)*((1+$C$14)/(1+0.1)) | D9: =$C$13*(20/$C$15)*((1+$C$14)/(1+0.15)) | E9: =$C$13*(20/$C$15)*((1+$C$14)/(1+0.2)) | F9: =$C$13*(20/$C$15)*((1+$C$14)/(1+0.25)) | G9: =$C$13*(20/$C$15)*((1+$C$14)/(1+0.3)) | H9: =$C$13*(20/$C$15)*((1+$C$14)/(1+0.4))
B10: 22 | C10: =$C$13*(22/$C$15)*((1+$C$14)/(1+0.1)) | D10: =$C$13*(22/$C$15)*((1+$C$14)/(1+0.15)) | E10: =$C$13*(22/$C$15)*((1+$C$14)/(1+0.2)) | F10: =$C$13*(22/$C$15)*((1+$C$14)/(1+0.25)) | G10: =$C$13*(22/$C$15)*((1+$C$14)/(1+0.3)) | H10: =$C$13*(22/$C$15)*((1+$C$14)/(1+0.4))
B11: 25 | C11: =$C$13*(25/$C$15)*((1+$C$14)/(1+0.1)) | D11: =$C$13*(25/$C$15)*((1+$C$14)/(1+0.15)) | E11: =$C$13*(25/$C$15)*((1+$C$14)/(1+0.2)) | F11: =$C$13*(25/$C$15)*((1+$C$14)/(1+0.25)) | G11: =$C$13*(25/$C$15)*((1+$C$14)/(1+0.3)) | H11: =$C$13*(25/$C$15)*((1+$C$14)/(1+0.4))
B13: Base case MoIC (from Returns) | C13: ='05_Returns'!C11
B14: Base premium | C14: ='01_Assumptions'!C8
B15: Base exit multiple | C15: ='01_Assumptions'!C20
B17: IRR grid (same axes)
B18: IRR | C18: 0.1 | D18: 0.15 | E18: 0.2 | F18: 0.25 | G18: 0.3 | H18: 0.4
B19: 14 | C19: =(C6)^(1/'01_Assumptions'!$C$19)-1 | D19: =(D6)^(1/'01_Assumptions'!$C$19)-1 | E19: =(E6)^(1/'01_Assumptions'!$C$19)-1 | F19: =(F6)^(1/'01_Assumptions'!$C$19)-1 | G19: =(G6)^(1/'01_Assumptions'!$C$19)-1 | H19: =(H6)^(1/'01_Assumptions'!$C$19)-1
B20: 16 | C20: =(C7)^(1/'01_Assumptions'!$C$19)-1 | D20: =(D7)^(1/'01_Assumptions'!$C$19)-1 | E20: =(E7)^(1/'01_Assumptions'!$C$19)-1 | F20: =(F7)^(1/'01_Assumptions'!$C$19)-1 | G20: =(G7)^(1/'01_Assumptions'!$C$19)-1 | H20: =(H7)^(1/'01_Assumptions'!$C$19)-1
B21: 18 | C21: =(C8)^(1/'01_Assumptions'!$C$19)-1 | D21: =(D8)^(1/'01_Assumptions'!$C$19)-1 | E21: =(E8)^(1/'01_Assumptions'!$C$19)-1 | F21: =(F8)^(1/'01_Assumptions'!$C$19)-1 | G21: =(G8)^(1/'01_Assumptions'!$C$19)-1 | H21: =(H8)^(1/'01_Assumptions'!$C$19)-1
B22: 20 | C22: =(C9)^(1/'01_Assumptions'!$C$19)-1 | D22: =(D9)^(1/'01_Assumptions'!$C$19)-1 | E22: =(E9)^(1/'01_Assumptions'!$C$19)-1 | F22: =(F9)^(1/'01_Assumptions'!$C$19)-1 | G22: =(G9)^(1/'01_Assumptions'!$C$19)-1 | H22: =(H9)^(1/'01_Assumptions'!$C$19)-1
B23: 22 | C23: =(C10)^(1/'01_Assumptions'!$C$19)-1 | D23: =(D10)^(1/'01_Assumptions'!$C$19)-1 | E23: =(E10)^(1/'01_Assumptions'!$C$19)-1 | F23: =(F10)^(1/'01_Assumptions'!$C$19)-1 | G23: =(G10)^(1/'01_Assumptions'!$C$19)-1 | H23: =(H10)^(1/'01_Assumptions'!$C$19)-1
B24: 25 | C24: =(C11)^(1/'01_Assumptions'!$C$19)-1 | D24: =(D11)^(1/'01_Assumptions'!$C$19)-1 | E24: =(E11)^(1/'01_Assumptions'!$C$19)-1 | F24: =(F11)^(1/'01_Assumptions'!$C$19)-1 | G24: =(G11)^(1/'01_Assumptions'!$C$19)-1 | H24: =(H11)^(1/'01_Assumptions'!$C$19)-1
