Workbook

Sheet 00_ReadMe
A1: FICO (Fair Isaac Corporation) — Investor DCF / Valuation Workbook
A3: What this file is
A4: A full investor-style valuation pack for FICO built from SEC EDGAR 10-K / 10-Q fundamentals, with a working 5-year FCFF DCF, WACC, and sensitivity tables.
A6: Color key
A7: Yellow cells + blue font = INPUTS you should edit
A8: Black font = formulas (do not overwrite)
A10: How to use (guided path)
A11: 1) Read 01_Template_Links for downloadable external DCF / LBO / comps templates (Damodaran, CFI, Macabacus, etc.).
A12: 2) Review 02_EDGAR_Sources for filing links and CIK.
A13: 3) Confirm historical line items on 03_IS / 04_BS / 05_CF (pre-filled from FY2025 10-K; override in yellow if needed).
A14: 4) Set forecast drivers on 06_Assumptions (growth, margins, tax, reinvestment, WACC components).
A15: 5) Read implied value on 07_DCF and 10_Output; stress with 09_Sensitivity.
... A27: Educational / research model only. Not investment advice. Verify figures against primary SEC filings before relying on outputs.

Sheet 01_Template_Links
A1: Downloadable valuation / DCF templates (external)
A3: Source | B3: Template | C3: Direct / landing URL | D3: Notes
A4: Aswath Damodaran (NYU) | B4: All valuation spreadsheets hub | C4: https://pages.stern.nyu.edu/~adamodar/New_Home_Page/spreadsh.htm | D4: Best free academic suite; FCFF/FCFE/DDM/ginzu models
A5: Aswath Damodaran | B5: fcffsimpleginzu.xlsx (recommended FCFF) | C5: https://pages.stern.nyu.edu/~adamodar/pc/fcffsimpleginzu.xlsx | D5: Direct XLSX download — all-in-one firm DCF
A6: Aswath Damodaran | B6: fcffginzu.xls (full kitchen-sink FCFF) | C6: https://pages.stern.nyu.edu/~adamodar/pc/fcffginzu.xls | D6: Ratings, R&D capitalize, leases, bottom-up beta
A7: Aswath Damodaran | B7: Equity valuation spreadsheets page | C7: https://pages.stern.nyu.edu/~adamodar/New_Home_Page/eqspread.htm | D7: Stable/2-stage/3-stage FCFF & FCFE models
A8: Aswath Damodaran | B8: fcff2st.xls (two-stage FCFF) | C8: https://pages.stern.nyu.edu/~adamodar/pc/fcff2st.xls | D8: Direct download
A9: Aswath Damodaran | B9: fcff3st.xls (three-stage FCFF) | C9: https://pages.stern.nyu.edu/~adamodar/pc/fcff3st.xls | D9: Direct download
A10: Aswath Damodaran | B10: firmmult.xls (implied multiples from DCF) | C10: https://pages.stern.nyu.edu/~adamodar/pc/firmmult.xls | D10: Direct download
A11: Corporate Finance Institute (CFI) | B11: Free DCF Model Template | C11: https://corporatefinanceinstitute.com/resources/financial-modeling/dcf-model-template/ | D11: 3-statement linked + 5yr FCFF; email gate possible
A12: CFI (direct asset) | B12: DCF-Valuation-Compact-Complete.xlsx | C12: https://corporatefinanceinstitute.com/assets/DCF-Valuation-Compact-Complete.xlsx | D12: Direct XLSX linked from CFI DCF training
A13: CT Acquisitions | B13: 2026 Free DCF Excel Model | C13: https://ctacquisitions.com/dcf-template-and-excel/ | D13: 6-tab PE/IB style DCF walkthrough
A14: Limelight | B14: Free DCF Calculator Template | C14: https://www.golimelight.com/templates/dcf-calculator-template | D14: WACC + dual TV + scenario/sensitivity
... A24: SEC data API | B24: FICO companyfacts XBRL JSON | C24: https://data.sec.gov/api/xbrl/companyfacts/CIK0000814547.json | D24: Machine-readable fundamentals used in this repo

Sheet 02_EDGAR_Sources
A1: EDGAR source map — Fair Isaac Corp (FICO)
A3: Field | B3: Value
A4: CIK | B4: 0000814547
A5: Ticker | B5: FICO
A6: Fiscal year end | B6: September 30
A7: Latest 10-K | B7: FY2025 ended 2025-09-30, filed 2025-11-07
A8: 10-K HTML | B8: https://www.sec.gov/Archives/edgar/data/814547/000081454725000030/fico-20250930.htm
A9: 10-K index | B9: https://www.sec.gov/Archives/edgar/data/814547/000081454725000030/0000814547-25-000030-index.html
A10: Investor PDF copy | B10: https://investors.fico.com/static-files/663245db-39a2-4db7-8f89-284034bbccbf
A11: Latest 10-Q used | B11: Q3 FY2026 ended 2026-06-30, filed 2026-07-29
A12: 10-Q HTML | B12: https://www.sec.gov/Archives/edgar/data/814547/000081454726000030/fico-20260630.htm
A13: Companyfacts API | B13: https://data.sec.gov/api/xbrl/companyfacts/CIK0000814547.json
A14: Submissions API | B14: https://data.sec.gov/submissions/CIK0000814547.json

Sheet 03_IS_Historical
A1: Consolidated Statements of Income — FICO ($ thousands)
A2: Source: FY2025 Form 10-K. Yellow/blue = editable inputs. Values in thousands USD except EPS and share counts.
A4: Line item | B4: 2025 | C4: 2024 | D4: 2023
A5: On-premises and SaaS software | B5: 740145 | C5: 711340 | D5: 640182
A6: Professional services | B6: 82149 | C6: 86536 | D6: 99547
A7: Scores | B7: 1168575 | C7: 919650 | D7: 773828
A8: Total revenues | B8: 1990869 | C8: 1717526 | D8: 1513557
A9: Cost of revenues | B9: 353722 | C9: 348206 | D9: 311053
A10: Research and development | B10: 188347 | C10: 171940 | D10: 159950
A11: Selling, general and administrative | B11: 513028 | C11: 462834 | D11: 400565
A12: Amortization of intangible assets | B12: 0 | C12: 917 | D12: 1100
A13: Restructuring charges | B13: 10922 | C13: 0 | D13: 0
A14: Gain on product line asset sale | B14: 0 | C14: 0 | D14: -1941
A15: Total operating expenses | B15: 1066019 | C15: 983897 | D15: 870727
A16: Operating income | B16: 924850 | C16: 733629 | D16: 642830
... A25: Shares diluted (000s) | B25: 24561 | C25: 25079 | D25: 25367

Sheet 04_BS_Historical
A1: Consolidated Balance Sheets — FICO ($ thousands)
A2: FY columns from FY2025 10-K; 2026Q3 from 10-Q ended 2026-06-30 (latest public BS for net debt bridge).
A4: Line item | B4: 2026Q3 | C4: 2025 | D4: 2024
A5: Cash and cash equivalents | B5: 248444 | C5: 134136 | D5: 150667
A6: Accounts receivable, net | B6: 592530 | C6: 529148 | D6: 426642
A7: Prepaid expenses and other current assets | B7: 40589 | C7: 41881 | D7: 40104
A8: Total current assets | B8: 881563 | C8: 705165 | D8: 617413
A9: Marketable securities | B9: 56093 | C9: 54625 | D9: 45289
A10: Property and equipment, net | C10: 67713 | D10: 38465
A11: Operating lease right-of-use assets | C11: 26213 | D11: 29580
A12: Goodwill | C12: 783340 | D12: 782752
A13: Deferred income taxes | C13: 118553 | D13: 86513
A14: Other assets | C14: 112524 | D14: 117872
A15: Total assets | B15: 2037373 | C15: 1868133 | D15: 1717884
A16: Accounts payable | B16: 26878 | C16: 32315 | D16: 22473
A17: Accrued compensation and employee benefits | C17: 115369 | D17: 106103
A18: Other accrued liabilities | C18: 114618 | D18: 79812
A19: Deferred revenue | B19: 205424 | C19: 187372 | D19: 156897
A20: Current maturities on debt | B20: 300000 | C20: 399541 | D20: 15000
A21: Total current liabilities | B21: 745191 | C21: 849215 | D21: 380285
A22: Long-term debt | B22: 5282389 | C22: 2656150 | D22: 2194021
A23: Operating lease liabilities (noncurrent) | B23: 15621 | C23: 19187 | D23: 21963
A24: Other liabilities | B24: 91307 | C24: 89365 | D24: 84294
A25: Total liabilities | B25: 6134508 | C25: 3613917 | D25: 2680563
A26: Common stock (par) | C26: 238 | D26: 244
A27: Additional paid-in-capital | C27: 1331120 | D27: 1366572
A28: Treasury stock | C28: -7537908 | D28: -6138736
A29: Retained earnings | C29: 4552816 | D29: 3900870
A30: AOCI | C30: -92050 | D30: -91629
A31: Total stockholders deficit | C31: -1745784 | D31: -962679
A32: Shares outstanding (000s) | C32: 23764 | D32: 24392
A33: Total debt (current + LT) | B33: 5582389 | C33: 3055691 | D33: 2209021

Sheet 05_CF_Historical
A1: Consolidated Statements of Cash Flows — FICO ($ thousands)
A2: Source: FY2025 Form 10-K. Capex for DCF = Purchases of PP&E + Capitalized internal-use software.
A4: Line item | B4: 2025 | C4: 2024 | D4: 2023
A5: Net income | B5: 651946 | C5: 512811 | D5: 429375
A6: Depreciation and amortization | B6: 14952 | C6: 13827 | D6: 14638
A7: Share-based compensation | B7: 156667 | C7: 149439 | D7: 123847
A8: Deferred income taxes | B8: -32486 | C8: -27330 | D8: -47378
A9: Net gain on marketable securities | B9: -5024 | C9: -9834 | D9: -2908
A10: Non-cash operating lease costs | B10: 9604 | C10: 12423 | D10: 14708
A11: Provision of doubtful accounts | B11: 1485 | C11: 1675 | D11: 1475
A12: Gain on product line asset sale | B12: 0 | C12: 0 | D12: -1941
A13: Net loss on sales/abandonment of PP&E | B13: 210 | C13: 438 | D13: 547
A14: Change in accounts receivable | B14: -100377 | C14: -34144 | D14: -70117
A15: Change in prepaid expenses and other assets | B15: 610 | C15: -14034 | D15: -11904
A16: Change in accounts payable | B16: 9849 | C16: 3316 | D16: 2236
... A41: Cash paid for interest | B41: 103564 | C41: 106388 | D41: 96877

Sheet 06_Assumptions
A1: Forecast & valuation assumptions (edit yellow/blue cells)
A2: All $ figures on this tab and DCF are in $ millions unless noted.
A4: A. Market & capital structure
A6: Share price ($) | B6: 1046.23
A7: Diluted shares outstanding (millions) | B7: 21.597635
A8: Cash & equivalents ($m) | B8: 248.444
A9: Marketable securities ($m) | B9: 56.093
A10: Total debt ($m) | B10: 5582.389
A11: Minority interest ($m) | B11: 0
A12: Preferred equity ($m) | B12: 0
A14: B. WACC components
A16: Risk-free rate | B16: 0.043
A17: Equity risk premium | B17: 0.05
A18: Beta | B18: 1.321
A19: Size / specific risk premium | B19: 0
A20: Pre-tax cost of debt | B20: 0.055
A21: Marginal tax rate | B21: 0.188
A22: Target equity weight | B22: 0.8
A23: Target debt weight | B23: 0.2
A25: Cost of equity (CAPM) | B25: =B16+B18*B17+B19
A26: After-tax cost of debt | B26: =B20*(1-B21)
A27: WACC | B27: =B22*B25+B23*B26
A29: C. Operating forecast drivers
A30: Base year revenue FY2025 ($m) | B30: 1990.869
A31: Base year EBIT FY2025 ($m) | B31: 924.85
A32: Base year D&A FY2025 ($m) | B32: 14.952
A33: Base year SBC FY2025 ($m) — optional add-back toggle below | B33: 156.667
A35: Driver | B35: FY2026 | C35: FY2027 | D35: FY2028 | E35: FY2029 | F35: FY2030
A36: Revenue growth | B36: 0.14 | C36: 0.12 | D36: 0.1 | E36: 0.09 | F36: 0.08
A37: EBIT margin | B37: 0.455 | C37: 0.45 | D37: 0.445 | E37: 0.44 | F37: 0.44
A38: Tax rate on EBIT | B38: 0.188 | C38: 0.188 | D38: 0.188 | E38: 0.188 | F38: 0.188
A39: D&A % of revenue | B39: 0.008 | C39: 0.008 | D39: 0.008 | E39: 0.008 | F39: 0.008
A40: Capex + capitalized software % of revenue | B40: 0.02 | C40: 0.02 | D40: 0.02 | E40: 0.02 | F40: 0.02
A41: ΔNWC % of ΔRevenue (use of cash if +) | B41: 0.05 | C41: 0.05 | D41: 0.05 | E41: 0.05 | F41: 0.05
A42: Add back SBC in FCFF? (1=yes, 0=no) | B42: 0 | C42: Conservative default = 0 (treat SBC as real economic cost)
A44: D. Terminal value
A45: Perpetuity growth rate g | B45: 0.03
A46: Exit EV/EBIT multiple | B46: 22
A47: TV method weight on perpetuity (1=100% g, 0=100% exit multiple) | B47: 0.5
A48: Mid-year discounting? (1=yes) | B48: 1
...

Sheet 07_DCF
A1: FCFF DCF valuation — FICO
A2: $ millions. Explicit forecast FY2026–FY2030. Edit drivers on 06_Assumptions.
A4: ($ millions) | B4: FY2025A | C4: FY2026E | D4: FY2027E | E4: FY2028E | F4: FY2029E | G4: FY2030E
A5: Revenue | B5: ='06_Assumptions'!B30 | C5: =B5*(1+C6) | D5: =C5*(1+D6) | E5: =D5*(1+E6) | F5: =E5*(1+F6) | G5: =F5*(1+G6)
A6: Revenue growth | B6: — | C6: ='06_Assumptions'!B36 | D6: ='06_Assumptions'!C36 | E6: ='06_Assumptions'!D36 | F6: ='06_Assumptions'!E36 | G6: ='06_Assumptions'!F36
A7: EBIT | B7: ='06_Assumptions'!B31 | C7: =C5*C8 | D7: =D5*D8 | E7: =E5*E8 | F7: =F5*F8 | G7: =G5*G8
A8: EBIT margin | B8: =B7/B5 | C8: ='06_Assumptions'!B37 | D8: ='06_Assumptions'!C37 | E8: ='06_Assumptions'!D37 | F8: ='06_Assumptions'!E37 | G8: ='06_Assumptions'!F37
A9: Cash tax on EBIT | B9: =B7*'06_Assumptions'!B21 | C9: =C7*'06_Assumptions'!B38 | D9: =D7*'06_Assumptions'!C38 | E9: =E7*'06_Assumptions'!D38 | F9: =F7*'06_Assumptions'!E38 | G9: =G7*'06_Assumptions'!F38
A10: NOPAT | B10: =B7-B9 | C10: =C7-C9 | D10: =D7-D9 | E10: =E7-E9 | F10: =F7-F9 | G10: =G7-G9
A11: (+) D&A | B11: ='06_Assumptions'!B32 | C11: =C5*'06_Assumptions'!B39 | D11: =D5*'06_Assumptions'!C39 | E11: =E5*'06_Assumptions'!D39 | F11: =F5*'06_Assumptions'!E39 | G11: =G5*'06_Assumptions'!F39
A12: (+) SBC add-back (optional) | B12: ='06_Assumptions'!B33*'06_Assumptions'!B42 | C12: ='06_Assumptions'!B33*'06_Assumptions'!B42*(C5/'06_Assumptions'!B30) | D12: ='06_Assumptions'!B33*'06_Assumptions'!B42*(D5/'06_Assumptions'!B30) | E12: ='06_Assumptions'!B33*'06_Assumptions'!B42*(E5/'06_Assumptions'!B30) | F12: ='06_Assumptions'!B33*'06_Assumptions'!B42*(F5/'06_Assumptions'!B30) | G12: ='06_Assumptions'!B33*'06_Assumptions'!B42*(G5/'06_Assumptions'!B30)
A13: Gross cash flow | B13: =B10+B11+B12 | C13: =C10+C11+C12 | D13: =D10+D11+D12 | E13: =E10+E11+E12 | F13: =F10+F11+F12 | G13: =G10+G11+G12
A14: (−) Capex + capitalized software | B14: 39.407 | C14: =C5*'06_Assumptions'!B40 | D14: =D5*'06_Assumptions'!C40 | E14: =E5*'06_Assumptions'!D40 | F14: =F5*'06_Assumptions'!E40 | G14: =G5*'06_Assumptions'!F40
A15: (−) Δ Net working capital | B15: 0 | C15: =MAX(0,C5-B5)*'06_Assumptions'!B41 | D15: =MAX(0,D5-C5)*'06_Assumptions'!C41 | E15: =MAX(0,E5-D5)*'06_Assumptions'!D41 | F15: =MAX(0,F5-E5)*'06_Assumptions'!E41 | G15: =MAX(0,G5-F5)*'06_Assumptions'!F41
A16: Unlevered FCFF | B16: =B13-B14-B15 | C16: =C13-C14-C15 | D16: =D13-D14-D15 | E16: =E13-E14-E15 | F16: =F13-F14-F15 | G16: =G13-G14-G15
A17: Discount period (years) | B17: — | C17: =1-'06_Assumptions'!B48*0.5 | D17: =C17+1 | E17: =D17+1 | F17: =E17+1 | G17: =F17+1
A18: Discount factor | B18: — | C18: =1/(1+'06_Assumptions'!B27)^C17 | D18: =1/(1+'06_Assumptions'!B27)^D17 | E18: =1/(1+'06_Assumptions'!B27)^E17 | F18: =1/(1+'06_Assumptions'!B27)^F17 | G18: =1/(1+'06_Assumptions'!B27)^G17
A19: PV of FCFF | B19: — | C19: =C16*C18 | D19: =D16*D18 | E19: =E16*E18 | F19: =F16*F18 | G19: =G16*G18
A21: Terminal value
A22: TV — Gordon growth (perpetuity) | G22: =G16*(1+'06_Assumptions'!B45)/('06_Assumptions'!B27-'06_Assumptions'!B45)
A23: TV — Exit multiple on EBIT | G23: =G7*'06_Assumptions'!B46
A24: Blended TV | G24: =G22*'06_Assumptions'!B47+G23*(1-'06_Assumptions'!B47)
A25: PV of terminal value | G25: =G24*G18
A27: Enterprise value bridge
A28: PV of explicit FCFF | B28: =SUM(C19:G19)
A29: PV of terminal value | B29: =G25
A30: Enterprise value | B30: =B28+B29
A31: (−) Total debt | B31: ='06_Assumptions'!B10
A32: (+) Cash | B32: ='06_Assumptions'!B8
A33: (+) Marketable securities | B33: ='06_Assumptions'!B9
A34: (−) Minorities | B34: ='06_Assumptions'!B11
A35: (−) Preferred | B35: ='06_Assumptions'!B12
A36: Equity value | B36: =B30-B31+B32+B33-B34-B35
A37: Diluted shares (m) | B37: ='06_Assumptions'!B7
A38: Intrinsic value / share | B38: =B36/B37
A39: Current price | B39: ='06_Assumptions'!B6
A40: Upside / (downside) | B40: =B38/B39-1
A42: Implied metrics
A43: TV as % of EV | B43: =B29/B30
A44: Implied FY25A EV/EBIT | B44: =B30/'06_Assumptions'!B31
...

Sheet 08_WACC
A1: WACC build
A3: Linked from 06_Assumptions
A5: Component | B5: Value
A6: Risk-free rate | B6: ='06_Assumptions'!B16
A7: ERP | B7: ='06_Assumptions'!B17
A8: Beta | B8: ='06_Assumptions'!B18
A9: Cost of equity | B9: ='06_Assumptions'!B25
A10: Pre-tax cost of debt | B10: ='06_Assumptions'!B20
A11: Tax rate | B11: ='06_Assumptions'!B21
A12: After-tax cost of debt | B12: ='06_Assumptions'!B26
A13: Equity weight | B13: ='06_Assumptions'!B22
A14: Debt weight | B14: ='06_Assumptions'!B23
A15: WACC | B15: ='06_Assumptions'!B27
A18: Notes
A19: Beta sourced from Yahoo Finance at model build (~1.32). Cost of debt ~blended coupon / interest (~5.5% placeholder — replace with YTM if available).
A20: Target weights are judgmental (FICO runs with structural net leverage due to buybacks). Current market gearing is higher after 2026 debt raise — adjust B22/B23 accordingly.

Sheet 09_Sensitivity
A1: Sensitivity: intrinsic value / share vs WACC and terminal growth
A2: Grid uses Gordon TV only for isolation. Base case blended value remains on 07_DCF.
A4: Value/share | B4: 0.025 | C4: 0.03 | D4: 0.035 | E4: 0.04
A5: 0.08 | B5: ((('07_DCF'!C16)/(1+$A5)^'07_DCF'!C17)+ (('07_DCF'!D16)/(1+$A5)^'07_DCF'!D17)+ (('07_DCF'!E16)/(1+$A5)^'07_DCF'!E17)+ (('07_DCF'!F16)/(1+$A5)^'07_DCF'!F17)+ (('07_DCF'!G16)/(1+$A5)^'07_DCF'!G17)+ ((('07_DCF'!G16)*(1+B$4)/($A5-B$4))/(1+$A5)^'07_DCF'!G17)-'06_Assumptions'!B10+'06_Assumptions'!B8+'06_Assumptions'!B9)/'06_Assumptions'!B7 | C5: ((('07_DCF'!C16)/(1+$A5)^'07_DCF'!C17)+ (('07_DCF'!D16)/(1+$A5)^'07_DCF'!D17)+ (('07_DCF'!E16)/(1+$A5)^'07_DCF'!E17)+ (('07_DCF'!F16)/(1+$A5)^'07_DCF'!F17)+ (('07_DCF'!G16)/(1+$A5)^'07_DCF'!G17)+ ((('07_DCF'!G16)*(1+C$4)/($A5-C$4))/(1+$A5)^'07_DCF'!G17)-'06_Assumptions'!B10+'06_Assumptions'!B8+'06_Assumptions'!B9)/'06_Assumptions'!B7 | D5: ((('07_DCF'!C16)/(1+$A5)^'07_DCF'!C17)+ (('07_DCF'!D16)/(1+$A5)^'07_DCF'!D17)+ (('07_DCF'!E16)/(1+$A5)^'07_DCF'!E17)+ (('07_DCF'!F16)/(1+$A5)^'07_DCF'!F17)+ (('07_DCF'!G16)/(1+$A5)^'07_DCF'!G17)+ ((('07_DCF'!G16)*(1+D$4)/($A5-D$4))/(1+$A5)^'07_DCF'!G17)-'06_Assumptions'!B10+'06_Assumptions'!B8+'06_Assumptions'!B9)/'06_Assumptions'!B7 | E5: ((('07_DCF'!C16)/(1+$A5)^'07_DCF'!C17)+ (('07_DCF'!D16)/(1+$A5)^'07_DCF'!D17)+ (('07_DCF'!E16)/(1+$A5)^'07_DCF'!E17)+ (('07_DCF'!F16)/(1+$A5)^'07_DCF'!F17)+ (('07_DCF'!G16)/(1+$A5)^'07_DCF'!G17)+ ((('07_DCF'!G16)*(1+E$4)/($A5-E$4))/(1+$A5)^'07_DCF'!G17)-'06_Assumptions'!B10+'06_Assumptions'!B8+'06_Assumptions'!B9)/'06_Assumptions'!B7
A6: 0.09 | B6: ((('07_DCF'!C16)/(1+$A6)^'07_DCF'!C17)+ (('07_DCF'!D16)/(1+$A6)^'07_DCF'!D17)+ (('07_DCF'!E16)/(1+$A6)^'07_DCF'!E17)+ (('07_DCF'!F16)/(1+$A6)^'07_DCF'!F17)+ (('07_DCF'!G16)/(1+$A6)^'07_DCF'!G17)+ ((('07_DCF'!G16)*(1+B$4)/($A6-B$4))/(1+$A6)^'07_DCF'!G17)-'06_Assumptions'!B10+'06_Assumptions'!B8+'06_Assumptions'!B9)/'06_Assumptions'!B7 | C6: ((('07_DCF'!C16)/(1+$A6)^'07_DCF'!C17)+ (('07_DCF'!D16)/(1+$A6)^'07_DCF'!D17)+ (('07_DCF'!E16)/(1+$A6)^'07_DCF'!E17)+ (('07_DCF'!F16)/(1+$A6)^'07_DCF'!F17)+ (('07_DCF'!G16)/(1+$A6)^'07_DCF'!G17)+ ((('07_DCF'!G16)*(1+C$4)/($A6-C$4))/(1+$A6)^'07_DCF'!G17)-'06_Assumptions'!B10+'06_Assumptions'!B8+'06_Assumptions'!B9)/'06_Assumptions'!B7 | D6: ((('07_DCF'!C16)/(1+$A6)^'07_DCF'!C17)+ (('07_DCF'!D16)/(1+$A6)^'07_DCF'!D17)+ (('07_DCF'!E16)/(1+$A6)^'07_DCF'!E17)+ (('07_DCF'!F16)/(1+$A6)^'07_DCF'!F17)+ (('07_DCF'!G16)/(1+$A6)^'07_DCF'!G17)+ ((('07_DCF'!G16)*(1+D$4)/($A6-D$4))/(1+$A6)^'07_DCF'!G17)-'06_Assumptions'!B10+'06_Assumptions'!B8+'06_Assumptions'!B9)/'06_Assumptions'!B7 | E6: ((('07_DCF'!C16)/(1+$A6)^'07_DCF'!C17)+ (('07_DCF'!D16)/(1+$A6)^'07_DCF'!D17)+ (('07_DCF'!E16)/(1+$A6)^'07_DCF'!E17)+ (('07_DCF'!F16)/(1+$A6)^'07_DCF'!F17)+ (('07_DCF'!G16)/(1+$A6)^'07_DCF'!G17)+ ((('07_DCF'!G16)*(1+E$4)/($A6-E$4))/(1+$A6)^'07_DCF'!G17)-'06_Assumptions'!B10+'06_Assumptions'!B8+'06_Assumptions'!B9)/'06_Assumptions'!B7
A7: 0.1 | B7: ((('07_DCF'!C16)/(1+$A7)^'07_DCF'!C17)+ (('07_DCF'!D16)/(1+$A7)^'07_DCF'!D17)+ (('07_DCF'!E16)/(1+$A7)^'07_DCF'!E17)+ (('07_DCF'!F16)/(1+$A7)^'07_DCF'!F17)+ (('07_DCF'!G16)/(1+$A7)^'07_DCF'!G17)+ ((('07_DCF'!G16)*(1+B$4)/($A7-B$4))/(1+$A7)^'07_DCF'!G17)-'06_Assumptions'!B10+'06_Assumptions'!B8+'06_Assumptions'!B9)/'06_Assumptions'!B7 | C7: ((('07_DCF'!C16)/(1+$A7)^'07_DCF'!C17)+ (('07_DCF'!D16)/(1+$A7)^'07_DCF'!D17)+ (('07_DCF'!E16)/(1+$A7)^'07_DCF'!E17)+ (('07_DCF'!F16)/(1+$A7)^'07_DCF'!F17)+ (('07_DCF'!G16)/(1+$A7)^'07_DCF'!G17)+ ((('07_DCF'!G16)*(1+C$4)/($A7-C$4))/(1+$A7)^'07_DCF'!G17)-'06_Assumptions'!B10+'06_Assumptions'!B8+'06_Assumptions'!B9)/'06_Assumptions'!B7 | D7: ((('07_DCF'!C16)/(1+$A7)^'07_DCF'!C17)+ (('07_DCF'!D16)/(1+$A7)^'07_DCF'!D17)+ (('07_DCF'!E16)/(1+$A7)^'07_DCF'!E17)+ (('07_DCF'!F16)/(1+$A7)^'07_DCF'!F17)+ (('07_DCF'!G16)/(1+$A7)^'07_DCF'!G17)+ ((('07_DCF'!G16)*(1+D$4)/($A7-D$4))/(1+$A7)^'07_DCF'!G17)-'06_Assumptions'!B10+'06_Assumptions'!B8+'06_Assumptions'!B9)/'06_Assumptions'!B7 | E7: ((('07_DCF'!C16)/(1+$A7)^'07_DCF'!C17)+ (('07_DCF'!D16)/(1+$A7)^'07_DCF'!D17)+ (('07_DCF'!E16)/(1+$A7)^'07_DCF'!E17)+ (('07_DCF'!F16)/(1+$A7)^'07_DCF'!F17)+ (('07_DCF'!G16)/(1+$A7)^'07_DCF'!G17)+ ((('07_DCF'!G16)*(1+E$4)/($A7-E$4))/(1+$A7)^'07_DCF'!G17)-'06_Assumptions'!B10+'06_Assumptions'!B8+'06_Assumptions'!B9)/'06_Assumptions'!B7
A8: 0.11 | B8: ((('07_DCF'!C16)/(1+$A8)^'07_DCF'!C17)+ (('07_DCF'!D16)/(1+$A8)^'07_DCF'!D17)+ (('07_DCF'!E16)/(1+$A8)^'07_DCF'!E17)+ (('07_DCF'!F16)/(1+$A8)^'07_DCF'!F17)+ (('07_DCF'!G16)/(1+$A8)^'07_DCF'!G17)+ ((('07_DCF'!G16)*(1+B$4)/($A8-B$4))/(1+$A8)^'07_DCF'!G17)-'06_Assumptions'!B10+'06_Assumptions'!B8+'06_Assumptions'!B9)/'06_Assumptions'!B7 | C8: ((('07_DCF'!C16)/(1+$A8)^'07_DCF'!C17)+ (('07_DCF'!D16)/(1+$A8)^'07_DCF'!D17)+ (('07_DCF'!E16)/(1+$A8)^'07_DCF'!E17)+ (('07_DCF'!F16)/(1+$A8)^'07_DCF'!F17)+ (('07_DCF'!G16)/(1+$A8)^'07_DCF'!G17)+ ((('07_DCF'!G16)*(1+C$4)/($A8-C$4))/(1+$A8)^'07_DCF'!G17)-'06_Assumptions'!B10+'06_Assumptions'!B8+'06_Assumptions'!B9)/'06_Assumptions'!B7 | D8: ((('07_DCF'!C16)/(1+$A8)^'07_DCF'!C17)+ (('07_DCF'!D16)/(1+$A8)^'07_DCF'!D17)+ (('07_DCF'!E16)/(1+$A8)^'07_DCF'!E17)+ (('07_DCF'!F16)/(1+$A8)^'07_DCF'!F17)+ (('07_DCF'!G16)/(1+$A8)^'07_DCF'!G17)+ ((('07_DCF'!G16)*(1+D$4)/($A8-D$4))/(1+$A8)^'07_DCF'!G17)-'06_Assumptions'!B10+'06_Assumptions'!B8+'06_Assumptions'!B9)/'06_Assumptions'!B7 | E8: ((('07_DCF'!C16)/(1+$A8)^'07_DCF'!C17)+ (('07_DCF'!D16)/(1+$A8)^'07_DCF'!D17)+ (('07_DCF'!E16)/(1+$A8)^'07_DCF'!E17)+ (('07_DCF'!F16)/(1+$A8)^'07_DCF'!F17)+ (('07_DCF'!G16)/(1+$A8)^'07_DCF'!G17)+ ((('07_DCF'!G16)*(1+E$4)/($A8-E$4))/(1+$A8)^'07_DCF'!G17)-'06_Assumptions'!B10+'06_Assumptions'!B8+'06_Assumptions'!B9)/'06_Assumptions'!B7
A9: 0.12 | B9: ((('07_DCF'!C16)/(1+$A9)^'07_DCF'!C17)+ (('07_DCF'!D16)/(1+$A9)^'07_DCF'!D17)+ (('07_DCF'!E16)/(1+$A9)^'07_DCF'!E17)+ (('07_DCF'!F16)/(1+$A9)^'07_DCF'!F17)+ (('07_DCF'!G16)/(1+$A9)^'07_DCF'!G17)+ ((('07_DCF'!G16)*(1+B$4)/($A9-B$4))/(1+$A9)^'07_DCF'!G17)-'06_Assumptions'!B10+'06_Assumptions'!B8+'06_Assumptions'!B9)/'06_Assumptions'!B7 | C9: ((('07_DCF'!C16)/(1+$A9)^'07_DCF'!C17)+ (('07_DCF'!D16)/(1+$A9)^'07_DCF'!D17)+ (('07_DCF'!E16)/(1+$A9)^'07_DCF'!E17)+ (('07_DCF'!F16)/(1+$A9)^'07_DCF'!F17)+ (('07_DCF'!G16)/(1+$A9)^'07_DCF'!G17)+ ((('07_DCF'!G16)*(1+C$4)/($A9-C$4))/(1+$A9)^'07_DCF'!G17)-'06_Assumptions'!B10+'06_Assumptions'!B8+'06_Assumptions'!B9)/'06_Assumptions'!B7 | D9: ((('07_DCF'!C16)/(1+$A9)^'07_DCF'!C17)+ (('07_DCF'!D16)/(1+$A9)^'07_DCF'!D17)+ (('07_DCF'!E16)/(1+$A9)^'07_DCF'!E17)+ (('07_DCF'!F16)/(1+$A9)^'07_DCF'!F17)+ (('07_DCF'!G16)/(1+$A9)^'07_DCF'!G17)+ ((('07_DCF'!G16)*(1+D$4)/($A9-D$4))/(1+$A9)^'07_DCF'!G17)-'06_Assumptions'!B10+'06_Assumptions'!B8+'06_Assumptions'!B9)/'06_Assumptions'!B7 | E9: ((('07_DCF'!C16)/(1+$A9)^'07_DCF'!C17)+ (('07_DCF'!D16)/(1+$A9)^'07_DCF'!D17)+ (('07_DCF'!E16)/(1+$A9)^'07_DCF'!E17)+ (('07_DCF'!F16)/(1+$A9)^'07_DCF'!F17)+ (('07_DCF'!G16)/(1+$A9)^'07_DCF'!G17)+ ((('07_DCF'!G16)*(1+E$4)/($A9-E$4))/(1+$A9)^'07_DCF'!G17)-'06_Assumptions'!B10+'06_Assumptions'!B8+'06_Assumptions'!B9)/'06_Assumptions'!B7
A11: Exit multiple sensitivity (EV/EBIT) — value/share using exit-multiple TV only
A13: Value/share | B13: 18 | C13: 20 | D13: 22 | E13: 24 | F13: 26
A14: 0.08 | B14: ((('07_DCF'!C16)/(1+$A14)^'07_DCF'!C17)+ (('07_DCF'!D16)/(1+$A14)^'07_DCF'!D17)+ (('07_DCF'!E16)/(1+$A14)^'07_DCF'!E17)+ (('07_DCF'!F16)/(1+$A14)^'07_DCF'!F17)+ (('07_DCF'!G16)/(1+$A14)^'07_DCF'!G17)+ ((('07_DCF'!G7*B$13))/(1+$A14)^'07_DCF'!G17)-'06_Assumptions'!B10+'06_Assumptions'!B8+'06_Assumptions'!B9)/'06_Assumptions'!B7 | C14: ((('07_DCF'!C16)/(1+$A14)^'07_DCF'!C17)+ (('07_DCF'!D16)/(1+$A14)^'07_DCF'!D17)+ (('07_DCF'!E16)/(1+$A14)^'07_DCF'!E17)+ (('07_DCF'!F16)/(1+$A14)^'07_DCF'!F17)+ (('07_DCF'!G16)/(1+$A14)^'07_DCF'!G17)+ ((('07_DCF'!G7*C$13))/(1+$A14)^'07_DCF'!G17)-'06_Assumptions'!B10+'06_Assumptions'!B8+'06_Assumptions'!B9)/'06_Assumptions'!B7 | D14: ((('07_DCF'!C16)/(1+$A14)^'07_DCF'!C17)+ (('07_DCF'!D16)/(1+$A14)^'07_DCF'!D17)+ (('07_DCF'!E16)/(1+$A14)^'07_DCF'!E17)+ (('07_DCF'!F16)/(1+$A14)^'07_DCF'!F17)+ (('07_DCF'!G16)/(1+$A14)^'07_DCF'!G17)+ ((('07_DCF'!G7*D$13))/(1+$A14)^'07_DCF'!G17)-'06_Assumptions'!B10+'06_Assumptions'!B8+'06_Assumptions'!B9)/'06_Assumptions'!B7 | E14: ((('07_DCF'!C16)/(1+$A14)^'07_DCF'!C17)+ (('07_DCF'!D16)/(1+$A14)^'07_DCF'!D17)+ (('07_DCF'!E16)/(1+$A14)^'07_DCF'!E17)+ (('07_DCF'!F16)/(1+$A14)^'07_DCF'!F17)+ (('07_DCF'!G16)/(1+$A14)^'07_DCF'!G17)+ ((('07_DCF'!G7*E$13))/(1+$A14)^'07_DCF'!G17)-'06_Assumptions'!B10+'06_Assumptions'!B8+'06_Assumptions'!B9)/'06_Assumptions'!B7 | F14: ((('07_DCF'!C16)/(1+$A14)^'07_DCF'!C17)+ (('07_DCF'!D16)/(1+$A14)^'07_DCF'!D17)+ (('07_DCF'!E16)/(1+$A14)^'07_DCF'!E17)+ (('07_DCF'!F16)/(1+$A14)^'07_DCF'!F17)+ (('07_DCF'!G16)/(1+$A14)^'07_DCF'!G17)+ ((('07_DCF'!G7*F$13))/(1+$A14)^'07_DCF'!G17)-'06_Assumptions'!B10+'06_Assumptions'!B8+'06_Assumptions'!B9)/'06_Assumptions'!B7
A15: 0.09 | B15: ((('07_DCF'!C16)/(1+$A15)^'07_DCF'!C17)+ (('07_DCF'!D16)/(1+$A15)^'07_DCF'!D17)+ (('07_DCF'!E16)/(1+$A15)^'07_DCF'!E17)+ (('07_DCF'!F16)/(1+$A15)^'07_DCF'!F17)+ (('07_DCF'!G16)/(1+$A15)^'07_DCF'!G17)+ ((('07_DCF'!G7*B$13))/(1+$A15)^'07_DCF'!G17)-'06_Assumptions'!B10+'06_Assumptions'!B8+'06_Assumptions'!B9)/'06_Assumptions'!B7 | C15: ((('07_DCF'!C16)/(1+$A15)^'07_DCF'!C17)+ (('07_DCF'!D16)/(1+$A15)^'07_DCF'!D17)+ (('07_DCF'!E16)/(1+$A15)^'07_DCF'!E17)+ (('07_DCF'!F16)/(1+$A15)^'07_DCF'!F17)+ (('07_DCF'!G16)/(1+$A15)^'07_DCF'!G17)+ ((('07_DCF'!G7*C$13))/(1+$A15)^'07_DCF'!G17)-'06_Assumptions'!B10+'06_Assumptions'!B8+'06_Assumptions'!B9)/'06_Assumptions'!B7 | D15: ((('07_DCF'!C16)/(1+$A15)^'07_DCF'!C17)+ (('07_DCF'!D16)/(1+$A15)^'07_DCF'!D17)+ (('07_DCF'!E16)/(1+$A15)^'07_DCF'!E17)+ (('07_DCF'!F16)/(1+$A15)^'07_DCF'!F17)+ (('07_DCF'!G16)/(1+$A15)^'07_DCF'!G17)+ ((('07_DCF'!G7*D$13))/(1+$A15)^'07_DCF'!G17)-'06_Assumptions'!B10+'06_Assumptions'!B8+'06_Assumptions'!B9)/'06_Assumptions'!B7 | E15: ((('07_DCF'!C16)/(1+$A15)^'07_DCF'!C17)+ (('07_DCF'!D16)/(1+$A15)^'07_DCF'!D17)+ (('07_DCF'!E16)/(1+$A15)^'07_DCF'!E17)+ (('07_DCF'!F16)/(1+$A15)^'07_DCF'!F17)+ (('07_DCF'!G16)/(1+$A15)^'07_DCF'!G17)+ ((('07_DCF'!G7*E$13))/(1+$A15)^'07_DCF'!G17)-'06_Assumptions'!B10+'06_Assumptions'!B8+'06_Assumptions'!B9)/'06_Assumptions'!B7 | F15: ((('07_DCF'!C16)/(1+$A15)^'07_DCF'!C17)+ (('07_DCF'!D16)/(1+$A15)^'07_DCF'!D17)+ (('07_DCF'!E16)/(1+$A15)^'07_DCF'!E17)+ (('07_DCF'!F16)/(1+$A15)^'07_DCF'!F17)+ (('07_DCF'!G16)/(1+$A15)^'07_DCF'!G17)+ ((('07_DCF'!G7*F$13))/(1+$A15)^'07_DCF'!G17)-'06_Assumptions'!B10+'06_Assumptions'!B8+'06_Assumptions'!B9)/'06_Assumptions'!B7
A16: 0.1 | B16: ((('07_DCF'!C16)/(1+$A16)^'07_DCF'!C17)+ (('07_DCF'!D16)/(1+$A16)^'07_DCF'!D17)+ (('07_DCF'!E16)/(1+$A16)^'07_DCF'!E17)+ (('07_DCF'!F16)/(1+$A16)^'07_DCF'!F17)+ (('07_DCF'!G16)/(1+$A16)^'07_DCF'!G17)+ ((('07_DCF'!G7*B$13))/(1+$A16)^'07_DCF'!G17)-'06_Assumptions'!B10+'06_Assumptions'!B8+'06_Assumptions'!B9)/'06_Assumptions'!B7 | C16: ((('07_DCF'!C16)/(1+$A16)^'07_DCF'!C17)+ (('07_DCF'!D16)/(1+$A16)^'07_DCF'!D17)+ (('07_DCF'!E16)/(1+$A16)^'07_DCF'!E17)+ (('07_DCF'!F16)/(1+$A16)^'07_DCF'!F17)+ (('07_DCF'!G16)/(1+$A16)^'07_DCF'!G17)+ ((('07_DCF'!G7*C$13))/(1+$A16)^'07_DCF'!G17)-'06_Assumptions'!B10+'06_Assumptions'!B8+'06_Assumptions'!B9)/'06_Assumptions'!B7 | D16: ((('07_DCF'!C16)/(1+$A16)^'07_DCF'!C17)+ (('07_DCF'!D16)/(1+$A16)^'07_DCF'!D17)+ (('07_DCF'!E16)/(1+$A16)^'07_DCF'!E17)+ (('07_DCF'!F16)/(1+$A16)^'07_DCF'!F17)+ (('07_DCF'!G16)/(1+$A16)^'07_DCF'!G17)+ ((('07_DCF'!G7*D$13))/(1+$A16)^'07_DCF'!G17)-'06_Assumptions'!B10+'06_Assumptions'!B8+'06_Assumptions'!B9)/'06_Assumptions'!B7 | E16: ((('07_DCF'!C16)/(1+$A16)^'07_DCF'!C17)+ (('07_DCF'!D16)/(1+$A16)^'07_DCF'!D17)+ (('07_DCF'!E16)/(1+$A16)^'07_DCF'!E17)+ (('07_DCF'!F16)/(1+$A16)^'07_DCF'!F17)+ (('07_DCF'!G16)/(1+$A16)^'07_DCF'!G17)+ ((('07_DCF'!G7*E$13))/(1+$A16)^'07_DCF'!G17)-'06_Assumptions'!B10+'06_Assumptions'!B8+'06_Assumptions'!B9)/'06_Assumptions'!B7 | F16: ((('07_DCF'!C16)/(1+$A16)^'07_DCF'!C17)+ (('07_DCF'!D16)/(1+$A16)^'07_DCF'!D17)+ (('07_DCF'!E16)/(1+$A16)^'07_DCF'!E17)+ (('07_DCF'!F16)/(1+$A16)^'07_DCF'!F17)+ (('07_DCF'!G16)/(1+$A16)^'07_DCF'!G17)+ ((('07_DCF'!G7*F$13))/(1+$A16)^'07_DCF'!G17)-'06_Assumptions'!B10+'06_Assumptions'!B8+'06_Assumptions'!B9)/'06_Assumptions'!B7
A17: 0.11 | B17: ((('07_DCF'!C16)/(1+$A17)^'07_DCF'!C17)+ (('07_DCF'!D16)/(1+$A17)^'07_DCF'!D17)+ (('07_DCF'!E16)/(1+$A17)^'07_DCF'!E17)+ (('07_DCF'!F16)/(1+$A17)^'07_DCF'!F17)+ (('07_DCF'!G16)/(1+$A17)^'07_DCF'!G17)+ ((('07_DCF'!G7*B$13))/(1+$A17)^'07_DCF'!G17)-'06_Assumptions'!B10+'06_Assumptions'!B8+'06_Assumptions'!B9)/'06_Assumptions'!B7 | C17: ((('07_DCF'!C16)/(1+$A17)^'07_DCF'!C17)+ (('07_DCF'!D16)/(1+$A17)^'07_DCF'!D17)+ (('07_DCF'!E16)/(1+$A17)^'07_DCF'!E17)+ (('07_DCF'!F16)/(1+$A17)^'07_DCF'!F17)+ (('07_DCF'!G16)/(1+$A17)^'07_DCF'!G17)+ ((('07_DCF'!G7*C$13))/(1+$A17)^'07_DCF'!G17)-'06_Assumptions'!B10+'06_Assumptions'!B8+'06_Assumptions'!B9)/'06_Assumptions'!B7 | D17: ((('07_DCF'!C16)/(1+$A17)^'07_DCF'!C17)+ (('07_DCF'!D16)/(1+$A17)^'07_DCF'!D17)+ (('07_DCF'!E16)/(1+$A17)^'07_DCF'!E17)+ (('07_DCF'!F16)/(1+$A17)^'07_DCF'!F17)+ (('07_DCF'!G16)/(1+$A17)^'07_DCF'!G17)+ ((('07_DCF'!G7*D$13))/(1+$A17)^'07_DCF'!G17)-'06_Assumptions'!B10+'06_Assumptions'!B8+'06_Assumptions'!B9)/'06_Assumptions'!B7 | E17: ((('07_DCF'!C16)/(1+$A17)^'07_DCF'!C17)+ (('07_DCF'!D16)/(1+$A17)^'07_DCF'!D17)+ (('07_DCF'!E16)/(1+$A17)^'07_DCF'!E17)+ (('07_DCF'!F16)/(1+$A17)^'07_DCF'!F17)+ (('07_DCF'!G16)/(1+$A17)^'07_DCF'!G17)+ ((('07_DCF'!G7*E$13))/(1+$A17)^'07_DCF'!G17)-'06_Assumptions'!B10+'06_Assumptions'!B8+'06_Assumptions'!B9)/'06_Assumptions'!B7 | F17: ((('07_DCF'!C16)/(1+$A17)^'07_DCF'!C17)+ (('07_DCF'!D16)/(1+$A17)^'07_DCF'!D17)+ (('07_DCF'!E16)/(1+$A17)^'07_DCF'!E17)+ (('07_DCF'!F16)/(1+$A17)^'07_DCF'!F17)+ (('07_DCF'!G16)/(1+$A17)^'07_DCF'!G17)+ ((('07_DCF'!G7*F$13))/(1+$A17)^'07_DCF'!G17)-'06_Assumptions'!B10+'06_Assumptions'!B8+'06_Assumptions'!B9)/'06_Assumptions'!B7
A18: 0.12 | B18: ((('07_DCF'!C16)/(1+$A18)^'07_DCF'!C17)+ (('07_DCF'!D16)/(1+$A18)^'07_DCF'!D17)+ (('07_DCF'!E16)/(1+$A18)^'07_DCF'!E17)+ (('07_DCF'!F16)/(1+$A18)^'07_DCF'!F17)+ (('07_DCF'!G16)/(1+$A18)^'07_DCF'!G17)+ ((('07_DCF'!G7*B$13))/(1+$A18)^'07_DCF'!G17)-'06_Assumptions'!B10+'06_Assumptions'!B8+'06_Assumptions'!B9)/'06_Assumptions'!B7 | C18: ((('07_DCF'!C16)/(1+$A18)^'07_DCF'!C17)+ (('07_DCF'!D16)/(1+$A18)^'07_DCF'!D17)+ (('07_DCF'!E16)/(1+$A18)^'07_DCF'!E17)+ (('07_DCF'!F16)/(1+$A18)^'07_DCF'!F17)+ (('07_DCF'!G16)/(1+$A18)^'07_DCF'!G17)+ ((('07_DCF'!G7*C$13))/(1+$A18)^'07_DCF'!G17)-'06_Assumptions'!B10+'06_Assumptions'!B8+'06_Assumptions'!B9)/'06_Assumptions'!B7 | D18: ((('07_DCF'!C16)/(1+$A18)^'07_DCF'!C17)+ (('07_DCF'!D16)/(1+$A18)^'07_DCF'!D17)+ (('07_DCF'!E16)/(1+$A18)^'07_DCF'!E17)+ (('07_DCF'!F16)/(1+$A18)^'07_DCF'!F17)+ (('07_DCF'!G16)/(1+$A18)^'07_DCF'!G17)+ ((('07_DCF'!G7*D$13))/(1+$A18)^'07_DCF'!G17)-'06_Assumptions'!B10+'06_Assumptions'!B8+'06_Assumptions'!B9)/'06_Assumptions'!B7 | E18: ((('07_DCF'!C16)/(1+$A18)^'07_DCF'!C17)+ (('07_DCF'!D16)/(1+$A18)^'07_DCF'!D17)+ (('07_DCF'!E16)/(1+$A18)^'07_DCF'!E17)+ (('07_DCF'!F16)/(1+$A18)^'07_DCF'!F17)+ (('07_DCF'!G16)/(1+$A18)^'07_DCF'!G17)+ ((('07_DCF'!G7*E$13))/(1+$A18)^'07_DCF'!G17)-'06_Assumptions'!B10+'06_Assumptions'!B8+'06_Assumptions'!B9)/'06_Assumptions'!B7 | F18: ((('07_DCF'!C16)/(1+$A18)^'07_DCF'!C17)+ (('07_DCF'!D16)/(1+$A18)^'07_DCF'!D17)+ (('07_DCF'!E16)/(1+$A18)^'07_DCF'!E17)+ (('07_DCF'!F16)/(1+$A18)^'07_DCF'!F17)+ (('07_DCF'!G16)/(1+$A18)^'07_DCF'!G17)+ ((('07_DCF'!G7*F$13))/(1+$A18)^'07_DCF'!G17)-'06_Assumptions'!B10+'06_Assumptions'!B8+'06_Assumptions'!B9)/'06_Assumptions'!B7
A21: Row headers = WACC; column headers = g or exit multiple.

Sheet 10_Output
A1: Valuation output summary — FICO
A3: Intrinsic value / share | B3: ='07_DCF'!B38
A4: Current price | B4: ='06_Assumptions'!B6
A5: Upside/(downside) | B5: ='07_DCF'!B40
A7: Enterprise value ($m) | B7: ='07_DCF'!B30
A8: Equity value ($m) | B8: ='07_DCF'!B36
A9: Net debt ($m) | B9: ='06_Assumptions'!B10-'06_Assumptions'!B8-'06_Assumptions'!B9
A10: WACC | B10: ='06_Assumptions'!B27
A11: Terminal growth | B11: ='06_Assumptions'!B45
A12: Exit EV/EBIT | B12: ='06_Assumptions'!B46
A14: Key FY2025 fundamentals ($m)
A15: Metric | B15: Value
A16: Revenue | B16: 1990.869
A17: Operating income (EBIT) | B17: 924.85
A18: Net income | B18: 651.946
A19: Operating cash flow | B19: 778.807
A20: Capex + capitalized software | B20: 39.407
A21: Approx FCFF proxy (OCF − capex − cap. software) | B21: 739.4
A22: EBIT margin | B22: 0.4645
A23: Effective tax rate | B23: 0.1877
A26: Latest BS bridge (10-Q 2026-06-30, $m)
A27: Cash | B27: 248.444
A28: Marketable securities | B28: 56.093
A29: Total debt | B29: 5582.389
A30: Net debt | B30: 5277.852
A31: Shares diluted outstanding (Yahoo, m) | B31: 21.597635
A32: Market cap ($m) | B32: 22596.09
A33: EV market ($m) | B33: 29603.06
A36: What to change first if the output looks off
A37: 1) Growth path (06_Assumptions row 36) — Scores growth has been the engine; fading too slowly inflates value.
A38: 2) EBIT margins (row 37) — FY25 margin ~46.5% is elevated vs history; mean-reversion matters.
A39: 3) WACC / leverage weights — buyback-funded leverage makes current gearing atypical.
A40: 4) Terminal multiple / g — with high ROIC software economics, TV dominates; keep g < WACC.
A41: 5) SBC treatment (B42) — turning on SBC add-back materially increases FCFF.

Sheet 11_Input_Checklist
A1: Blank input checklist — paste or override every line item
A2: Use this sheet if you want to hard-enter your own case from scratch. Units: $ thousands for statements; decimals for rates.
A4: Section | B4: Line item | C4: Your input | D4: Model currently uses | E4: Unit | F4: Source suggestion
A5: Income Statement | B5: On-premises and SaaS software | D5: 740145 | E5: $000 | F5: 10-K IS
A6: Income Statement | B6: Professional services | D6: 82149 | E6: $000 | F6: 10-K IS
A7: Income Statement | B7: Scores | D7: 1168575 | E7: $000 | F7: 10-K IS
A8: Income Statement | B8: Total revenues | D8: 1990869 | E8: $000 | F8: 10-K IS
A9: Income Statement | B9: Cost of revenues | D9: 353722 | E9: $000 | F9: 10-K IS
A10: Income Statement | B10: Research and development | D10: 188347 | E10: $000 | F10: 10-K IS
A11: Income Statement | B11: Selling, general and administrative | D11: 513028 | E11: $000 | F11: 10-K IS
A12: Income Statement | B12: Amortization of intangible assets | D12: 0 | E12: $000 | F12: 10-K IS
A13: Income Statement | B13: Restructuring charges | D13: 10922 | E13: $000 | F13: 10-K IS
A14: Income Statement | B14: Gain on product line asset sale | D14: 0 | E14: $000 | F14: 10-K IS
A15: Income Statement | B15: Total operating expenses | D15: 1066019 | E15: $000 | F15: 10-K IS
A16: Income Statement | B16: Operating income | D16: 924850 | E16: $000 | F16: 10-K IS
... A104: Forecast | B104: ΔNWC % ΔSales | D104: 0.05 | E104: decimal | F104: Judgment

Sheet 12_XBRL_Extract
A1: SEC companyfacts extract (keyed by period-end year, USD/shares)
A2: Raw XBRL pull from data.sec.gov — cross-check against audited statements on 03/04/05.
A4: Concept | B4: 2021 | C4: 2022 | D4: 2023 | E4: 2024 | F4: 2025 | G4: Unit
A5: RevenueFromContractWithCustomerExcludingAssessedTax | B5: 1316536000 | C5: 1377270000 | D5: 1513557000 | E5: 1717526000 | F5: 1990869000 | G5: USD
A6: CostOfRevenue | B6: 332462000 | C6: 302174000 | D6: 311053000 | E6: 348206000 | F6: 353722000 | G6: USD
A7: ResearchAndDevelopmentExpense | B7: 171231000 | C7: 146758000 | D7: 159950000 | E7: 171940000 | F7: 188347000 | G7: USD
A8: SellingGeneralAndAdministrativeExpense | B8: 396281000 | C8: 383863000 | D8: 400565000 | E8: 462834000 | F8: 513028000 | G8: USD
A9: AmortizationOfIntangibleAssets | B9: 3255000 | C9: 2061000 | D9: 1100000 | E9: 917000 | F9: 0 | G9: USD
A10: RestructuringCharges | B10: 7956000 | C10: 0 | D10: 0 | E10: 0 | F10: 10922000 | G10: USD
A11: OperatingIncomeLoss | B11: 505489000 | C11: 542414000 | D11: 642830000 | E11: 733629000 | F11: 924850000 | G11: USD
A12: InterestExpense | B12: 40092000 | C12: 68967000 | D12: 95546000 | E12: 105638000 | G12: USD
A13: OtherNonoperatingIncomeExpense | B13: 7745000 | C13: -2138000 | D13: 6340000 | E13: 14034000 | F13: 11392000 | G13: USD
A14: IncomeLossFromContinuingOperationsBeforeIncomeTaxesExtraordinaryItemsNoncontrollingInterest | B14: 473142000 | C14: 471309000 | D14: 553624000 | E14: 642025000 | F14: 802595000 | G14: USD
A15: IncomeTaxExpenseBenefit | B15: 81058000 | C15: 97768000 | D15: 124249000 | E15: 129214000 | F15: 150649000 | G15: USD
A16: NetIncomeLoss | B16: 392084000 | C16: 373541000 | D16: 429375000 | E16: 512811000 | F16: 651946000 | G16: USD
A17: EarningsPerShareBasic | B17: 13.65 | C17: 14.34 | D17: 17.18 | E17: 20.78 | F17: 26.9 | G17: USD/shares
A18: EarningsPerShareDiluted | B18: 13.4 | C18: 14.18 | D18: 16.93 | E18: 20.45 | F18: 26.54 | G18: USD/shares
A19: WeightedAverageNumberOfSharesOutstandingBasic | B19: 28734000 | C19: 26042000 | D19: 24986000 | E19: 24676000 | F19: 24239000 | G19: shares
A20: WeightedAverageNumberOfDilutedSharesOutstanding | B20: 29260000 | C20: 26347000 | D20: 25367000 | E20: 25079000 | F20: 24561000 | G20: shares
A21: CashAndCashEquivalentsAtCarryingValue | B21: 195354000 | C21: 133202000 | D21: 136778000 | E21: 150667000 | F21: 134136000 | G21: USD
A22: AccountsReceivableNetCurrent | B22: 312107000 | C22: 322410000 | D22: 387947000 | E22: 426642000 | F22: 529148000 | G22: USD
A23: AssetsCurrent | B23: 550974000 | C23: 484715000 | D23: 556448000 | E23: 617413000 | F23: 705165000 | G23: USD
A24: PropertyPlantAndEquipmentNet | B24: 27913000 | C24: 17580000 | D24: 10966000 | E24: 38465000 | F24: 67713000 | G24: USD
... A31: ContractWithCustomerLiabilityCurrent | B31: 105400000 | C31: 120000000 | D31: 136700000 | E31: 156900000 | F31: 187400000 | G31: USD
A32: LongTermDebtCurrent | E32: 15000000 | F32: 399541000 | G32: USD
A33: LiabilitiesCurrent | B33: 559207000 | C33: 331459000 | D33: 367688000 | E33: 380285000 | F33: 849215000 | G33: USD
A34: LongTermDebtNoncurrent | B34: 1009018000 | C34: 1823669000 | D34: 1811658000 | E34: 2194021000 | F34: 2656150000 | G34: USD
A35: OperatingLeaseLiabilityNoncurrent | B35: 53670000 | C35: 39192000 | D35: 23903000 | E35: 21963000 | F35: 19187000 | G35: USD
A36: OtherLiabilitiesNoncurrent | B36: 56823000 | C36: 49661000 | D36: 60022000 | E36: 84294000 | F36: 89365000 | G36: USD
A37: Liabilities | B37: 1678718000 | C37: 2243981000 | D37: 2263271000 | E37: 2680563000 | F37: 3613917000 | G37: USD
A38: RetainedEarningsAccumulatedDeficit | B38: 2585143000 | C38: 2958684000 | D38: 3388059000 | E38: 3900870000 | F38: 4552816000 | G38: USD
A39: TreasuryStockValue | B39: 3857855000 | C39: 4935769000 | D39: 5324865000 | E39: 6138736000 | F39: 7537908000 | G39: USD
A40: AccumulatedOtherComprehensiveIncomeLossNetOfTax | B40: -75854000 | C40: -124702000 | D40: -102145000 | E40: -91629000 | F40: -92050000 | G40: USD
A41: StockholdersEquity | B41: -110942000 | C41: -801947000 | D41: -687990000 | E41: -962679000 | F41: -1745784000 | G41: USD
A42: CommonStockSharesOutstanding | B42: 27568000 | C42: 25154000 | D42: 24770000 | E42: 24392000 | F42: 23764000 | G42: shares
A43: NetCashProvidedByUsedInOperatingActivities | B43: 423817000 | C43: 509450000 | D43: 468915000 | E43: 632964000 | F43: 778807000 | G43: USD
A44: NetCashProvidedByUsedInInvestingActivities | B44: 137850000 | C44: -5671000 | D44: -15954000 | E44: -27993000 | F44: -43719000 | G44: USD
... A56: OperatingLeaseLiabilityCurrent | B56: 22074000 | C56: 19369000 | D56: 16336000 | E56: 11555000 | F56: 9615000 | G56: USD
